Workbook

Sheet Sheet1
A1: codigo | B1: glosa | C1: anio | D1: pais | E1: valor | F1: variable | G1: deflactor | H1: unidad | I1: valor_dfl
A2: C | B2: Industrias manufactureras | C2: 2023 | D2: Brasil | E2: 768089.77 | F2: consumo_intermedio | H2: =VLOOKUP(F2,Hoja1!$A$2:$B$8,2,0) -> Millones de dólares | I2: =IFERROR(IF(H2="Millones de dólares",E2/G2*100,E2),"")
A3: C10 | B3: Elaboración de productos alimenticios | C3: 2023 | D3: Brasil | E3: 201405.06 | F3: consumo_intermedio | H3: =VLOOKUP(F3,Hoja1!$A$2:$B$8,2,0) -> Millones de dólares | I3: =IFERROR(IF(H3="Millones de dólares",E3/G3*100,E3),"")
A4: C11 | B4: Elaboración de bebidas | C4: 2023 | D4: Brasil | E4: 20950.57 | F4: consumo_intermedio | H4: =VLOOKUP(F4,Hoja1!$A$2:$B$8,2,0) -> Millones de dólares | I4: =IFERROR(IF(H4="Millones de dólares",E4/G4*100,E4),"")
A5: C12 | B5: Elaboración de productos de tabaco | C5: 2023 | D5: Brasil | E5: 3703.11 | F5: consumo_intermedio | H5: =VLOOKUP(F5,Hoja1!$A$2:$B$8,2,0) -> Millones de dólares | I5: =IFERROR(IF(H5="Millones de dólares",E5/G5*100,E5),"")
A6: C13 | B6: Fabricación de productos textiles | C6: 2023 | D6: Brasil | E6: 9516.41 | F6: consumo_intermedio | H6: =VLOOKUP(F6,Hoja1!$A$2:$B$8,2,0) -> Millones de dólares | I6: =IFERROR(IF(H6="Millones de dólares",E6/G6*100,E6),"")
A7: C14 | B7: Fabricación de prendas de vestir | C7: 2023 | D7: Brasil | E7: 6931.3 | F7: consumo_intermedio | H7: =VLOOKUP(F7,Hoja1!$A$2:$B$8,2,0) -> Millones de dólares | I7: =IFERROR(IF(H7="Millones de dólares",E7/G7*100,E7),"")
A8: C15 | B8: Fabricación de productos de cuero y productos conexos | C8: 2023 | D8: Brasil | E8: 6326.71 | F8: consumo_intermedio | H8: =VLOOKUP(F8,Hoja1!$A$2:$B$8,2,0) -> Millones de dólares | I8: =IFERROR(IF(H8="Millones de dólares",E8/G8*100,E8),"")
A9: C16 | B9: Producción de madera y fabricación de productos de madera y corcho, excepto muebles; fabricación de artículos de paja y de materiales trenzables | C9: 2023 | D9: Brasil | E9: 5867.78 | F9: consumo_intermedio | H9: =VLOOKUP(F9,Hoja1!$A$2:$B$8,2,0) -> Millones de dólares | I9: =IFERROR(IF(H9="Millones de dólares",E9/G9*100,E9),"")
A10: C17 | B10: Fabricación de papel y de productos de papel | C10: 2023 | D10: Brasil | E10: 23968.51 | F10: consumo_intermedio | H10: =VLOOKUP(F10,Hoja1!$A$2:$B$8,2,0) -> Millones de dólares | I10: =IFERROR(IF(H10="Millones de dólares",E10/G10*100,E10),"")
A11: C18 | B11: Impresión y reproducción de grabaciones | C11: 2023 | D11: Brasil | E11: 1921.59 | F11: consumo_intermedio | H11: =VLOOKUP(F11,Hoja1!$A$2:$B$8,2,0) -> Millones de dólares | I11: =IFERROR(IF(H11="Millones de dólares",E11/G11*100,E11),"")
A12: C19 | B12: Fabricación de coque y productos de la refinación del petróleo | C12: 2023 | D12: Brasil | E12: 62334.14 | F12: consumo_intermedio | H12: =VLOOKUP(F12,Hoja1!$A$2:$B$8,2,0) -> Millones de dólares | I12: =IFERROR(IF(H12="Millones de dólares",E12/G12*100,E12),"")
A13: C20 | B13: Fabricación de sustancias y productos químicos | C13: 2023 | D13: Brasil | E13: 99799.39 | F13: consumo_intermedio | H13: =VLOOKUP(F13,Hoja1!$A$2:$B$8,2,0) -> Millones de dólares | I13: =IFERROR(IF(H13="Millones de dólares",E13/G13*100,E13),"")
... A26: C33 | B26: Reparación e instalación de maquinaria y equipo | C26: 2023 | D26: Brasil | E26: 5540.42 | F26: consumo_intermedio | H26: =VLOOKUP(F26,Hoja1!$A$2:$B$8,2,0) -> Millones de dólares | I26: =IFERROR(IF(H26="Millones de dólares",E26/G26*100,E26),"")
A27: C | B27: Industrias manufactureras | C27: 2023 | D27: Chile | E27: 60219.28 | F27: consumo_intermedio | G27: 142.91079 | H27: =VLOOKUP(F27,Hoja1!$A$2:$B$8,2,0) -> Millones de dólares | I27: =IFERROR(IF(H27="Millones de dólares",E27/G27*100,E27),"") -> 42137.671
A28: C10 | B28: Elaboración de productos alimenticios | C28: 2023 | D28: Chile | E28: 24144.65 | F28: consumo_intermedio | G28: 150.0858 | H28: =VLOOKUP(F28,Hoja1!$A$2:$B$8,2,0) -> Millones de dólares | I28: =IFERROR(IF(H28="Millones de dólares",E28/G28*100,E28),"") -> 16087.232
A29: C11 | B29: Elaboración de bebidas | C29: 2023 | D29: Chile | E29: 4015.59 | F29: consumo_intermedio | G29: 129.04104 | H29: =VLOOKUP(F29,Hoja1!$A$2:$B$8,2,0) -> Millones de dólares | I29: =IFERROR(IF(H29="Millones de dólares",E29/G29*100,E29),"") -> 3111.8703
A30: C13 | B30: Fabricación de productos textiles | C30: 2023 | D30: Chile | E30: 158.09 | F30: consumo_intermedio | G30: 69.851283 | H30: =VLOOKUP(F30,Hoja1!$A$2:$B$8,2,0) -> Millones de dólares | I30: =IFERROR(IF(H30="Millones de dólares",E30/G30*100,E30),"") -> 226.32369
A31: C14 | B31: Fabricación de prendas de vestir | C31: 2023 | D31: Chile | E31: 64.4 | F31: consumo_intermedio | G31: 69.851283 | H31: =VLOOKUP(F31,Hoja1!$A$2:$B$8,2,0) -> Millones de dólares | I31: =IFERROR(IF(H31="Millones de dólares",E31/G31*100,E31),"") -> 92.195872
A32: C15 | B32: Fabricación de productos de cuero y productos conexos | C32: 2023 | D32: Chile | E32: 25.5 | F32: consumo_intermedio | G32: 69.851283 | H32: =VLOOKUP(F32,Hoja1!$A$2:$B$8,2,0) -> Millones de dólares | I32: =IFERROR(IF(H32="Millones de dólares",E32/G32*100,E32),"") -> 36.50613
A33: C16 | B33: Producción de madera y fabricación de productos de madera y corcho, excepto muebles; fabricación de artículos de paja y de materiales trenzables | C33: 2023 | D33: Chile | E33: 2068.8 | F33: consumo_intermedio | G33: 130.15282 | H33: =VLOOKUP(F33,Hoja1!$A$2:$B$8,2,0) -> Millones de dólares | I33: =IFERROR(IF(H33="Millones de dólares",E33/G33*100,E33),"") -> 1589.5161
A34: C17 | B34: Fabricación de papel y de productos de papel | C34: 2023 | D34: Chile | E34: 2804.53 | F34: consumo_intermedio | G34: 89.311059 | H34: =VLOOKUP(F34,Hoja1!$A$2:$B$8,2,0) -> Millones de dólares | I34: =IFERROR(IF(H34="Millones de dólares",E34/G34*100,E34),"") -> 3140.1822
A35: C18 | B35: Impresión y reproducción de grabaciones | C35: 2023 | D35: Chile | E35: 197.76 | F35: consumo_intermedio | G35: 89.311059 | H35: =VLOOKUP(F35,Hoja1!$A$2:$B$8,2,0) -> Millones de dólares | I35: =IFERROR(IF(H35="Millones de dólares",E35/G35*100,E35),"") -> 221.42835
A36: C20 | B36: Fabricación de sustancias y productos químicos | C36: 2023 | D36: Chile | E36: 12427.37 | F36: consumo_intermedio | G36: 179.38969 | H36: =VLOOKUP(F36,Hoja1!$A$2:$B$8,2,0) -> Millones de dólares | I36: =IFERROR(IF(H36="Millones de dólares",E36/G36*100,E36),"") -> 6927.5831
A37: C21 | B37: Fabricación de productos farmacéuticos, sustancias químicas medicinales y productos botánicos de uso farmacéutico | C37: 2023 | D37: Chile | E37: 744.69 | F37: consumo_intermedio | G37: 179.38969 | H37: =VLOOKUP(F37,Hoja1!$A$2:$B$8,2,0) -> Millones de dólares | I37: =IFERROR(IF(H37="Millones de dólares",E37/G37*100,E37),"") -> 415.12419
A38: C22 | B38: Fabricación de productos de caucho y de plástico | C38: 2023 | D38: Chile | E38: 2004.2 | F38: consumo_intermedio | G38: 179.38969 | H38: =VLOOKUP(F38,Hoja1!$A$2:$B$8,2,0) -> Millones de dólares | I38: =IFERROR(IF(H38="Millones de dólares",E38/G38*100,E38),"") -> 1117.2325
... A98: CXX | B98: Otras empresas/establecimientos anonimizados | C98: 2023 | D98: Chile | E98: 29385976 | F98: horas_trabajadas | G98: 142.91079 | H98: =VLOOKUP(F98,Hoja1!$A$2:$B$8,2,0) -> Unidades | I98: =IFERROR(IF(H98="Millones de dólares",E98/G98*100,E98),"") -> 29385976
A99: C | B99: Industrias manufactureras | C99: 2023 | D99: Brasil | E99: 6322197 | F99: nivel_ocupados | H99: =VLOOKUP(F99,Hoja1!$A$2:$B$8,2,0) -> Unidades | I99: =IFERROR(IF(H99="Millones de dólares",E99/G99*100,E99),"") -> 6322197
A100: C10 | B100: Elaboración de productos alimenticios | C100: 2023 | D100: Brasil | E100: 1715308 | F100: nivel_ocupados | H100: =VLOOKUP(F100,Hoja1!$A$2:$B$8,2,0) -> Unidades | I100: =IFERROR(IF(H100="Millones de dólares",E100/G100*100,E100),"") -> 1715308
A101: C11 | B101: Elaboración de bebidas | C101: 2023 | D101: Brasil | E101: 170841 | F101: nivel_ocupados | H101: =VLOOKUP(F101,Hoja1!$A$2:$B$8,2,0) -> Unidades | I101: =IFERROR(IF(H101="Millones de dólares",E101/G101*100,E101),"") -> 170841
A102: C12 | B102: Elaboración de productos de tabaco | C102: 2023 | D102: Brasil | E102: 16162 | F102: nivel_ocupados | H102: =VLOOKUP(F102,Hoja1!$A$2:$B$8,2,0) -> Unidades | I102: =IFERROR(IF(H102="Millones de dólares",E102/G102*100,E102),"") -> 16162
A103: C13 | B103: Fabricación de productos textiles | C103: 2023 | D103: Brasil | E103: 203240 | F103: nivel_ocupados | H103: =VLOOKUP(F103,Hoja1!$A$2:$B$8,2,0) -> Unidades | I103: =IFERROR(IF(H103="Millones de dólares",E103/G103*100,E103),"") -> 203240
A104: C14 | B104: Fabricación de prendas de vestir | C104: 2023 | D104: Brasil | E104: 316253 | F104: nivel_ocupados | H104: =VLOOKUP(F104,Hoja1!$A$2:$B$8,2,0) -> Unidades | I104: =IFERROR(IF(H104="Millones de dólares",E104/G104*100,E104),"") -> 316253
A105: C15 | B105: Fabricación de productos de cuero y productos conexos | C105: 2023 | D105: Brasil | E105: 277687 | F105: nivel_ocupados | H105: =VLOOKUP(F105,Hoja1!$A$2:$B$8,2,0) -> Unidades | I105: =IFERROR(IF(H105="Millones de dólares",E105/G105*100,E105),"") -> 277687
A106: C16 | B106: Producción de madera y fabricación de productos de madera y corcho, excepto muebles; fabricación de artículos de paja y de materiales trenzables | C106: 2023 | D106: Brasil | E106: 107480 | F106: nivel_ocupados | H106: =VLOOKUP(F106,Hoja1!$A$2:$B$8,2,0) -> Unidades | I106: =IFERROR(IF(H106="Millones de dólares",E106/G106*100,E106),"") -> 107480
A107: C17 | B107: Fabricación de papel y de productos de papel | C107: 2023 | D107: Brasil | E107: 189920 | F107: nivel_ocupados | H107: =VLOOKUP(F107,Hoja1!$A$2:$B$8,2,0) -> Unidades | I107: =IFERROR(IF(H107="Millones de dólares",E107/G107*100,E107),"") -> 189920
A108: C18 | B108: Impresión y reproducción de grabaciones | C108: 2023 | D108: Brasil | E108: 39647 | F108: nivel_ocupados | H108: =VLOOKUP(F108,Hoja1!$A$2:$B$8,2,0) -> Unidades | I108: =IFERROR(IF(H108="Millones de dólares",E108/G108*100,E108),"") -> 39647
A109: C19 | B109: Fabricación de coque y productos de la refinación del petróleo | C109: 2023 | D109: Brasil | E109: 73427 | F109: nivel_ocupados | H109: =VLOOKUP(F109,Hoja1!$A$2:$B$8,2,0) -> Unidades | I109: =IFERROR(IF(H109="Millones de dólares",E109/G109*100,E109),"") -> 73427
A110: C20 | B110: Fabricación de sustancias y productos químicos | C110: 2023 | D110: Brasil | E110: 400861 | F110: nivel_ocupados | H110: =VLOOKUP(F110,Hoja1!$A$2:$B$8,2,0) -> Unidades | I110: =IFERROR(IF(H110="Millones de dólares",E110/G110*100,E110),"") -> 400861
... A123: C33 | B123: Reparación e instalación de maquinaria y equipo | C123: 2023 | D123: Brasil | E123: 165358 | F123: nivel_ocupados | H123: =VLOOKUP(F123,Hoja1!$A$2:$B$8,2,0) -> Unidades | I123: =IFERROR(IF(H123="Millones de dólares",E123/G123*100,E123),"") -> 165358
...

Sheet Hoja1
A1: variable | B1: unidad
A2: consumo_intermedio | B2: Millones de dólares
A3: horas_trabajadas | B3: Unidades
A4: nivel_ocupados | B4: Unidades
A5: remuneracion | B5: Millones de dólares
A6: valor_agregado | B6: Millones de dólares
A7: valor_bruto_produccion | B7: Millones de dólares
A8: consumo_energetico | B8: Terajulios
