Workbook
Name FECHA: #REF!
Name PERIODO: #REF!
Name TITULO: #REF!
Name VA: #REF!
Name VA_Ktes: #REF!

Sheet Cuadro 1
A3: Producto Interno Bruto - PIB
A5: Valores a precios corrientes
A6: Miles de millones de pesos
A7: Base 2015
A8: 2005 - 2024pr | Y8: Índice
A10: Clasificación Cuentas Nacionales | B10: Secciones CIIU Rev. 4 A.C. 12 agrupaciones | C10: Secciones y divisiones CIIU Rev. 4 A.C. 25 agrupaciones | D10: Divisiones CIIU Rev. 4 A.C. 61 agrupaciones | E10: Concepto | F10: 2005 | G10: 2006 | H10: 2007 | I10: 2008 | J10: 2009 | K10: 2010 | L10: 2011 | M10: 2012 | N10: 2013 | O10: 2014 | P10: 2015 | Q10: 2016 | R10: 2017 | S10: 2018 | T10: 2019 | U10: 2020 | V10: 2021 | W10: 2022 | X10: 2023p | Y10: 2024pr
A12: PIB enfoque de la producción
B14: A | E14: Agricultura, ganadería, caza, silvicultura y pesca | F14: 25439 | G14: 27425 | H14: 29715 | I14: 31869 | J14: 33554 | K14: 34411 | L14: 37709 | M14: 37209 | N14: 38509 | O14: 41555 | P14: 48124 | Q14: 57065 | R14: 58815 | S14: 61497 | T14: 67958 | U14: 74970 | V14: 92690 | W14: 129919 | X14: 139567 | Y14: 158406.08
C15: A | E15: Agricultura, ganadería, caza, silvicultura y pesca | F15: 25439 | G15: 27425 | H15: 29715 | I15: 31869 | J15: 33554 | K15: 34411 | L15: 37709 | M15: 37209 | N15: 38509 | O15: 41555 | P15: 48124 | Q15: 57065 | R15: 58815 | S15: 61497 | T15: 67958 | U15: 74970 | V15: 92690 | W15: 129919 | X15: 139567 | Y15: 158406.08
D16: 001 - 008, 013 | E16: Cultivos agrícolas transitorios; otros cultivos agrícolas permanentes; Propagación de plantas (actividades de viveros, excepto viveros forestales); actividades de apoyo a la agricultura y la ganadería, y posteriores a la cosecha, explotación mixta (agrícola y pecuaria) y caza ordinaria y mediante trampas y actividades de servicios conexas | F16: 13312 | G16: 14490 | H16: 15675 | I16: 17044 | J16: 18522 | K16: 18653 | L16: 20760 | M16: 20538 | N16: 20723 | O16: 22133 | P16: 27339 | Q16: 33033 | R16: 33979 | S16: 36116 | T16: 40735 | U16: 44817 | V16: 53191 | W16: 80655 | X16: 87726 | Y16: 99008.74
D17: 003 | E17: Cultivo permanente de café | F17: 2763 | G17: 3039 | H17: 3195 | I17: 3140 | J17: 2986 | K17: 3810 | L17: 4453 | M17: 3254 | N17: 4067 | O17: 4659 | P17: 5299 | Q17: 6299 | R17: 6482 | S17: 6173 | T17: 7310 | U17: 8105 | V17: 11273 | W17: 14406 | X17: 12865 | Y17: 19384.83
D18: 009 - 012 | E18: Ganadería | F18: 7843 | G18: 8223 | H18: 9043 | I18: 9815 | J18: 10043 | K18: 9931 | L18: 10392 | M18: 11091 | N18: 11238 | O18: 11910 | P18: 12265 | Q18: 14098 | R18: 14639 | S18: 15224 | T18: 15735 | U18: 16980 | V18: 21931 | W18: 27215 | X18: 30322 | Y18: 30870.41
D19: 014, 015 | E19: Silvicultura y extracción de madera | F19: 854 | G19: 915 | H19: 984 | I19: 1011 | J19: 1109 | K19: 1127 | L19: 1197 | M19: 1352 | N19: 1493 | O19: 1617 | P19: 1796 | Q19: 1963 | R19: 2047 | S19: 2075 | T19: 2201 | U19: 2332 | V19: 2986 | W19: 3289 | X19: 3877 | Y19: 3895.9
D20: 016 | E20: Pesca y acuicultura | F20: 667 | G20: 758 | H20: 818 | I20: 859 | J20: 894 | K20: 890 | L20: 907 | M20: 974 | N20: 988 | O20: 1236 | P20: 1425 | Q20: 1672 | R20: 1668 | S20: 1909 | T20: 1977 | U20: 2736 | V20: 3309 | W20: 4354 | X20: 4777 | Y20: 5246.21
B21: B | E21: Explotación de minas y canteras | F21: 22071 | G21: 26127 | H21: 26443 | I21: 38675 | J21: 37234 | K21: 47105 | L21: 70548 | M21: 74557 | N21: 73340 | O21: 64274 | P21: 47627 | Q21: 40999 | R21: 47538 | S21: 57788 | T21: 58317 | U21: 40689 | V21: 64235 | W21: 107532 | X21: 89489 | Y21: 75886.25
C22: B | E22: Explotación de minas y canteras | F22: 22071 | G22: 26127 | H22: 26443 | I22: 38675 | J22: 37234 | K22: 47105 | L22: 70548 | M22: 74557 | N22: 73340 | O22: 64274 | P22: 47627 | Q22: 40999 | R22: 47538 | S22: 57788 | T22: 58317 | U22: 40689 | V22: 64235 | W22: 107532 | X22: 89489 | Y22: 75886.25
D23: 017 | E23: Extracción de carbón de piedra y lignito | F23: 4915 | G23: 5705 | H23: 5577 | I23: 8542 | J23: 8610 | K23: 8621 | L23: 11256 | M23: 10973 | N23: 9303 | O23: 8404 | P23: 8833 | Q23: 11027 | R23: 13634 | S23: 15167 | T23: 12226 | U23: 7429 | V23: 15146 | W23: 37050 | X23: 26365 | Y23: 16021.16
D24: 018, 021 | E24: Extracción de petróleo crudo y gas natural y actividades de apoyo para la extracción de petróleo y de gas natural | F24: 14038 | G24: 15969 | H24: 15526 | I24: 25915 | J24: 24058 | K24: 33071 | L24: 53113 | M24: 56982 | N24: 58714 | O24: 50497 | P24: 32852 | Q24: 22289 | R24: 27822 | S24: 36871 | T24: 39127 | U24: 24320 | V24: 38429 | W24: 58383 | X24: 49629 | Y24: 45363.31
D25: 019 | E25: Extracción de minerales metalíferos | F25: 2143 | G25: 3275 | H25: 3999 | I25: 2706 | J25: 2994 | K25: 3917 | L25: 4448 | M25: 4754 | N25: 3313 | O25: 3131 | P25: 3592 | Q25: 5001 | R25: 3472 | S25: 3112 | T25: 4163 | U25: 6849 | V25: 8125 | W25: 9210 | X25: 10433 | Y25: 11217.77
D26: 020 | E26: Extracción de otras minas y canteras | F26: 865 | G26: 1046 | H26: 1197 | I26: 1352 | J26: 1406 | K26: 1317 | L26: 1511 | M26: 1625 | N26: 1825 | O26: 2067 | P26: 2156 | Q26: 2435 | R26: 2421 | S26: 2437 | T26: 2628 | U26: 1932 | V26: 2292 | W26: 2464 | X26: 2712 | Y26: 2982.66
D27: 022 | E27: Actividades de apoyo para otras actividades de explotación de minas y canteras | F27: 110 | G27: 132 | H27: 144 | I27: 160 | J27: 166 | K27: 179 | L27: 220 | M27: 223 | N27: 185 | O27: 175 | P27: 194 | Q27: 247 | R27: 189 | S27: 201 | T27: 173 | U27: 159 | V27: 243 | W27: 425 | X27: 350 | Y27: 301.35
B28: C | E28: Industrias manufactureras | F28: 54043 | G28: 60975 | H28: 69222 | I28: 73264 | J28: 74133 | K28: 75989 | L28: 81820 | M28: 87241 | N28: 90421 | O28: 93603 | P28: 99789 | Q28: 106226 | R28: 105022 | S28: 110157 | T28: 115830 | U28: 107111 | V28: 133565 | W28: 163991 | X28: 172226 | Y28: 172275.15
C29: C01 | E29: Elaboración de productos alimenticios; elaboración de bebidas; elaboración de productos de tabaco | F29: 16767 | G29: 18095 | H29: 20270 | I29: 22528 | J29: 24071 | K29: 23065 | L29: 24019 | M29: 24776 | N29: 25438 | O29: 26163 | P29: 27219 | Q29: 30138 | R29: 30603 | S29: 31305 | T29: 31682 | U29: 32205 | V29: 39352 | W29: 49066 | X29: 51605 | Y29: 51899.4
D30: 023 - 025 | E30: Procesamiento y conservación de carne y productos cárnicos de bovinos, bufalinos, porcinos y otras carnes n.c.p.; procesamiento y conservación de carne y productos cárnicos de aves de corral y procesamiento y conservación de pescados, crustáceos y moluscos | F30: 3222 | G30: 3345 | H30: 3920 | I30: 4568 | J30: 4835 | K30: 4566 | L30: 4830 | M30: 4997 | N30: 5232 | O30: 5475 | P30: 5896 | Q30: 6543 | R30: 6579 | S30: 6924 | T30: 7112 | U30: 7595 | V30: 10228 | W30: 12957 | X30: 14058 | Y30: 14783.27
D31: 026 | E31: Elaboración de aceites y grasas de origen vegetal y animal | F31: 1255 | G31: 1165 | H31: 1284 | I31: 1456 | J31: 1467 | K31: 1420 | L31: 1483 | M31: 1271 | N31: 1093 | O31: 1373 | P31: 1506 | Q31: 1986 | R31: 1884 | S31: 1715 | T31: 1570 | U31: 1443 | V31: 2848 | W31: 3596 | X31: 3011 | Y31: 2630.82
D32: 027 | E32: Elaboración de productos lácteos | F32: 1916 | G32: 1989 | H32: 2188 | I32: 2460 | J32: 2464 | K32: 2528 | L32: 2722 | M32: 2962 | N32: 3095 | O32: 3131 | P32: 3217 | Q32: 3421 | R32: 3553 | S32: 3609 | T32: 3644 | U32: 3863 | V32: 3954 | W32: 4851 | X32: 5388 | Y32: 5307.38
D33: 028, 032, 035 | E33: Elaboración de productos de molinería, almidones y productos derivados del almidón; elaboración de productos de panadería; elaboración de macarrones, fideos, alcuzcuz, y productos farináceos similares y elaboración de alimentos preparados para animales | F33: 3057 | G33: 3110 | H33: 3581 | I33: 4238 | J33: 4290 | K33: 3893 | L33: 3961 | M33: 4139 | N33: 4229 | O33: 3970 | P33: 3922 | Q33: 4737 | R33: 4560 | S33: 4682 | T33: 5156 | U33: 6021 | V33: 6488 | W33: 8502 | X33: 8399 | Y33: 7687.59
D34: 029 | E34: Elaboración de productos de café | F34: 894 | G34: 795 | H34: 637 | I34: 587 | J34: 503 | K34: 465 | L34: 373 | M34: 402 | N34: 501 | O34: 517 | P34: 702 | Q34: 625 | R34: 702 | S34: 651 | T34: 722 | U34: 282 | V34: 386 | W34: 488 | X34: 455 | Y34: 613.7
D35: 030, 031 | E35: Elaboración de azúcar y elaboración de panela | F35: 1509 | G35: 2220 | H35: 2107 | I35: 2156 | J35: 2742 | K35: 2945 | L35: 3339 | M35: 2712 | N35: 2386 | O35: 2516 | P35: 2618 | Q35: 2793 | R35: 3066 | S35: 3060 | T35: 2656 | U35: 3039 | V35: 3502 | W35: 4101 | X35: 4205 | Y35: 4228.68
D36: 033 | E36: Elaboración de cacao, chocolate y productos de confitería | F36: 620 | G36: 641 | H36: 675 | I36: 745 | J36: 748 | K36: 677 | L36: 721 | M36: 790 | N36: 760 | O36: 747 | P36: 688 | Q36: 635 | R36: 665 | S36: 702 | T36: 756 | U36: 726 | V36: 859 | W36: 1077 | X36: 1175 | Y36: 1209.29
D37: 034 | E37: Procesamiento y conservación de frutas, legumbres, hortalizas y tubérculos; elaboración de otros productos alimenticios (platos preparados y conservados mediante enlatado o congelado, elaboración de sopas y caldos en estado sólidos, polvo o instantáneas entre otros) | F37: 1064 | G37: 1179 | H37: 1397 | I37: 1531 | J37: 1657 | K37: 1548 | L37: 1483 | M37: 1795 | N37: 1997 | O37: 1986 | P37: 2276 | Q37: 2333 | R37: 2398 | S37: 2453 | T37: 2520 | U37: 2640 | V37: 2985 | W37: 3652 | X37: 3826 | Y37: 3832.14
D38: 036 | E38: Elaboración de bebidas (incluido el hielo) y elaboración de productos de tabaco | F38: 3230 | G38: 3651 | H38: 4481 | I38: 4787 | J38: 5365 | K38: 5023 | L38: 5107 | M38: 5708 | N38: 6145 | O38: 6448 | P38: 6394 | Q38: 7065 | R38: 7196 | S38: 7509 | T38: 7546 | U38: 6596 | V38: 8102 | W38: 9842 | X38: 11088 | Y38: 11606.53
C39: C02 | E39: Fabricación de productos textiles; confección de prendas de vestir; curtido y recurtido de cueros; fabricación de calzado; fabricación de artículos de viaje, maletas, bolsos de mano y artículos similares, y fabricación de artículos de talabartería y guarnicionería; adobo y teñido de pieles | F39: 6783 | G39: 7663 | H39: 9159 | I39: 9358 | J39: 8140 | K39: 8263 | L39: 9078 | M39: 9671 | N39: 9964 | O39: 9996 | P39: 10343 | Q39: 10806 | R39: 10409 | S39: 10412 | T39: 11174 | U39: 8370 | V39: 12307 | W39: 14664 | X39: 14168 | Y39: 14049.38
D40: 037, 038 | E40: Preparación, hilatura, tejeduría y acabado de productos textiles; fabricación de otros productos textiles, Confección de prendas de vestir | F40: 5597 | G40: 6382 | H40: 7553 | I40: 7511 | J40: 6618 | K40: 6799 | L40: 7455 | M40: 7958 | N40: 8243 | O40: 8280 | P40: 8584 | Q40: 8992 | R40: 8771 | S40: 8912 | T40: 9718 | U40: 7554 | V40: 11114 | W40: 13277 | X40: 12784 | Y40: 12711.32
D41: 039 | E41: Curtido y recurtido de cueros; fabricación de calzado; fabricación de artículos de viaje, maletas, bolsos de mano y artículos similares, y fabricación de artículos de talabartería y guarnicionería; adobo y teñido de pieles | F41: 1186 | G41: 1281 | H41: 1606 | I41: 1847 | J41: 1522 | K41: 1464 | L41: 1623 | M41: 1713 | N41: 1721 | O41: 1716 | P41: 1759 | Q41: 1814 | R41: 1638 | S41: 1500 | T41: 1456 | U41: 816 | V41: 1193 | W41: 1387 | X41: 1384 | Y41: 1338.06
C42: C03 | E42: Transformación de la madera y fabricación de productos de madera y de corcho, excepto muebles; fabricación de artículos de cestería y espartería; fabricación de papel, cartón y productos de papel y de cartón; actividades de impresión; producción de copias a partir de grabaciones originales | F42: 3401 | G42: 3842 | H42: 4338 | I42: 4616 | J42: 4892 | K42: 4662 | L42: 4773 | M42: 5123 | N42: 5273 | O42: 5403 | P42: 6057 | Q42: 5931 | R42: 5798 | S42: 5961 | T42: 6293 | U42: 6124 | V42: 6721 | W42: 8706 | X42: 8875 | Y42: 8922.24
D43: 040 | E43: Transformación de la madera y fabricación de productos de madera y de corcho, excepto muebles; fabricación de artículos de cestería y espartería | F43: 531 | G43: 645 | H43: 834 | I43: 908 | J43: 903 | K43: 938 | L43: 961 | M43: 996 | N43: 1039 | O43: 1094 | P43: 1137 | Q43: 1170 | R43: 1092 | S43: 1036 | T43: 1010 | U43: 973 | V43: 935 | W43: 1168 | X43: 1137 | Y43: 1114.62
D44: 041 | E44: Fabricación de papel, cartón y productos de papel y de cartón | F44: 1977 | G44: 2187 | H44: 2356 | I44: 2478 | J44: 2653 | K44: 2350 | L44: 2318 | M44: 2523 | N44: 2581 | O44: 2655 | P44: 3219 | Q44: 3115 | R44: 3269 | S44: 3479 | T44: 3818 | U44: 3764 | V44: 4244 | W44: 5629 | X44: 5798 | Y44: 5847.87
D45: 042 | E45: Actividades de impresión; producción de copias a partir de grabaciones originales (Copia a partir de un original en CD, DVD, Bluray) | F45: 893 | G45: 1010 | H45: 1148 | I45: 1230 | J45: 1336 | K45: 1374 | L45: 1494 | M45: 1604 | N45: 1653 | O45: 1654 | P45: 1701 | Q45: 1646 | R45: 1437 | S45: 1446 | T45: 1465 | U45: 1387 | V45: 1542 | W45: 1909 | X45: 1940 | Y45: 1959.76
C46: C04 | E46: Coquización, fabricación de productos de la refinación del petróleo y actividad de mezcla de combustibles; fabricación de sustancias y productos químicos; fabricación de productos farmacéuticos, sustancias químicas medicinales y productos botánicos de uso farmacéutico; fabricación de productos de caucho y de plástico; fabricación de otros productos minerales no metálicos | F46: 15277 | G46: 17718 | H46: 20014 | I46: 21641 | J46: 21960 | K46: 23509 | L46: 26517 | M46: 28334 | N46: 30322 | O46: 32235 | P46: 35555 | Q46: 38111 | R46: 39071 | S46: 42105 | T46: 44731 | U46: 40040 | V46: 50786 | W46: 61741 | X46: 67520 | Y46: 66953.1
...

Sheet Cuadro 2
A3: Producto Interno Bruto - PIB
A5: Series encadenadas de volumen con año de referencia 2015
A6: Miles de millones de pesos
A7: 2005 - 2024pr | Y7: Índice
A9: Clasificación Cuentas Nacionales | B9: Secciones CIIU Rev. 4 A.C. 12 agrupaciones | C9: Secciones y divisiones CIIU Rev. 4 A.C. 25 agrupaciones | D9: Divisiones CIIU Rev. 4 A.C. 61 agrupaciones | E9: Concepto | F9: 2005 | G9: 2006 | H9: 2007 | I9: 2008 | J9: 2009 | K9: 2010 | L9: 2011 | M9: 2012 | N9: 2013 | O9: 2014 | P9: 2015 | Q9: 2016 | R9: 2017 | S9: 2018 | T9: 2019 | U9: 2020 | V9: 2021 | W9: 2022 | X9: 2023p | Y9: 2024pr
A11: PIB enfoque de la producción
B13: A | E13: Agricultura, ganadería, caza, silvicultura y pesca | F13: 37909 | G13: 38717 | H13: 40239 | I13: 39915 | J13: 39822 | K13: 39943 | L13: 40706 | M13: 41725 | N13: 44835 | O13: 46140 | P13: 48124 | Q13: 49441 | R13: 52198 | S13: 53030 | T13: 54471 | U13: 55539 | V13: 57968 | W13: 57442 | X13: 58406 | Y13: 63061.23
C14: A | E14: Agricultura, ganadería, caza, silvicultura y pesca | F14: 37909 | G14: 38717 | H14: 40239 | I14: 39915 | J14: 39822 | K14: 39943 | L14: 40706 | M14: 41725 | N14: 44835 | O14: 46140 | P14: 48124 | Q14: 49441 | R14: 52198 | S14: 53030 | T14: 54471 | U14: 55539 | V14: 57968 | W14: 57442 | X14: 58406 | Y14: 63061.23
D15: 001 - 008, 013 | E15: Cultivos agrícolas transitorios; otros cultivos agrícolas permanentes; Propagación de plantas (actividades de viveros, excepto viveros forestales); actividades de apoyo a la agricultura y la ganadería, y posteriores a la cosecha, explotación mixta (agrícola y pecuaria) y caza ordinaria y mediante trampas y actividades de servicios conexas | F15: 21844 | G15: 21729 | H15: 22630 | I15: 22152 | J15: 23060 | K15: 22863 | L15: 23482 | M15: 24221 | N15: 25727 | O15: 26164 | P15: 27339 | Q15: 28339 | R15: 30612 | S15: 30933 | T15: 31344 | U15: 32005 | V15: 33477 | W15: 33829 | X15: 34677 | Y15: 37349.47
D16: 003 | E16: Cultivo permanente de café | F16: 3845 | G16: 4153 | H16: 4336 | I16: 3972 | J16: 3066 | K16: 3415 | L16: 3134 | M16: 3066 | N16: 4167 | O16: 4810 | P16: 5299 | Q16: 5489 | R16: 5470 | S16: 5393 | T16: 5981 | U16: 5327 | V16: 5140 | W16: 4232 | X16: 4403 | Y16: 5384.5
D17: 009 - 012 | E17: Ganadería | F17: 9857 | G17: 10271 | H17: 10633 | I17: 11033 | J17: 10996 | K17: 10902 | L17: 11348 | M17: 11652 | N17: 11930 | O17: 11959 | P17: 12265 | Q17: 12418 | R17: 12956 | S17: 13400 | T17: 13729 | U17: 14259 | V17: 15223 | W17: 15300 | X17: 15068 | Y17: 15920.56
D18: 014, 015 | E18: Silvicultura y extracción de madera | F18: 1332 | G18: 1351 | H18: 1366 | I18: 1367 | J18: 1394 | K18: 1423 | L18: 1494 | M18: 1593 | N18: 1652 | O18: 1759 | P18: 1796 | Q18: 1837 | R18: 1856 | S18: 1877 | T18: 1963 | U18: 2029 | V18: 2107 | W18: 2143 | X18: 2129 | Y18: 2086.45
D19: 016 | E19: Pesca y acuicultura | F19: 1252 | G19: 1346 | H19: 1422 | I19: 1455 | J19: 1380 | K19: 1354 | L19: 1359 | M19: 1405 | N19: 1424 | O19: 1448 | P19: 1425 | Q19: 1358 | R19: 1295 | S19: 1410 | T19: 1446 | U19: 1878 | V19: 2059 | W19: 2325 | X19: 2331 | Y19: 2261.38
B20: B | E20: Explotación de minas y canteras | F20: 27430 | G20: 28059 | H20: 28434 | I20: 31101 | J20: 34659 | K20: 38427 | L20: 43974 | M20: 46335 | N20: 48794 | O20: 48136 | P20: 47627 | Q20: 46253 | R20: 43592 | S20: 42868 | T20: 43693 | U20: 37056 | V20: 36980 | W20: 37518 | X20: 38496 | Y20: 36555
C21: B | E21: Explotación de minas y canteras | F21: 27430 | G21: 28059 | H21: 28434 | I21: 31101 | J21: 34659 | K21: 38427 | L21: 43974 | M21: 46335 | N21: 48794 | O21: 48136 | P21: 47627 | Q21: 46253 | R21: 43592 | S21: 42868 | T21: 43693 | U21: 37056 | V21: 36980 | W21: 37518 | X21: 38496 | Y21: 36555
D22: 017 | E22: Extracción de carbón de piedra y lignito | F22: 6106 | G22: 6772 | H22: 7240 | I22: 7606 | J22: 7578 | K22: 7721 | L22: 8857 | M22: 9199 | N22: 8829 | O22: 9099 | P22: 8833 | Q22: 10031 | R22: 9996 | S22: 9447 | T22: 9329 | U22: 6021 | V22: 6490 | W22: 6539 | X22: 6687 | Y22: 5820.33
D23: 018, 021 | E23: Extracción de petróleo crudo y gas natural y actividades de apoyo para la extracción de petróleo y de gas natural | F23: 16418 | G23: 16323 | H23: 16367 | I23: 18886 | J23: 21756 | K23: 25403 | L23: 29921 | M23: 31308 | N23: 33967 | O23: 33135 | P23: 32852 | Q23: 29705 | R23: 28532 | S23: 29011 | T23: 29826 | U23: 26499 | V23: 24776 | W23: 25259 | X23: 25946 | Y23: 25776.61
D24: 019 | E24: Extracción de minerales metalíferos | F24: 4157 | G24: 4077 | H24: 3834 | I24: 3574 | J24: 4174 | K24: 4203 | L24: 3733 | M24: 4432 | N24: 3876 | O24: 3820 | P24: 3592 | Q24: 4064 | R24: 2982 | S24: 2574 | T24: 2710 | U24: 3185 | V24: 3511 | W24: 3557 | X24: 3710 | Y24: 3412.09
D25: 020 | E25: Extracción de otras minas y canteras | F25: 1267 | G25: 1391 | H25: 1529 | I25: 1629 | J25: 1696 | K25: 1492 | L25: 1581 | M25: 1621 | N25: 1786 | O25: 1990 | P25: 2156 | Q25: 2232 | R25: 2175 | S25: 2144 | T25: 2235 | U25: 1504 | V25: 1661 | W25: 1634 | X25: 1619 | Y25: 1664.9
D26: 022 | E26: Actividades de apoyo para otras actividades de explotación de minas y canteras | F26: 143 | G26: 152 | H26: 155 | I26: 156 | J26: 164 | K26: 164 | L26: 172 | M26: 186 | N26: 177 | O26: 182 | P26: 194 | Q26: 221 | R26: 179 | S26: 181 | T26: 178 | U26: 148 | V26: 162 | W26: 163 | X26: 163 | Y26: 158.27
B27: C | E27: Industrias manufactureras | F27: 77252 | G27: 82885 | H27: 89320 | I27: 89639 | J27: 86354 | K27: 87980 | L27: 92896 | M27: 93667 | N27: 95081 | O27: 97829 | P27: 99789 | Q27: 103006 | R27: 101135 | S27: 102627 | T27: 103860 | U27: 94254 | V27: 107066 | W27: 115802 | X27: 112628 | Y27: 110281.94
C28: C01 | E28: Elaboración de productos alimenticios; elaboración de bebidas; elaboración de productos de tabaco | F28: 21322 | G28: 22235 | H28: 23431 | I28: 24041 | J28: 24387 | K28: 23932 | L28: 24803 | M28: 25068 | N28: 25935 | O28: 26660 | P28: 27219 | Q28: 27871 | R28: 27924 | S28: 28594 | T28: 29391 | U28: 28425 | V28: 30075 | W28: 32252 | X28: 31968 | Y28: 31721.05
D29: 023 - 025 | E29: Procesamiento y conservación de carne y productos cárnicos de bovinos, bufalinos, porcinos y otras carnes n.c.p.; procesamiento y conservación de carne y productos cárnicos de aves de corral y procesamiento y conservación de pescados, crustáceos y moluscos | F29: 4355 | G29: 4578 | H29: 4901 | I29: 5176 | J29: 5202 | K29: 5217 | L29: 5407 | M29: 5626 | N29: 5646 | O29: 5742 | P29: 5896 | Q29: 6033 | R29: 6013 | S29: 6313 | T29: 6650 | U29: 6752 | V29: 7094 | W29: 7491 | X29: 7660 | Y29: 7842.24
D30: 026 | E30: Elaboración de aceites y grasas de origen vegetal y animal | F30: 978 | G30: 987 | H30: 1038 | I30: 1059 | J30: 1129 | K30: 1173 | L30: 1237 | M30: 1250 | N30: 1314 | O30: 1392 | P30: 1506 | Q30: 1508 | R30: 1570 | S30: 1494 | T30: 1522 | U30: 1435 | V30: 1655 | W30: 1720 | X30: 1690 | Y30: 1569.08
D31: 027 | E31: Elaboración de productos lácteos | F31: 2609 | G31: 2659 | H31: 2726 | I31: 2880 | J31: 2855 | K31: 2838 | L31: 2947 | M31: 2981 | N31: 3139 | O31: 3177 | P31: 3217 | Q31: 3271 | R31: 3301 | S31: 3312 | T31: 3371 | U31: 3405 | V31: 3127 | W31: 3159 | X31: 3019 | Y31: 2914.95
D32: 028, 032, 035 | E32: Elaboración de productos de molinería, almidones y productos derivados del almidón; elaboración de productos de panadería; elaboración de macarrones, fideos, alcuzcuz, y productos farináceos similares y elaboración de alimentos preparados para animales | F32: 3401 | G32: 3504 | H32: 3762 | I32: 3883 | J32: 3817 | K32: 3908 | L32: 4030 | M32: 3966 | N32: 3918 | O32: 3825 | P32: 3922 | Q32: 4237 | R32: 4336 | S32: 4398 | T32: 4585 | U32: 4801 | V32: 4615 | W32: 4917 | X32: 4735 | Y32: 4521.64
D33: 029 | E33: Elaboración de productos de café | F33: 616 | G33: 638 | H33: 633 | I33: 609 | J33: 471 | K33: 486 | L33: 453 | M33: 418 | N33: 564 | O33: 631 | P33: 702 | Q33: 715 | R33: 736 | S33: 713 | T33: 793 | U33: 649 | V33: 640 | W33: 608 | X33: 606 | Y33: 693.47
D34: 030, 031 | E34: Elaboración de azúcar y elaboración de panela | F34: 2056 | G34: 2256 | H34: 2194 | I34: 2097 | J34: 2398 | K34: 2104 | L34: 2328 | M34: 2297 | N34: 2411 | O34: 2721 | P34: 2618 | Q34: 2381 | R34: 2424 | S34: 2465 | T34: 2439 | U34: 2448 | V34: 2489 | W34: 2546 | X34: 2439 | Y34: 2565.03
D35: 033 | E35: Elaboración de cacao, chocolate y productos de confitería | F35: 615 | G35: 619 | H35: 641 | I35: 691 | J35: 683 | K35: 658 | L35: 662 | M35: 670 | N35: 663 | O35: 704 | P35: 688 | Q35: 702 | R35: 723 | S35: 781 | T35: 828 | U35: 813 | V35: 915 | W35: 1032 | X35: 997 | Y35: 958.52
D36: 034 | E36: Procesamiento y conservación de frutas, legumbres, hortalizas y tubérculos; elaboración de otros productos alimenticios (platos preparados y conservados mediante enlatado o congelado, elaboración de sopas y caldos en estado sólidos, polvo o instantáneas entre otros) | F36: 1597 | G36: 1719 | H36: 1948 | I36: 1991 | J36: 2022 | K36: 1983 | L36: 2016 | M36: 2030 | N36: 2143 | O36: 2187 | P36: 2276 | Q36: 2329 | R36: 2308 | S36: 2365 | T36: 2361 | U36: 2411 | V36: 2506 | W36: 2769 | X36: 2620 | Y36: 2542.27
D37: 036 | E37: Elaboración de bebidas (incluido el hielo) y elaboración de productos de tabaco | F37: 4977 | G37: 5204 | H37: 5610 | I37: 5705 | J37: 5833 | K37: 5585 | L37: 5657 | M37: 5804 | N37: 6110 | O37: 6274 | P37: 6394 | Q37: 6695 | R37: 6495 | S37: 6746 | T37: 6862 | U37: 5718 | V37: 7078 | W37: 8140 | X37: 8367 | Y37: 8308.44
C38: C02 | E38: Fabricación de productos textiles; confección de prendas de vestir; curtido y recurtido de cueros; fabricación de calzado; fabricación de artículos de viaje, maletas, bolsos de mano y artículos similares, y fabricación de artículos de talabartería y guarnicionería; adobo y teñido de pieles | F38: 8833 | G38: 9638 | H38: 10852 | I38: 10760 | J38: 9324 | K38: 9642 | L38: 10422 | M38: 10355 | N38: 10128 | O38: 10303 | P38: 10343 | Q38: 10815 | R38: 10510 | S38: 10397 | T38: 10473 | U38: 8241 | V38: 11683 | W38: 13106 | X38: 11464 | Y38: 11045.48
D39: 037, 038 | E39: Preparación, hilatura, tejeduría y acabado de productos textiles; fabricación de otros productos textiles, Confección de prendas de vestir | F39: 7341 | G39: 8075 | H39: 9064 | I39: 8826 | J39: 7734 | K39: 7967 | L39: 8555 | M39: 8552 | N39: 8428 | O39: 8552 | P39: 8584 | Q39: 9004 | R39: 8693 | S39: 8729 | T39: 8892 | U39: 7272 | V39: 10245 | W39: 11560 | X39: 10064 | Y39: 9721.5
D40: 039 | E40: Curtido y recurtido de cueros; fabricación de calzado; fabricación de artículos de viaje, maletas, bolsos de mano y artículos similares, y fabricación de artículos de talabartería y guarnicionería; adobo y teñido de pieles | F40: 1496 | G40: 1569 | H40: 1793 | I40: 1927 | J40: 1593 | K40: 1676 | L40: 1866 | M40: 1803 | N40: 1701 | O40: 1751 | P40: 1759 | Q40: 1811 | R40: 1817 | S40: 1653 | T40: 1554 | U40: 902 | V40: 1353 | W40: 1436 | X40: 1313 | Y40: 1235.06
C41: C03 | E41: Transformación de la madera y fabricación de productos de madera y de corcho, excepto muebles; fabricación de artículos de cestería y espartería; fabricación de papel, cartón y productos de papel y de cartón; actividades de impresión; producción de copias a partir de grabaciones originales | F41: 4590 | G41: 4917 | H41: 5249 | I41: 5345 | J41: 5274 | K41: 5406 | L41: 5541 | M41: 5671 | N41: 5660 | O41: 5782 | P41: 6057 | Q41: 6414 | R41: 6404 | S41: 6431 | T41: 6389 | U41: 5921 | V41: 6192 | W41: 6689 | X41: 6656 | Y41: 6641.05
D42: 040 | E42: Transformación de la madera y fabricación de productos de madera y de corcho, excepto muebles; fabricación de artículos de cestería y espartería | F42: 1002 | G42: 1093 | H42: 1210 | I42: 1162 | J42: 1056 | K42: 1052 | L42: 1027 | M42: 1009 | N42: 1032 | O42: 1059 | P42: 1137 | Q42: 1161 | R42: 1121 | S42: 1028 | T42: 965 | U42: 884 | V42: 921 | W42: 1086 | X42: 955 | Y42: 888.78
D43: 041 | E43: Fabricación de papel, cartón y productos de papel y de cartón | F43: 2181 | G43: 2355 | H43: 2481 | I43: 2581 | J43: 2589 | K43: 2769 | L43: 2881 | M43: 2989 | N43: 2995 | O43: 3131 | P43: 3219 | Q43: 3468 | R43: 3567 | S43: 3707 | T43: 3769 | U43: 3525 | V43: 3621 | W43: 3797 | X43: 3888 | Y43: 3917.22
D44: 042 | E44: Actividades de impresión; producción de copias a partir de grabaciones originales (Copia a partir de un original en CD, DVD, Bluray) | F44: 1442 | G44: 1500 | H44: 1608 | I44: 1632 | J44: 1651 | K44: 1578 | L44: 1627 | M44: 1673 | N44: 1633 | O44: 1603 | P44: 1701 | Q44: 1785 | R44: 1722 | S44: 1706 | T44: 1666 | U44: 1519 | V44: 1669 | W44: 1849 | X44: 1813 | Y44: 1827.33
C45: C04 | E45: Coquización, fabricación de productos de la refinación del petróleo y actividad de mezcla de combustibles; fabricación de sustancias y productos químicos; fabricación de productos farmacéuticos, sustancias químicas medicinales y productos botánicos de uso farmacéutico; fabricación de productos de caucho y de plástico; fabricación de otros productos minerales no metálicos | F45: 26681 | G45: 28964 | H45: 30971 | I45: 31407 | J45: 30481 | K45: 30822 | L45: 32688 | M45: 32768 | N45: 33774 | O45: 34786 | P45: 35555 | Q45: 37081 | R45: 37118 | S45: 37535 | T45: 37685 | U45: 33901 | V45: 38222 | W45: 40657 | X45: 40114 | Y45: 38706.5
D46: 043, 044 | E46: Coquización, fabricación de productos de la refinación del petróleo y actividades de mezcla de combustibles | F46: 7974 | G46: 8211 | H46: 8477 | I46: 8483 | J46: 8266 | K46: 8555 | L46: 8677 | M46: 8332 | N46: 8860 | O46: 8147 | P46: 7761 | Q46: 9223 | R46: 9836 | S46: 10282 | T46: 10214 | U46: 9036 | V46: 10625 | W46: 11170 | X46: 11961 | Y46: 11540.04
...

Sheet Deflactores
B1: 2005 | C1: 2006 | D1: 2007 | E1: 2008 | F1: 2009 | G1: 2010 | H1: 2011 | I1: 2012 | J1: 2013 | K1: 2014 | L1: 2015 | M1: 2016 | N1: 2017 | O1: 2018 | P1: 2019 | Q1: 2020 | R1: 2021 | S1: 2022 | T1: 2023p | U1: 2024pr
A2: Agricultura, ganadería, caza, silvicultura y pesca | B2: =+'Cuadro 1'!F14/'Cuadro 2'!F13*100 -> 67.105437 | C2: =+'Cuadro 1'!G14/'Cuadro 2'!G13*100 -> 70.834517 | D2: =+'Cuadro 1'!H14/'Cuadro 2'!H13*100 -> 73.846269 | E2: =+'Cuadro 1'!I14/'Cuadro 2'!I13*100 -> 79.842165 | F2: =+'Cuadro 1'!J14/'Cuadro 2'!J13*100 -> 84.259957 | G2: =+'Cuadro 1'!K14/'Cuadro 2'!K13*100 -> 86.150264 | H2: =+'Cuadro 1'!L14/'Cuadro 2'!L13*100 -> 92.637449 | I2: =+'Cuadro 1'!M14/'Cuadro 2'!M13*100 -> 89.176753 | ... U2: =+'Cuadro 1'!Y14/'Cuadro 2'!Y13*100 -> 251.19409
A3: Agricultura, ganadería, caza, silvicultura y pesca | B3: =+'Cuadro 1'!F15/'Cuadro 2'!F14*100 -> 67.105437 | C3: =+'Cuadro 1'!G15/'Cuadro 2'!G14*100 -> 70.834517 | D3: =+'Cuadro 1'!H15/'Cuadro 2'!H14*100 -> 73.846269 | E3: =+'Cuadro 1'!I15/'Cuadro 2'!I14*100 -> 79.842165 | F3: =+'Cuadro 1'!J15/'Cuadro 2'!J14*100 -> 84.259957 | G3: =+'Cuadro 1'!K15/'Cuadro 2'!K14*100 -> 86.150264 | H3: =+'Cuadro 1'!L15/'Cuadro 2'!L14*100 -> 92.637449 | I3: =+'Cuadro 1'!M15/'Cuadro 2'!M14*100 -> 89.176753 | ... U3: =+'Cuadro 1'!Y15/'Cuadro 2'!Y14*100 -> 251.19408
A4: Cultivos agrícolas transitorios; otros cultivos agrícolas permanentes; Propagación de plantas (actividades de viveros, excepto viveros forestales); actividades de apoyo a la agricultura y la ganadería, y posteriores a la cosecha, explotación mixta (agrícola y pecuaria) y caza ordinaria y mediante trampas y actividades de servicios conexas | B4: =+'Cuadro 1'!F16/'Cuadro 2'!F15*100 -> 60.94122 | C4: =+'Cuadro 1'!G16/'Cuadro 2'!G15*100 -> 66.685075 | D4: =+'Cuadro 1'!H16/'Cuadro 2'!H15*100 -> 69.26646 | E4: =+'Cuadro 1'!I16/'Cuadro 2'!I15*100 -> 76.941134 | F4: =+'Cuadro 1'!J16/'Cuadro 2'!J15*100 -> 80.320902 | G4: =+'Cuadro 1'!K16/'Cuadro 2'!K15*100 -> 81.585969 | H4: =+'Cuadro 1'!L16/'Cuadro 2'!L15*100 -> 88.408142 | I4: =+'Cuadro 1'!M16/'Cuadro 2'!M15*100 -> 84.794187 | ... U4: =+'Cuadro 1'!Y16/'Cuadro 2'!Y15*100 -> 265.0874
A5: Cultivo permanente de café | B5: =+'Cuadro 1'!F17/'Cuadro 2'!F16*100 -> 71.859558 | C5: =+'Cuadro 1'!G17/'Cuadro 2'!G16*100 -> 73.176017 | D5: =+'Cuadro 1'!H17/'Cuadro 2'!H16*100 -> 73.685424 | E5: =+'Cuadro 1'!I17/'Cuadro 2'!I16*100 -> 79.053374 | F5: =+'Cuadro 1'!J17/'Cuadro 2'!J16*100 -> 97.390737 | G5: =+'Cuadro 1'!K17/'Cuadro 2'!K16*100 -> 111.56662 | H5: =+'Cuadro 1'!L17/'Cuadro 2'!L16*100 -> 142.08679 | I5: =+'Cuadro 1'!M17/'Cuadro 2'!M16*100 -> 106.13177 | ... U5: =+'Cuadro 1'!Y17/'Cuadro 2'!Y16*100 -> 360.0117
A6: Ganadería | B6: =+'Cuadro 1'!F18/'Cuadro 2'!F17*100 -> 79.56782 | C6: =+'Cuadro 1'!G18/'Cuadro 2'!G17*100 -> 80.060364 | D6: =+'Cuadro 1'!H18/'Cuadro 2'!H17*100 -> 85.046553 | E6: =+'Cuadro 1'!I18/'Cuadro 2'!I17*100 -> 88.960392 | F6: =+'Cuadro 1'!J18/'Cuadro 2'!J17*100 -> 91.333212 | G6: =+'Cuadro 1'!K18/'Cuadro 2'!K17*100 -> 91.093377 | H6: =+'Cuadro 1'!L18/'Cuadro 2'!L17*100 -> 91.575608 | I6: =+'Cuadro 1'!M18/'Cuadro 2'!M17*100 -> 95.185376 | ... U6: =+'Cuadro 1'!Y18/'Cuadro 2'!Y17*100 -> 193.90279
A7: Silvicultura y extracción de madera | B7: =+'Cuadro 1'!F19/'Cuadro 2'!F18*100 -> 64.114114 | C7: =+'Cuadro 1'!G19/'Cuadro 2'!G18*100 -> 67.727609 | D7: =+'Cuadro 1'!H19/'Cuadro 2'!H18*100 -> 72.035139 | E7: =+'Cuadro 1'!I19/'Cuadro 2'!I18*100 -> 73.957571 | F7: =+'Cuadro 1'!J19/'Cuadro 2'!J18*100 -> 79.555237 | G7: =+'Cuadro 1'!K19/'Cuadro 2'!K18*100 -> 79.198876 | H7: =+'Cuadro 1'!L19/'Cuadro 2'!L18*100 -> 80.120482 | I7: =+'Cuadro 1'!M19/'Cuadro 2'!M18*100 -> 84.871312 | ... U7: =+'Cuadro 1'!Y19/'Cuadro 2'!Y18*100 -> 186.72386
A8: Pesca y acuicultura | B8: =+'Cuadro 1'!F20/'Cuadro 2'!F19*100 -> 53.27476 | C8: =+'Cuadro 1'!G20/'Cuadro 2'!G19*100 -> 56.315007 | D8: =+'Cuadro 1'!H20/'Cuadro 2'!H19*100 -> 57.524613 | E8: =+'Cuadro 1'!I20/'Cuadro 2'!I19*100 -> 59.037801 | F8: =+'Cuadro 1'!J20/'Cuadro 2'!J19*100 -> 64.782609 | G8: =+'Cuadro 1'!K20/'Cuadro 2'!K19*100 -> 65.731167 | H8: =+'Cuadro 1'!L20/'Cuadro 2'!L19*100 -> 66.74025 | I8: =+'Cuadro 1'!M20/'Cuadro 2'!M19*100 -> 69.323843 | ... U8: =+'Cuadro 1'!Y20/'Cuadro 2'!Y19*100 -> 231.99153
A9: Explotación de minas y canteras | B9: =+'Cuadro 1'!F21/'Cuadro 2'!F20*100 -> 80.462997 | C9: =+'Cuadro 1'!G21/'Cuadro 2'!G20*100 -> 93.114509 | D9: =+'Cuadro 1'!H21/'Cuadro 2'!H20*100 -> 92.99782 | E9: =+'Cuadro 1'!I21/'Cuadro 2'!I20*100 -> 124.35291 | F9: =+'Cuadro 1'!J21/'Cuadro 2'!J20*100 -> 107.42953 | G9: =+'Cuadro 1'!K21/'Cuadro 2'!K20*100 -> 122.58308 | H9: =+'Cuadro 1'!L21/'Cuadro 2'!L20*100 -> 160.43116 | I9: =+'Cuadro 1'!M21/'Cuadro 2'!M20*100 -> 160.9086 | ... U9: =+'Cuadro 1'!Y21/'Cuadro 2'!Y20*100 -> 207.59472
A10: Explotación de minas y canteras | B10: =+'Cuadro 1'!F22/'Cuadro 2'!F21*100 -> 80.462997 | C10: =+'Cuadro 1'!G22/'Cuadro 2'!G21*100 -> 93.114509 | D10: =+'Cuadro 1'!H22/'Cuadro 2'!H21*100 -> 92.99782 | E10: =+'Cuadro 1'!I22/'Cuadro 2'!I21*100 -> 124.35291 | F10: =+'Cuadro 1'!J22/'Cuadro 2'!J21*100 -> 107.42953 | G10: =+'Cuadro 1'!K22/'Cuadro 2'!K21*100 -> 122.58308 | H10: =+'Cuadro 1'!L22/'Cuadro 2'!L21*100 -> 160.43116 | I10: =+'Cuadro 1'!M22/'Cuadro 2'!M21*100 -> 160.9086 | ... U10: =+'Cuadro 1'!Y22/'Cuadro 2'!Y21*100 -> 207.59472
A11: Extracción de carbón de piedra y lignito | B11: =+'Cuadro 1'!F23/'Cuadro 2'!F22*100 -> 80.494595 | C11: =+'Cuadro 1'!G23/'Cuadro 2'!G22*100 -> 84.243946 | D11: =+'Cuadro 1'!H23/'Cuadro 2'!H22*100 -> 77.030387 | E11: =+'Cuadro 1'!I23/'Cuadro 2'!I22*100 -> 112.30607 | F11: =+'Cuadro 1'!J23/'Cuadro 2'!J22*100 -> 113.61837 | G11: =+'Cuadro 1'!K23/'Cuadro 2'!K22*100 -> 111.65652 | H11: =+'Cuadro 1'!L23/'Cuadro 2'!L22*100 -> 127.08592 | I11: =+'Cuadro 1'!M23/'Cuadro 2'!M22*100 -> 119.2847 | ... U11: =+'Cuadro 1'!Y23/'Cuadro 2'!Y22*100 -> 275.26206
A12: Extracción de petróleo crudo y gas natural y actividades de apoyo para la extracción de petróleo y de gas natural | B12: =+'Cuadro 1'!F24/'Cuadro 2'!F23*100 -> 85.503715 | C12: =+'Cuadro 1'!G24/'Cuadro 2'!G23*100 -> 97.831281 | D12: =+'Cuadro 1'!H24/'Cuadro 2'!H23*100 -> 94.861612 | E12: =+'Cuadro 1'!I24/'Cuadro 2'!I23*100 -> 137.21805 | F12: =+'Cuadro 1'!J24/'Cuadro 2'!J23*100 -> 110.58099 | G12: =+'Cuadro 1'!K24/'Cuadro 2'!K23*100 -> 130.18541 | H12: =+'Cuadro 1'!L24/'Cuadro 2'!L23*100 -> 177.51078 | I12: =+'Cuadro 1'!M24/'Cuadro 2'!M23*100 -> 182.0046 | ... U12: =+'Cuadro 1'!Y24/'Cuadro 2'!Y23*100 -> 175.98633
A13: Extracción de minerales metalíferos | B13: =+'Cuadro 1'!F25/'Cuadro 2'!F24*100 -> 51.5516 | C13: =+'Cuadro 1'!G25/'Cuadro 2'!G24*100 -> 80.328673 | D13: =+'Cuadro 1'!H25/'Cuadro 2'!H24*100 -> 104.3036 | E13: =+'Cuadro 1'!I25/'Cuadro 2'!I24*100 -> 75.713486 | F13: =+'Cuadro 1'!J25/'Cuadro 2'!J24*100 -> 71.729756 | G13: =+'Cuadro 1'!K25/'Cuadro 2'!K24*100 -> 93.195337 | H13: =+'Cuadro 1'!L25/'Cuadro 2'!L24*100 -> 119.1535 | I13: =+'Cuadro 1'!M25/'Cuadro 2'!M24*100 -> 107.26534 | ... U13: =+'Cuadro 1'!Y25/'Cuadro 2'!Y24*100 -> 328.76536
... A107: Gasto de consumo final individual de los hogares; gasto de consumo final de las ISFLH1 | B107: =+'Cuadro 1'!F119/'Cuadro 2'!F118*100 -> 65.769726 | C107: =+'Cuadro 1'!G119/'Cuadro 2'!G118*100 -> 69.298806 | D107: =+'Cuadro 1'!H119/'Cuadro 2'!H118*100 -> 72.687667 | E107: =+'Cuadro 1'!I119/'Cuadro 2'!I118*100 -> 76.525906 | F107: =+'Cuadro 1'!J119/'Cuadro 2'!J118*100 -> 79.708331 | G107: =+'Cuadro 1'!K119/'Cuadro 2'!K118*100 -> 81.582155 | H107: =+'Cuadro 1'!L119/'Cuadro 2'!L118*100 -> 86.166578 | I107: =+'Cuadro 1'!M119/'Cuadro 2'!M118*100 -> 89.269957 | ... U107: =+'Cuadro 1'!Y119/'Cuadro 2'!Y118*100 -> 165.10551
A108: Gasto de consumo final individual de los hogares | B108: =+'Cuadro 1'!F120/'Cuadro 2'!F119*100 -> 65.76505 | C108: =+'Cuadro 1'!G120/'Cuadro 2'!G119*100 -> 69.296591 | D108: =+'Cuadro 1'!H120/'Cuadro 2'!H119*100 -> 72.683562 | E108: =+'Cuadro 1'!I120/'Cuadro 2'!I119*100 -> 76.518 | F108: =+'Cuadro 1'!J120/'Cuadro 2'!J119*100 -> 79.707179 | G108: =+'Cuadro 1'!K120/'Cuadro 2'!K119*100 -> 81.58149 | H108: =+'Cuadro 1'!L120/'Cuadro 2'!L119*100 -> 86.174268 | I108: =+'Cuadro 1'!M120/'Cuadro 2'!M119*100 -> 89.279194 | ... T108: =+'Cuadro 1'!X120/'Cuadro 2'!X119*100 -> 156.78763
A109: Gasto de consumo final de las ISFLH | B109: =+'Cuadro 1'!F121/'Cuadro 2'!F120*100 -> 67.226219 | C109: =+'Cuadro 1'!G121/'Cuadro 2'!G120*100 -> 70.119803 | D109: =+'Cuadro 1'!H121/'Cuadro 2'!H120*100 -> 74.014221 | E109: =+'Cuadro 1'!I121/'Cuadro 2'!I120*100 -> 78.8761 | F109: =+'Cuadro 1'!J121/'Cuadro 2'!J120*100 -> 80.474041 | G109: =+'Cuadro 1'!K121/'Cuadro 2'!K120*100 -> 82.215122 | H109: =+'Cuadro 1'!L121/'Cuadro 2'!L120*100 -> 85.037175 | I109: =+'Cuadro 1'!M121/'Cuadro 2'!M120*100 -> 87.82921 | ... T109: =+'Cuadro 1'!X121/'Cuadro 2'!X120*100 -> 169.57658
A110: Gasto de consumo final del gobierno general | B110: =+'Cuadro 1'!F122/'Cuadro 2'!F121*100 -> 67.020959 | C110: =+'Cuadro 1'!G122/'Cuadro 2'!G121*100 -> 71.537194 | D110: =+'Cuadro 1'!H122/'Cuadro 2'!H121*100 -> 75.986413 | E110: =+'Cuadro 1'!I122/'Cuadro 2'!I121*100 -> 77.269812 | F110: =+'Cuadro 1'!J122/'Cuadro 2'!J121*100 -> 81.528407 | G110: =+'Cuadro 1'!K122/'Cuadro 2'!K121*100 -> 83.775164 | H110: =+'Cuadro 1'!L122/'Cuadro 2'!L121*100 -> 86.846171 | I110: =+'Cuadro 1'!M122/'Cuadro 2'!M121*100 -> 90.062672 | ... U110: =+'Cuadro 1'!Y122/'Cuadro 2'!Y121*100 -> 158.8249
A111: Formación bruta de capital | B111: =+'Cuadro 1'!F124/'Cuadro 2'!F123*100 -> 84.39691 | C111: =+'Cuadro 1'!G124/'Cuadro 2'!G123*100 -> 86.32316 | D111: =+'Cuadro 1'!H124/'Cuadro 2'!H123*100 -> 85.589828 | E111: =+'Cuadro 1'!I124/'Cuadro 2'!I123*100 -> 88.252791 | F111: =+'Cuadro 1'!J124/'Cuadro 2'!J123*100 -> 91.883425 | G111: =+'Cuadro 1'!K124/'Cuadro 2'!K123*100 -> 90.559151 | H111: =+'Cuadro 1'!L124/'Cuadro 2'!L123*100 -> 91.335369 | I111: =+'Cuadro 1'!M124/'Cuadro 2'!M123*100 -> 91.879065 | ... U111: =+'Cuadro 1'!Y124/'Cuadro 2'!Y123*100 -> 163.76937
A112: Formación bruta de capital fijo | B112: =+'Cuadro 1'!F125/'Cuadro 2'!F124*100 -> 82.411739 | C112: =+'Cuadro 1'!G125/'Cuadro 2'!G124*100 -> 84.409719 | D112: =+'Cuadro 1'!H125/'Cuadro 2'!H124*100 -> 84.310265 | E112: =+'Cuadro 1'!I125/'Cuadro 2'!I124*100 -> 87.720286 | F112: =+'Cuadro 1'!J125/'Cuadro 2'!J124*100 -> 91.344066 | G112: =+'Cuadro 1'!K125/'Cuadro 2'!K124*100 -> 90.042721 | H112: =+'Cuadro 1'!L125/'Cuadro 2'!L124*100 -> 90.773081 | I112: =+'Cuadro 1'!M125/'Cuadro 2'!M124*100 -> 91.17051 | ... U112: =+'Cuadro 1'!Y125/'Cuadro 2'!Y124*100 -> 164.66692
A113: Vivienda | B113: =+'Cuadro 1'!F126/'Cuadro 2'!F125*100 -> 39.136454 | C113: =+'Cuadro 1'!G126/'Cuadro 2'!G125*100 -> 40.552065 | D113: =+'Cuadro 1'!H126/'Cuadro 2'!H125*100 -> 44.630346 | E113: =+'Cuadro 1'!I126/'Cuadro 2'!I125*100 -> 52.983633 | F113: =+'Cuadro 1'!J126/'Cuadro 2'!J125*100 -> 59.100385 | G113: =+'Cuadro 1'!K126/'Cuadro 2'!K125*100 -> 61.890802 | H113: =+'Cuadro 1'!L126/'Cuadro 2'!L125*100 -> 67.627937 | I113: =+'Cuadro 1'!M126/'Cuadro 2'!M125*100 -> 83.906734 | ... U113: =+'Cuadro 1'!Y126/'Cuadro 2'!Y125*100 -> 189.10296
A114: Otros edificios y estructuras | B114: =+'Cuadro 1'!F127/'Cuadro 2'!F126*100 -> 69.320122 | C114: =+'Cuadro 1'!G127/'Cuadro 2'!G126*100 -> 72.000927 | D114: =+'Cuadro 1'!H127/'Cuadro 2'!H126*100 -> 76.324585 | E114: =+'Cuadro 1'!I127/'Cuadro 2'!I126*100 -> 84.747932 | F114: =+'Cuadro 1'!J127/'Cuadro 2'!J126*100 -> 86.321071 | G114: =+'Cuadro 1'!K127/'Cuadro 2'!K126*100 -> 86.625817 | H114: =+'Cuadro 1'!L127/'Cuadro 2'!L126*100 -> 90.700488 | I114: =+'Cuadro 1'!M127/'Cuadro 2'!M126*100 -> 90.039796 | ... U114: =+'Cuadro 1'!Y127/'Cuadro 2'!Y126*100 -> 161.87579
A115: Maquinaria y equipo; sistemas de armamento | B115: =+'Cuadro 1'!F128/'Cuadro 2'!F127*100 -> 124.94509 | C115: =+'Cuadro 1'!G128/'Cuadro 2'!G127*100 -> 126.24565 | D115: =+'Cuadro 1'!H128/'Cuadro 2'!H127*100 -> 116.65225 | E115: =+'Cuadro 1'!I128/'Cuadro 2'!I127*100 -> 109.27932 | F115: =+'Cuadro 1'!J128/'Cuadro 2'!J127*100 -> 112.96282 | G115: =+'Cuadro 1'!K128/'Cuadro 2'!K127*100 -> 105.49986 | H115: =+'Cuadro 1'!L128/'Cuadro 2'!L127*100 -> 99.114761 | I115: =+'Cuadro 1'!M128/'Cuadro 2'!M127*100 -> 93.211533 | ... U115: =+'Cuadro 1'!Y128/'Cuadro 2'!Y127*100 -> 139.48016
A116: Recursos biológicos cultivados | B116: =+'Cuadro 1'!F129/'Cuadro 2'!F128*100 -> 65.560166 | C116: =+'Cuadro 1'!G129/'Cuadro 2'!G128*100 -> 65.191003 | D116: =+'Cuadro 1'!H129/'Cuadro 2'!H128*100 -> 72.900901 | E116: =+'Cuadro 1'!I129/'Cuadro 2'!I128*100 -> 85.729462 | F116: =+'Cuadro 1'!J129/'Cuadro 2'!J128*100 -> 96.318212 | G116: =+'Cuadro 1'!K129/'Cuadro 2'!K128*100 -> 98.688839 | H116: =+'Cuadro 1'!L129/'Cuadro 2'!L128*100 -> 97.699166 | I116: =+'Cuadro 1'!M129/'Cuadro 2'!M128*100 -> 88.685575 | ... U116: =+'Cuadro 1'!Y129/'Cuadro 2'!Y128*100 -> 405.69507
A117: Productos de propiedad intelectual | B117: =+'Cuadro 1'!F130/'Cuadro 2'!F129*100 -> 89.271109 | C117: =+'Cuadro 1'!G130/'Cuadro 2'!G129*100 -> 93.348683 | D117: =+'Cuadro 1'!H130/'Cuadro 2'!H129*100 -> 88.257576 | E117: =+'Cuadro 1'!I130/'Cuadro 2'!I129*100 -> 102.87798 | F117: =+'Cuadro 1'!J130/'Cuadro 2'!J129*100 -> 101.80213 | G117: =+'Cuadro 1'!K130/'Cuadro 2'!K129*100 -> 108.57671 | H117: =+'Cuadro 1'!L130/'Cuadro 2'!L129*100 -> 120.12424 | I117: =+'Cuadro 1'!M130/'Cuadro 2'!M129*100 -> 109.53534 | ... U117: =+'Cuadro 1'!Y130/'Cuadro 2'!Y129*100 -> 167.28349
A118: Variación de existencias2
A119: Adquisición menos disposición de objetos valiosos | B119: =+'Cuadro 1'!F132/'Cuadro 2'!F131*100 -> 142.85714 | C119: =+'Cuadro 1'!G132/'Cuadro 2'!G131*100 -> 125 | D119: =+'Cuadro 1'!H132/'Cuadro 2'!H131*100 -> 116.66667 | E119: =+'Cuadro 1'!I132/'Cuadro 2'!I131*100 -> 105.26316 | F119: =+'Cuadro 1'!J132/'Cuadro 2'!J131*100 -> 110.52632 | G119: =+'Cuadro 1'!K132/'Cuadro 2'!K131*100 -> 100 | H119: =+'Cuadro 1'!L132/'Cuadro 2'!L131*100 -> 91.304348 | I119: =+'Cuadro 1'!M132/'Cuadro 2'!M131*100 -> 92 | ... T119: =+'Cuadro 1'!X132/'Cuadro 2'!X131*100 -> 120.83333
A120: Exportaciones | B120: =+'Cuadro 1'!F133/'Cuadro 2'!F132*100 -> 65.083688 | C120: =+'Cuadro 1'!G133/'Cuadro 2'!G132*100 -> 70.097293 | D120: =+'Cuadro 1'!H133/'Cuadro 2'!H132*100 -> 68.68879 | E120: =+'Cuadro 1'!I133/'Cuadro 2'!I132*100 -> 82.503537 | F120: =+'Cuadro 1'!J133/'Cuadro 2'!J132*100 -> 83.080538 | G120: =+'Cuadro 1'!K133/'Cuadro 2'!K132*100 -> 87.847198 | H120: =+'Cuadro 1'!L133/'Cuadro 2'!L132*100 -> 105.0331 | I120: =+'Cuadro 1'!M133/'Cuadro 2'!M132*100 -> 105.63485 | ... U120: =+'Cuadro 1'!Y133/'Cuadro 2'!Y132*100 -> 194.4136
A121: Importaciones | B121: =+'Cuadro 1'!F134/'Cuadro 2'!F133*100 -> 87.815724 | C121: =+'Cuadro 1'!G134/'Cuadro 2'!G133*100 -> 90.278003 | D121: =+'Cuadro 1'!H134/'Cuadro 2'!H133*100 -> 83.968481 | E121: =+'Cuadro 1'!I134/'Cuadro 2'!I133*100 -> 84.574737 | F121: =+'Cuadro 1'!J134/'Cuadro 2'!J133*100 -> 86.676507 | G121: =+'Cuadro 1'!K134/'Cuadro 2'!K133*100 -> 81.17269 | H121: =+'Cuadro 1'!L134/'Cuadro 2'!L133*100 -> 86.546983 | I121: =+'Cuadro 1'!M134/'Cuadro 2'!M133*100 -> 84.481285 | ... U121: =+'Cuadro 1'!Y134/'Cuadro 2'!Y133*100 -> 149.45702
A122: Producto interno bruto | B122: =+'Cuadro 1'!F135/'Cuadro 2'!F134*100 -> 65.641649 | C122: =+'Cuadro 1'!G135/'Cuadro 2'!G134*100 -> 69.453894 | D122: =+'Cuadro 1'!H135/'Cuadro 2'!H134*100 -> 73.066909 | E122: =+'Cuadro 1'!I135/'Cuadro 2'!I134*100 -> 78.676535 | F122: =+'Cuadro 1'!J135/'Cuadro 2'!J134*100 -> 81.874127 | G122: =+'Cuadro 1'!K135/'Cuadro 2'!K134*100 -> 84.989323 | H122: =+'Cuadro 1'!L135/'Cuadro 2'!L134*100 -> 90.417424 | I122: =+'Cuadro 1'!M135/'Cuadro 2'!M134*100 -> 93.68751 | ... U122: =+'Cuadro 1'!Y135/'Cuadro 2'!Y134*100 -> 171.46078
