Workbook
Name Fin_Lateral: '[1]CI_Tv (65-2007K)'!$D$123
Name Fin_Registro: '[1]CI_Tv (65-2007K)'!$AW$123
Name Fin_Superior: '[1]CI_Tv (65-2007K)'!$AW$6
Name Ini_Lateral: '[1]CI_Tv (65-2007K)'!$D$8
Name Ini_Registro: '[1]CI_Tv (65-2007K)'!$E$8
Name Ini_Superior: '[1]CI_Tv (65-2007K)'!$E$6
Name Titulo: '[1]CI_Tv (65-2007K)'!$A$2

Sheet VAB corriente
A10: Millones de USD
A11: corrientes y a precios del año anterior
A13: CIIU | B13: COD. | C13: Industria | D13: 2018 | E13: 2019 | F13: 2020 | G13: 2021 | H13: 2022 | I13: 2023 (p)
A14: A -Agricultura, ganadería y silvicultura | B14: 01 | C14: Cultivo de cereales (excepto arroz), legumbres y semillas oleaginosas | D14: 389.928 | E14: 410.649 | F14: 384.715 | G14: 432.45 | H14: 463.245 | I14: 477.309
B15: 02 | C15: Cultivo de arroz | D15: 120.352 | E15: 123.794 | F15: 133.43 | G15: 98.774 | H15: 119.297 | I15: 162.028
B16: 03 | C16: Cultivo de hortalizas y melones, raíces y tubérculos | D16: 450.101 | E16: 467.223 | F16: 440.726 | G16: 478.945 | H16: 450.892 | I16: 539.878
B17: 04 | C17: Cultivo de caña de azúcar | D17: 82.613 | E17: 100.484 | F17: 85.863 | G17: 86.843 | H17: 80.554 | I17: 88.155
B18: 05 | C18: Cultivos de frutas, y otros tipos de cultivos n.c.p. | D18: 2590.387 | E18: 2614.194 | F18: 2679.495 | G18: 2620.144 | H18: 2556.121 | I18: 3095.126
B19: 06 | C19: Cultivo de otras plantas no perennes y propagación de plantas | D19: 767.842 | E19: 807.362 | F19: 715.609 | G19: 756.86 | H19: 782.175 | I19: 839.447
B20: 07 | C20: Cultivo de frutos oleaginosos | D20: 138.994 | E20: 136.455 | F20: 147.37 | G20: 205.917 | H20: 221.222 | I20: 228.719
B21: 08 | C21: Cultivo de plantas con las que se preparan bebidas | D21: 512.599 | E21: 514.474 | F21: 614.787 | G21: 622.111 | H21: 674.315 | I21: 926.109
B22: 09 | C22: Actividades de apoyo a la agricultura, poscosecha y tratamiento de semillas para propagación | D22: 370.692 | E22: 379.306 | F22: 357.402 | G22: 387.355 | H22: 371.919 | I22: 377.081
B23: 10 | C23: Ganadería | D23: 1022.501 | E23: 1064.623 | F23: 961.863 | G23: 1060.096 | H23: 1114.543 | I23: 1269.668
B24: 11 | C24: Silvicultura y extracción de madera | D24: 443.87 | E24: 391.536 | F24: 284.443 | G24: 316.332 | H24: 284.486 | I24: 270.397
B25: Total A -Agricultura, ganadería y silvicultura | D25: 6889.879 | E25: 7010.1 | F25: 6805.703 | G25: 7065.827 | H25: 7118.769 | I25: 8273.917
A26: A -Pesca y acuicultura | B26: 12 | C26: Pesca y acuicultura | D26: 1326.952 | E26: 1368.134 | F26: 1233.335 | G26: 1594.242 | H26: 1466.999 | I26: 1412.364
B27: Total A -Pesca y acuicultura | D27: 1326.952 | E27: 1368.134 | F27: 1233.335 | G27: 1594.242 | H27: 1466.999 | I27: 1412.364
A28: B -Explotación de minas y canteras | B28: 13 | C28: Servicios Petroleros - Explotación de otras minas y canteras, y actividades de apoyo | D28: 2565.542 | E28: 2498.162 | F28: 1682.067 | G28: 2633.41 | H28: 3113.294 | I28: 2680.461
B29: 14 | C29: Extracción de petróleo crudo y gas natural | D29: 5568.552 | E29: 5053.099 | F29: 2739.447 | G29: 4965.936 | H29: 7420.29 | I29: 5332.472
B30: 15 | C30: Extracción de minerales metalíferos | D30: 215.488 | E30: 238.804 | F30: 611.132 | G30: 1310.685 | H30: 1603.658 | I30: 1963.998
B31: 16 | C31: Explotación de otras minas y canteras, y actividades de apoyo | D31: 132.209 | E31: 121.577 | F31: 98.322 | G31: 117.367 | H31: 97.667 | I31: 128.282
B32: Total B -Explotación de minas y canteras | D32: 8481.791 | E32: 7911.642 | F32: 5130.968 | G32: 9027.398 | H32: 12234.909 | I32: 10105.213
A33: C -Manufactura de productos alimenticios | B33: 17 | C33: Elaboración y conservación de carne | D33: 993.327 | E33: 1026.593 | F33: 959.845 | G33: 1025.37 | H33: 1049.197 | I33: 1107.333
B34: 18 | C34: Preparación y conservación de pescado y otros productos acuaticos elaborados | D34: 474.222 | E34: 498.267 | F34: 567.703 | G34: 521.199 | H34: 565.837 | I34: 622.15
B35: 19 | C35: Procesamiento y conservación de camarón | D35: 1162.561 | E35: 1300.041 | F35: 1496.332 | G35: 1895.38 | H35: 2941.946 | I35: 2994.151
B36: 20 | C36: Elaboración de aceites y grasas de origen vegetal y animal | D36: 364.376 | E36: 321.479 | F36: 289.755 | G36: 311.051 | H36: 404.086 | I36: 388.181
B37: 21 | C37: Elaboración de productos lácteos | D37: 713.935 | E37: 629.521 | F37: 575.822 | G37: 582.972 | H37: 541.334 | I37: 635.847
B38: 22 | C38: Elaboración de productos de la panadería y pastelería | D38: 324.015 | E38: 319.258 | F38: 298.658 | G38: 289.205 | H38: 310.836 | I38: 370.827
B39: 23 | C39: Elaboración de productos de molinería | D39: 701.588 | E39: 710.666 | F39: 643.47 | G39: 623.053 | H39: 603.47 | I39: 732.876
B40: 24 | C40: Elaboración y refinación de azúcar | D40: 189.374 | E40: 190.931 | F40: 158.168 | G40: 183.771 | H40: 208.388 | I40: 278.514
B41: 25 | C41: Elaboración de cacao, chocolate y productos de confitería | D41: 118.725 | E41: 103.485 | F41: 76.233 | G41: 107.361 | H41: 111.351 | I41: 114.202
B42: 26 | C42: Elaboración de fideos y de otros productos farináceos | D42: 70.703 | E42: 78.507 | F42: 76.143 | G42: 68.675 | H42: 75.347 | I42: 103.818
B43: 27 | C43: Elaboración de café | D43: 63.81 | E43: 57.503 | F43: 65.71 | G43: 70.434 | H43: 69.167 | I43: 84.924
B44: 28 | C44: Elaboración de alimentos preparados para animales | D44: 308.631 | E44: 355.631 | F44: 406.439 | G44: 462.561 | H44: 486.705 | I44: 475.537
B45: 29 | C45: Elaboración de otros productos alimenticios diversos | D45: 355.337 | E45: 373.161 | F45: 390.607 | G45: 410.944 | H45: 445.267 | I45: 498.062
B46: 30 | C46: Elaboración bebidas no alcohólicas (jugos) | D46: 37.671 | E46: 31.319 | F46: 30.362 | G46: 30.391 | H46: 35.495 | I46: 40.949
B47: Total C -Manufactura de productos alimenticios | D47: 5878.275 | E47: 5996.362 | F47: 6035.247 | G47: 6582.367 | H47: 7848.426 | I47: 8447.371
A48: C -Manufactura de productos no alimenticios | B48: 31 | C48: Elaboración bebidas no alcohólicas (excepto jugos) | D48: 300.113 | E48: 256.751 | F48: 216.173 | G48: 210.665 | H48: 205.337 | I48: 248.395
B49: 32 | C49: Elaboración bebidas alcohólicas | D49: 452.426 | E49: 325.887 | F49: 241.386 | G49: 299.539 | H49: 275.399 | I49: 270.153
B50: 33 | C50: Elaboración de productos de tabaco | D50: 24.319 | E50: 18.411 | F50: 11.315 | G50: 0.891 | H50: 0 | I50: 0
...

Sheet VAB constante
A10: Millones de USD
A11: corrientes y a precios del año anterior
A13: CIIU | B13: COD. | C13: Industria | D13: 2018 | E13: 2019 a precios de 2018 | F13: 2020 a precios de 2019 | G13: 2021 a precios de 2020 | H13: 2022 a precios de 2021 | I13: 2023 a precios de 2022 (p)
A14: A -Agricultura, ganadería y silvicultura | B14: 01 | C14: Cultivo de cereales (excepto arroz), legumbres y semillas oleaginosas | D14: 389.928 | E14: 412.391 | F14: 379.674 | G14: 432.868 | H14: 422.058 | I14: 448.651
B15: 02 | C15: Cultivo de arroz | D15: 120.352 | E15: 109.533 | F15: 128.64 | G15: 141.907 | H15: 100.493 | I15: 119.134
B16: 03 | C16: Cultivo de hortalizas y melones, raíces y tubérculos | D16: 450.101 | E16: 456.314 | F16: 460.715 | G16: 495.229 | H16: 425.775 | I16: 486.051
B17: 04 | C17: Cultivo de caña de azúcar | D17: 82.613 | E17: 100.751 | F17: 97.798 | G17: 89.604 | H17: 88.051 | I17: 80.015
B18: 05 | C18: Cultivos de frutas, y otros tipos de cultivos n.c.p. | D18: 2590.387 | E18: 2535.947 | F18: 2678.692 | G18: 2728.328 | H18: 2562.134 | I18: 2653.914
B19: 06 | C19: Cultivo de otras plantas no perennes y propagación de plantas | D19: 767.842 | E19: 824.78 | F19: 751.342 | G19: 764.425 | H19: 766.155 | I19: 827.17
B20: 07 | C20: Cultivo de frutos oleaginosos | D20: 138.994 | E20: 130.291 | F20: 131.693 | G20: 160.363 | H20: 210.181 | I20: 226.002
B21: 08 | C21: Cultivo de plantas con las que se preparan bebidas | D21: 512.599 | E21: 476.267 | F21: 597.247 | G21: 636.846 | H21: 666.732 | I21: 661.633
B22: 09 | C22: Actividades de apoyo a la agricultura, poscosecha y tratamiento de semillas para propagación | D22: 370.692 | E22: 374.604 | F22: 401.103 | G22: 374.7 | H22: 401.123 | I22: 381.786
B23: 10 | C23: Ganadería | D23: 1022.501 | E23: 1039.378 | F23: 1016.193 | G23: 992.019 | H23: 1102.689 | I23: 1144.344
B24: 11 | C24: Silvicultura y extracción de madera | D24: 443.87 | E24: 389.799 | F24: 331.59 | G24: 295.856 | H24: 316.251 | I24: 296.703
B25: Total A -Agricultura, ganadería y silvicultura | D25: 6889.879 | E25: 6850.055 | F25: 6974.687 | G25: 7112.145 | H25: 7061.642 | I25: 7325.403
A26: A -Pesca y acuicultura | B26: 12 | C26: Pesca y acuicultura | D26: 1326.952 | E26: 1556.129 | F26: 1398.896 | G26: 1442.192 | H26: 1896.514 | I26: 1489.43
B27: Total A -Pesca y acuicultura | D27: 1326.952 | E27: 1556.129 | F27: 1398.896 | G27: 1442.192 | H27: 1896.514 | I27: 1489.43
A28: B -Explotación de minas y canteras | B28: 13 | C28: Servicios Petroleros - Explotación de otras minas y canteras, y actividades de apoyo | D28: 2565.542 | E28: 2186.113 | F28: 2462.9 | G28: 1849.117 | H28: 2559.914 | I28: 3011.014
B29: 14 | C29: Extracción de petróleo crudo y gas natural | D29: 5568.552 | E29: 6187.575 | F29: 4449.792 | G29: 2612.168 | H29: 4994.814 | I29: 7301.343
B30: 15 | C30: Extracción de minerales metalíferos | D30: 215.488 | E30: 236.341 | F30: 517.904 | G30: 946.451 | H30: 1633.259 | I30: 1640.323
B31: 16 | C31: Explotación de otras minas y canteras, y actividades de apoyo | D31: 132.209 | E31: 121.139 | F31: 98.959 | G31: 114.585 | H31: 120.511 | I31: 94.693
B32: Total B -Explotación de minas y canteras | D32: 8481.791 | E32: 8731.168 | F32: 7529.555 | G32: 5522.321 | H32: 9308.498 | I32: 12047.373
A33: C -Manufactura de productos alimenticios | B33: 17 | C33: Elaboración y conservación de carne | D33: 993.327 | E33: 1052.198 | F33: 968.263 | G33: 1082.375 | H33: 1090.065 | I33: 1055.427
B34: 18 | C34: Preparación y conservación de pescado y otros productos acuaticos elaborados | D34: 474.222 | E34: 518.402 | F34: 513.904 | G34: 687.383 | H34: 535.389 | I34: 545.787
B35: 19 | C35: Procesamiento y conservación de camarón | D35: 1162.561 | E35: 1458.08 | F35: 1356.209 | G35: 1656.415 | H35: 2409.39 | I35: 3059.679
B36: 20 | C36: Elaboración de aceites y grasas de origen vegetal y animal | D36: 364.376 | E36: 290.623 | F36: 300.147 | G36: 299.083 | H36: 315.842 | I36: 415.167
B37: 21 | C37: Elaboración de productos lácteos | D37: 713.935 | E37: 714.373 | F37: 570.909 | G37: 616.103 | H37: 587.752 | I37: 538.48
B38: 22 | C38: Elaboración de productos de la panadería y pastelería | D38: 324.015 | E38: 310.047 | F38: 303.5 | G38: 309.722 | H38: 312.994 | I38: 343.988
B39: 23 | C39: Elaboración de productos de molinería | D39: 701.588 | E39: 716.293 | F39: 661.706 | G39: 680.029 | H39: 608.038 | I39: 607.353
B40: 24 | C40: Elaboración y refinación de azúcar | D40: 189.374 | E40: 211.374 | F40: 174.947 | G40: 177.862 | H40: 188.484 | I40: 207.424
B41: 25 | C41: Elaboración de cacao, chocolate y productos de confitería | D41: 118.725 | E41: 116.483 | F41: 93.162 | G41: 93.948 | H41: 115.361 | I41: 115.761
B42: 26 | C42: Elaboración de fideos y de otros productos farináceos | D42: 70.703 | E42: 72.211 | F42: 73.131 | G42: 70.329 | H42: 71.229 | I42: 74.436
B43: 27 | C43: Elaboración de café | D43: 63.81 | E43: 65.527 | F43: 55.606 | G43: 78.045 | H43: 76.543 | I43: 70.764
B44: 28 | C44: Elaboración de alimentos preparados para animales | D44: 308.631 | E44: 336.338 | F44: 375.392 | G44: 518.272 | H44: 562.637 | I44: 448.058
B45: 29 | C45: Elaboración de otros productos alimenticios diversos | D45: 355.337 | E45: 351.899 | F45: 361.83 | G45: 407.296 | H45: 441.454 | I45: 433.171
B46: 30 | C46: Elaboración bebidas no alcohólicas (jugos) | D46: 37.671 | E46: 37.32 | F46: 29.241 | G46: 36.214 | H46: 30.586 | I46: 38.524
B47: Total C -Manufactura de productos alimenticios | D47: 5878.275 | E47: 6251.168 | F47: 5837.947 | G47: 6713.076 | H47: 7345.764 | I47: 7954.019
A48: C -Manufactura de productos no alimenticios | B48: 31 | C48: Elaboración bebidas no alcohólicas (excepto jugos) | D48: 300.113 | E48: 286.498 | F48: 212.262 | G48: 231.125 | H48: 219.148 | I48: 221.706
B49: 32 | C49: Elaboración bebidas alcohólicas | D49: 452.426 | E49: 347.972 | F49: 268.5 | G49: 262.105 | H49: 309.812 | I49: 277.673
B50: 33 | C50: Elaboración de productos de tabaco | D50: 24.319 | E50: 21.638 | F50: 10.379 | G50: 5.915 | H50: 0 | I50: 0
...

Sheet Deflactores
A10: Millones de USD
A11: corrientes y a precios del año anterior
A13: CIIU | B13: COD. | C13: Industria | D13: 2018 | E13: 2019 | F13: 2020 | G13: 2021 | H13: 2022 | I13: 2023 (p)
A14: A -Agricultura, ganadería y silvicultura | B14: 01 | C14: Cultivo de cereales (excepto arroz), legumbres y semillas oleaginosas | D14: =+'VAB corriente'!D14/'VAB constante'!D14*100 -> 100 | E14: =+'VAB corriente'!E14/'VAB constante'!E14*100 -> 99.577585 | F14: =+'VAB corriente'!F14/'VAB constante'!F14*100 -> 101.32772 | G14: =+'VAB corriente'!G14/'VAB constante'!G14*100 -> 99.903435 | H14: =+'VAB corriente'!H14/'VAB constante'!H14*100 -> 109.75861 | I14: =+'VAB corriente'!I14/'VAB constante'!I14*100 -> 106.38759
B15: 02 | C15: Cultivo de arroz | D15: =+'VAB corriente'!D15/'VAB constante'!D15*100 -> 100 | E15: =+'VAB corriente'!E15/'VAB constante'!E15*100 -> 113.01982 | F15: =+'VAB corriente'!F15/'VAB constante'!F15*100 -> 103.72357 | G15: =+'VAB corriente'!G15/'VAB constante'!G15*100 -> 69.604741 | H15: =+'VAB corriente'!H15/'VAB constante'!H15*100 -> 118.71175 | I15: =+'VAB corriente'!I15/'VAB constante'!I15*100 -> 136.00483
B16: 03 | C16: Cultivo de hortalizas y melones, raíces y tubérculos | D16: =+'VAB corriente'!D16/'VAB constante'!D16*100 -> 100 | E16: =+'VAB corriente'!E16/'VAB constante'!E16*100 -> 102.39068 | F16: =+'VAB corriente'!F16/'VAB constante'!F16*100 -> 95.661309 | G16: =+'VAB corriente'!G16/'VAB constante'!G16*100 -> 96.711824 | H16: =+'VAB corriente'!H16/'VAB constante'!H16*100 -> 105.89913 | I16: =+'VAB corriente'!I16/'VAB constante'!I16*100 -> 111.07435
B17: 04 | C17: Cultivo de caña de azúcar | D17: =+'VAB corriente'!D17/'VAB constante'!D17*100 -> 100 | E17: =+'VAB corriente'!E17/'VAB constante'!E17*100 -> 99.73499 | F17: =+'VAB corriente'!F17/'VAB constante'!F17*100 -> 87.796274 | G17: =+'VAB corriente'!G17/'VAB constante'!G17*100 -> 96.918664 | H17: =+'VAB corriente'!H17/'VAB constante'!H17*100 -> 91.485616 | I17: =+'VAB corriente'!I17/'VAB constante'!I17*100 -> 110.17309
B18: 05 | C18: Cultivos de frutas, y otros tipos de cultivos n.c.p. | D18: =+'VAB corriente'!D18/'VAB constante'!D18*100 -> 100 | E18: =+'VAB corriente'!E18/'VAB constante'!E18*100 -> 103.08551 | F18: =+'VAB corriente'!F18/'VAB constante'!F18*100 -> 100.02998 | G18: =+'VAB corriente'!G18/'VAB constante'!G18*100 -> 96.034788 | H18: =+'VAB corriente'!H18/'VAB constante'!H18*100 -> 99.765313 | I18: =+'VAB corriente'!I18/'VAB constante'!I18*100 -> 116.62495
B19: 06 | C19: Cultivo de otras plantas no perennes y propagación de plantas | D19: =+'VAB corriente'!D19/'VAB constante'!D19*100 -> 100 | E19: =+'VAB corriente'!E19/'VAB constante'!E19*100 -> 97.888164 | F19: =+'VAB corriente'!F19/'VAB constante'!F19*100 -> 95.24411 | G19: =+'VAB corriente'!G19/'VAB constante'!G19*100 -> 99.010367 | H19: =+'VAB corriente'!H19/'VAB constante'!H19*100 -> 102.09096 | I19: =+'VAB corriente'!I19/'VAB constante'!I19*100 -> 101.48422
B20: 07 | C20: Cultivo de frutos oleaginosos | D20: =+'VAB corriente'!D20/'VAB constante'!D20*100 -> 100 | E20: =+'VAB corriente'!E20/'VAB constante'!E20*100 -> 104.73095 | F20: =+'VAB corriente'!F20/'VAB constante'!F20*100 -> 111.9042 | G20: =+'VAB corriente'!G20/'VAB constante'!G20*100 -> 128.4068 | H20: =+'VAB corriente'!H20/'VAB constante'!H20*100 -> 105.25309 | I20: =+'VAB corriente'!I20/'VAB constante'!I20*100 -> 101.2022
B21: 08 | C21: Cultivo de plantas con las que se preparan bebidas | D21: =+'VAB corriente'!D21/'VAB constante'!D21*100 -> 100 | E21: =+'VAB corriente'!E21/'VAB constante'!E21*100 -> 108.02218 | F21: =+'VAB corriente'!F21/'VAB constante'!F21*100 -> 102.93681 | G21: =+'VAB corriente'!G21/'VAB constante'!G21*100 -> 97.686254 | H21: =+'VAB corriente'!H21/'VAB constante'!H21*100 -> 101.13734 | I21: =+'VAB corriente'!I21/'VAB constante'!I21*100 -> 139.97322
B22: 09 | C22: Actividades de apoyo a la agricultura, poscosecha y tratamiento de semillas para propagación | D22: =+'VAB corriente'!D22/'VAB constante'!D22*100 -> 100 | E22: =+'VAB corriente'!E22/'VAB constante'!E22*100 -> 101.25519 | F22: =+'VAB corriente'!F22/'VAB constante'!F22*100 -> 89.104794 | G22: =+'VAB corriente'!G22/'VAB constante'!G22*100 -> 103.37737 | H22: =+'VAB corriente'!H22/'VAB constante'!H22*100 -> 92.71944 | I22: =+'VAB corriente'!I22/'VAB constante'!I22*100 -> 98.767634
B23: 10 | C23: Ganadería | D23: =+'VAB corriente'!D23/'VAB constante'!D23*100 -> 100 | E23: =+'VAB corriente'!E23/'VAB constante'!E23*100 -> 102.42886 | F23: =+'VAB corriente'!F23/'VAB constante'!F23*100 -> 94.653575 | G23: =+'VAB corriente'!G23/'VAB constante'!G23*100 -> 106.86247 | H23: =+'VAB corriente'!H23/'VAB constante'!H23*100 -> 101.07501 | I23: =+'VAB corriente'!I23/'VAB constante'!I23*100 -> 110.9516
B24: 11 | C24: Silvicultura y extracción de madera | D24: =+'VAB corriente'!D24/'VAB constante'!D24*100 -> 100 | E24: =+'VAB corriente'!E24/'VAB constante'!E24*100 -> 100.44561 | F24: =+'VAB corriente'!F24/'VAB constante'!F24*100 -> 85.781537 | G24: =+'VAB corriente'!G24/'VAB constante'!G24*100 -> 106.92093 | H24: =+'VAB corriente'!H24/'VAB constante'!H24*100 -> 89.955763 | I24: =+'VAB corriente'!I24/'VAB constante'!I24*100 -> 91.133895
B25: Total A -Agricultura, ganadería y silvicultura | D25: =+'VAB corriente'!D25/'VAB constante'!D25*100 -> 100 | E25: =+'VAB corriente'!E25/'VAB constante'!E25*100 -> 102.3364 | F25: =+'VAB corriente'!F25/'VAB constante'!F25*100 -> 97.577182 | G25: =+'VAB corriente'!G25/'VAB constante'!G25*100 -> 99.348748 | H25: =+'VAB corriente'!H25/'VAB constante'!H25*100 -> 100.80898 | I25: =+'VAB corriente'!I25/'VAB constante'!I25*100 -> 112.94828
A26: A -Pesca y acuicultura | B26: 12 | C26: Pesca y acuicultura | D26: =+'VAB corriente'!D26/'VAB constante'!D26*100 -> 100 | E26: =+'VAB corriente'!E26/'VAB constante'!E26*100 -> 87.919061 | F26: =+'VAB corriente'!F26/'VAB constante'!F26*100 -> 88.164881 | G26: =+'VAB corriente'!G26/'VAB constante'!G26*100 -> 110.54298 | H26: =+'VAB corriente'!H26/'VAB constante'!H26*100 -> 77.352395 | I26: =+'VAB corriente'!I26/'VAB constante'!I26*100 -> 94.825806
B27: Total A -Pesca y acuicultura | D27: =+'VAB corriente'!D27/'VAB constante'!D27*100 -> 100 | E27: =+'VAB corriente'!E27/'VAB constante'!E27*100 -> 87.919061 | F27: =+'VAB corriente'!F27/'VAB constante'!F27*100 -> 88.164881 | G27: =+'VAB corriente'!G27/'VAB constante'!G27*100 -> 110.54298 | H27: =+'VAB corriente'!H27/'VAB constante'!H27*100 -> 77.352395 | I27: =+'VAB corriente'!I27/'VAB constante'!I27*100 -> 94.825806
A28: B -Explotación de minas y canteras | B28: 13 | C28: Servicios Petroleros - Explotación de otras minas y canteras, y actividades de apoyo | D28: =+'VAB corriente'!D28/'VAB constante'!D28*100 -> 100 | E28: =+'VAB corriente'!E28/'VAB constante'!E28*100 -> 114.27415 | F28: =+'VAB corriente'!F28/'VAB constante'!F28*100 -> 68.296196 | G28: =+'VAB corriente'!G28/'VAB constante'!G28*100 -> 142.41446 | H28: =+'VAB corriente'!H28/'VAB constante'!H28*100 -> 121.61713 | I28: =+'VAB corriente'!I28/'VAB constante'!I28*100 -> 89.021871
B29: 14 | C29: Extracción de petróleo crudo y gas natural | D29: =+'VAB corriente'!D29/'VAB constante'!D29*100 -> 100 | E29: =+'VAB corriente'!E29/'VAB constante'!E29*100 -> 81.665257 | F29: =+'VAB corriente'!F29/'VAB constante'!F29*100 -> 61.563484 | G29: =+'VAB corriente'!G29/'VAB constante'!G29*100 -> 190.10783 | H29: =+'VAB corriente'!H29/'VAB constante'!H29*100 -> 148.55989 | I29: =+'VAB corriente'!I29/'VAB constante'!I29*100 -> 73.034125
B30: 15 | C30: Extracción de minerales metalíferos | D30: =+'VAB corriente'!D30/'VAB constante'!D30*100 -> 100 | E30: =+'VAB corriente'!E30/'VAB constante'!E30*100 -> 101.04214 | F30: =+'VAB corriente'!F30/'VAB constante'!F30*100 -> 118.00102 | G30: =+'VAB corriente'!G30/'VAB constante'!G30*100 -> 138.48419 | H30: =+'VAB corriente'!H30/'VAB constante'!H30*100 -> 98.187611 | I30: =+'VAB corriente'!I30/'VAB constante'!I30*100 -> 119.73239
B31: 16 | C31: Explotación de otras minas y canteras, y actividades de apoyo | D31: =+'VAB corriente'!D31/'VAB constante'!D31*100 -> 100 | E31: =+'VAB corriente'!E31/'VAB constante'!E31*100 -> 100.36157 | F31: =+'VAB corriente'!F31/'VAB constante'!F31*100 -> 99.356299 | G31: =+'VAB corriente'!G31/'VAB constante'!G31*100 -> 102.42789 | H31: =+'VAB corriente'!H31/'VAB constante'!H31*100 -> 81.044054 | I31: =+'VAB corriente'!I31/'VAB constante'!I31*100 -> 135.47147
B32: Total B -Explotación de minas y canteras | D32: =+'VAB corriente'!D32/'VAB constante'!D32*100 -> 100 | E32: =+'VAB corriente'!E32/'VAB constante'!E32*100 -> 90.613787 | F32: =+'VAB corriente'!F32/'VAB constante'!F32*100 -> 68.144372 | G32: =+'VAB corriente'!G32/'VAB constante'!G32*100 -> 163.47108 | H32: =+'VAB corriente'!H32/'VAB constante'!H32*100 -> 131.43806 | I32: =+'VAB corriente'!I32/'VAB constante'!I32*100 -> 83.878975
A33: C -Manufactura de productos alimenticios | B33: 17 | C33: Elaboración y conservación de carne | D33: =+'VAB corriente'!D33/'VAB constante'!D33*100 -> 100 | E33: =+'VAB corriente'!E33/'VAB constante'!E33*100 -> 97.566523 | F33: =+'VAB corriente'!F33/'VAB constante'!F33*100 -> 99.130608 | G33: =+'VAB corriente'!G33/'VAB constante'!G33*100 -> 94.733341 | H33: =+'VAB corriente'!H33/'VAB constante'!H33*100 -> 96.250866 | I33: =+'VAB corriente'!I33/'VAB constante'!I33*100 -> 104.91801
B34: 18 | C34: Preparación y conservación de pescado y otros productos acuaticos elaborados | D34: =+'VAB corriente'!D34/'VAB constante'!D34*100 -> 100 | E34: =+'VAB corriente'!E34/'VAB constante'!E34*100 -> 96.115949 | F34: =+'VAB corriente'!F34/'VAB constante'!F34*100 -> 110.46869 | G34: =+'VAB corriente'!G34/'VAB constante'!G34*100 -> 75.823667 | H34: =+'VAB corriente'!H34/'VAB constante'!H34*100 -> 105.68708 | I34: =+'VAB corriente'!I34/'VAB constante'!I34*100 -> 113.99136
B35: 19 | C35: Procesamiento y conservación de camarón | D35: =+'VAB corriente'!D35/'VAB constante'!D35*100 -> 100 | E35: =+'VAB corriente'!E35/'VAB constante'!E35*100 -> 89.161157 | F35: =+'VAB corriente'!F35/'VAB constante'!F35*100 -> 110.33196 | G35: =+'VAB corriente'!G35/'VAB constante'!G35*100 -> 114.42664 | H35: =+'VAB corriente'!H35/'VAB constante'!H35*100 -> 122.10335 | I35: =+'VAB corriente'!I35/'VAB constante'!I35*100 -> 97.858337
B36: 20 | C36: Elaboración de aceites y grasas de origen vegetal y animal | D36: =+'VAB corriente'!D36/'VAB constante'!D36*100 -> 100 | E36: =+'VAB corriente'!E36/'VAB constante'!E36*100 -> 110.61719 | F36: =+'VAB corriente'!F36/'VAB constante'!F36*100 -> 96.537697 | G36: =+'VAB corriente'!G36/'VAB constante'!G36*100 -> 104.00156 | H36: =+'VAB corriente'!H36/'VAB constante'!H36*100 -> 127.93929 | I36: =+'VAB corriente'!I36/'VAB constante'!I36*100 -> 93.499965
B37: 21 | C37: Elaboración de productos lácteos | D37: =+'VAB corriente'!D37/'VAB constante'!D37*100 -> 100 | E37: =+'VAB corriente'!E37/'VAB constante'!E37*100 -> 88.122171 | F37: =+'VAB corriente'!F37/'VAB constante'!F37*100 -> 100.86056 | G37: =+'VAB corriente'!G37/'VAB constante'!G37*100 -> 94.62249 | H37: =+'VAB corriente'!H37/'VAB constante'!H37*100 -> 92.102451 | I37: =+'VAB corriente'!I37/'VAB constante'!I37*100 -> 118.08182
B38: 22 | C38: Elaboración de productos de la panadería y pastelería | D38: =+'VAB corriente'!D38/'VAB constante'!D38*100 -> 100 | E38: =+'VAB corriente'!E38/'VAB constante'!E38*100 -> 102.97084 | F38: =+'VAB corriente'!F38/'VAB constante'!F38*100 -> 98.404613 | G38: =+'VAB corriente'!G38/'VAB constante'!G38*100 -> 93.375672 | H38: =+'VAB corriente'!H38/'VAB constante'!H38*100 -> 99.31053 | I38: =+'VAB corriente'!I38/'VAB constante'!I38*100 -> 107.80231
B39: 23 | C39: Elaboración de productos de molinería | D39: =+'VAB corriente'!D39/'VAB constante'!D39*100 -> 100 | E39: =+'VAB corriente'!E39/'VAB constante'!E39*100 -> 99.214428 | F39: =+'VAB corriente'!F39/'VAB constante'!F39*100 -> 97.244093 | G39: =+'VAB corriente'!G39/'VAB constante'!G39*100 -> 91.621534 | H39: =+'VAB corriente'!H39/'VAB constante'!H39*100 -> 99.248731 | I39: =+'VAB corriente'!I39/'VAB constante'!I39*100 -> 120.66722
B40: 24 | C40: Elaboración y refinación de azúcar | D40: =+'VAB corriente'!D40/'VAB constante'!D40*100 -> 100 | E40: =+'VAB corriente'!E40/'VAB constante'!E40*100 -> 90.328517 | F40: =+'VAB corriente'!F40/'VAB constante'!F40*100 -> 90.409095 | G40: =+'VAB corriente'!G40/'VAB constante'!G40*100 -> 103.32224 | H40: =+'VAB corriente'!H40/'VAB constante'!H40*100 -> 110.56005 | I40: =+'VAB corriente'!I40/'VAB constante'!I40*100 -> 134.27279
B41: 25 | C41: Elaboración de cacao, chocolate y productos de confitería | D41: =+'VAB corriente'!D41/'VAB constante'!D41*100 -> 100 | E41: =+'VAB corriente'!E41/'VAB constante'!E41*100 -> 88.84129 | F41: =+'VAB corriente'!F41/'VAB constante'!F41*100 -> 81.828428 | G41: =+'VAB corriente'!G41/'VAB constante'!G41*100 -> 114.27705 | H41: =+'VAB corriente'!H41/'VAB constante'!H41*100 -> 96.523955 | I41: =+'VAB corriente'!I41/'VAB constante'!I41*100 -> 98.65326
B42: 26 | C42: Elaboración de fideos y de otros productos farináceos | D42: =+'VAB corriente'!D42/'VAB constante'!D42*100 -> 100 | E42: =+'VAB corriente'!E42/'VAB constante'!E42*100 -> 108.71889 | F42: =+'VAB corriente'!F42/'VAB constante'!F42*100 -> 104.11864 | G42: =+'VAB corriente'!G42/'VAB constante'!G42*100 -> 97.648196 | H42: =+'VAB corriente'!H42/'VAB constante'!H42*100 -> 105.78135 | I42: =+'VAB corriente'!I42/'VAB constante'!I42*100 -> 139.47284
B43: 27 | C43: Elaboración de café | D43: =+'VAB corriente'!D43/'VAB constante'!D43*100 -> 100 | E43: =+'VAB corriente'!E43/'VAB constante'!E43*100 -> 87.754666 | F43: =+'VAB corriente'!F43/'VAB constante'!F43*100 -> 118.1707 | G43: =+'VAB corriente'!G43/'VAB constante'!G43*100 -> 90.247934 | H43: =+'VAB corriente'!H43/'VAB constante'!H43*100 -> 90.363586 | I43: =+'VAB corriente'!I43/'VAB constante'!I43*100 -> 120.01017
B44: 28 | C44: Elaboración de alimentos preparados para animales | D44: =+'VAB corriente'!D44/'VAB constante'!D44*100 -> 100 | E44: =+'VAB corriente'!E44/'VAB constante'!E44*100 -> 105.73619 | F44: =+'VAB corriente'!F44/'VAB constante'!F44*100 -> 108.27055 | G44: =+'VAB corriente'!G44/'VAB constante'!G44*100 -> 89.250625 | H44: =+'VAB corriente'!H44/'VAB constante'!H44*100 -> 86.504265 | I44: =+'VAB corriente'!I44/'VAB constante'!I44*100 -> 106.13291
B45: 29 | C45: Elaboración de otros productos alimenticios diversos | D45: =+'VAB corriente'!D45/'VAB constante'!D45*100 -> 100 | E45: =+'VAB corriente'!E45/'VAB constante'!E45*100 -> 106.04207 | F45: =+'VAB corriente'!F45/'VAB constante'!F45*100 -> 107.95318 | G45: =+'VAB corriente'!G45/'VAB constante'!G45*100 -> 100.89566 | H45: =+'VAB corriente'!H45/'VAB constante'!H45*100 -> 100.86374 | I45: =+'VAB corriente'!I45/'VAB constante'!I45*100 -> 114.98046
B46: 30 | C46: Elaboración bebidas no alcohólicas (jugos) | D46: =+'VAB corriente'!D46/'VAB constante'!D46*100 -> 100 | E46: =+'VAB corriente'!E46/'VAB constante'!E46*100 -> 83.92015 | F46: =+'VAB corriente'!F46/'VAB constante'!F46*100 -> 103.83366 | G46: =+'VAB corriente'!G46/'VAB constante'!G46*100 -> 83.920583 | H46: =+'VAB corriente'!H46/'VAB constante'!H46*100 -> 116.04983 | I46: =+'VAB corriente'!I46/'VAB constante'!I46*100 -> 106.29478
B47: Total C -Manufactura de productos alimenticios | D47: =+'VAB corriente'!D47/'VAB constante'!D47*100 -> 100 | E47: =+'VAB corriente'!E47/'VAB constante'!E47*100 -> 95.923866 | F47: =+'VAB corriente'!F47/'VAB constante'!F47*100 -> 103.37961 | G47: =+'VAB corriente'!G47/'VAB constante'!G47*100 -> 98.052919 | H47: =+'VAB corriente'!H47/'VAB constante'!H47*100 -> 106.84288 | I47: =+'VAB corriente'!I47/'VAB constante'!I47*100 -> 106.20255
A48: C -Manufactura de productos no alimenticios | B48: 31 | C48: Elaboración bebidas no alcohólicas (excepto jugos) | D48: =+'VAB corriente'!D48/'VAB constante'!D48*100 -> 100 | E48: =+'VAB corriente'!E48/'VAB constante'!E48*100 -> 89.61703 | F48: =+'VAB corriente'!F48/'VAB constante'!F48*100 -> 101.84253 | G48: =+'VAB corriente'!G48/'VAB constante'!G48*100 -> 91.147647 | H48: =+'VAB corriente'!H48/'VAB constante'!H48*100 -> 93.697866 | I48: =+'VAB corriente'!I48/'VAB constante'!I48*100 -> 112.03801
B49: 32 | C49: Elaboración bebidas alcohólicas | D49: =+'VAB corriente'!D49/'VAB constante'!D49*100 -> 100 | E49: =+'VAB corriente'!E49/'VAB constante'!E49*100 -> 93.653225 | F49: =+'VAB corriente'!F49/'VAB constante'!F49*100 -> 89.901676 | G49: =+'VAB corriente'!G49/'VAB constante'!G49*100 -> 114.28206 | H49: =+'VAB corriente'!H49/'VAB constante'!H49*100 -> 88.892296 | I49: =+'VAB corriente'!I49/'VAB constante'!I49*100 -> 97.291778
B50: 33 | C50: Elaboración de productos de tabaco | D50: =+'VAB corriente'!D50/'VAB constante'!D50*100 -> 100 | E50: =+'VAB corriente'!E50/'VAB constante'!E50*100 -> 85.086422 | F50: =+'VAB corriente'!F50/'VAB constante'!F50*100 -> 109.01821 | G50: =+'VAB corriente'!G50/'VAB constante'!G50*100 -> 15.063398 | H50: =+'VAB corriente'!H50/'VAB constante'!H50*100 -> #DIV/0! | I50: =+'VAB corriente'!I50/'VAB constante'!I50*100 -> #DIV/0!
...
