Workbook
Name \a: [1]VOLORIGEN!#REF!
Name \a: [1]VOLORIGEN!#REF!
Name \b: [1]VOLORIGEN!#REF!
Name \b: [1]VOLORIGEN!#REF!
Name \c: #N/A
Name \e: #N/A
Name \g: #N/A
Name \h: #N/A
Name \k: #N/A
Name \m: #N/A
Name \o: #N/A
Name \p: #N/A
Name \r: #N/A
Name \t: #N/A
Name \v: #N/A
Name __DES10: #N/A
Name __R: #N/A
Name __VAR10: #N/A
Name __VAR92: #N/A
Name _A: #N/A
Name _DES10: #N/A
Name _H: #N/A
Name _R: #N/A
Name _VAR10: #N/A
Name _VAR92: #N/A
Name A_IMPRESIÓN_IM: [1]VOLORIGEN!#REF!
Name A_IMPRESIÓN_IM: [1]VOLORIGEN!#REF!
Name actual: #REF!
Name actual: #REF!
Name actual8: #REF!
Name actual8: #REF!
Name AGENERAR: [1]VOLORIGEN!#REF!
Name AGENERAR: [1]VOLORIGEN!#REF!
Name AMESES: #N/A
Name Área_de_impresión8: #REF!
Name Área_de_impresión8: #REF!
Name CEI_impresionç: #REF!
Name CODIGO: [1]VOLORIGEN!#REF!
Name CODIGO: [1]VOLORIGEN!#REF!
Name COMER: #N/A
Name COMER1: #N/A
Name CONSTA: #N/A
Name CONTINENTAL: #REF!
Name CONTINENTAL: #REF!
Name CONTINENTAL8: #REF!
Name CONTINENTAL8: #REF!
Name CORR: #N/A
Name COSECHA: #N/A
Name cuadro: [1]VOLORIGEN!#REF!
Name cuadro: [1]VOLORIGEN!#REF!
Name Datos1: #REF!,#REF!,#REF!
Name Datos1: #REF!,#REF!,#REF!
Name Datos18: #REF!,#REF!,#REF!
Name Datos18: #REF!,#REF!,#REF!
Name Datos2: #REF!,#REF!
Name Datos2: #REF!,#REF!
Name Datos28: #REF!,#REF!
Name Datos28: #REF!,#REF!
Name Datos3: #REF!,#REF!
Name Datos3: #REF!,#REF!

Sheet MillonesSoles
A2: PERÚ: PRODUCTO BRUTO INTERNO SEGÚN ACTIVIDAD ECONÓMICA (NIVEL 54), 2007-2024 Valores a precios corrientes (Millones de soles)
A4: Actividad Económica | D4: 2007 | E4: 2008 | F4: 2009 | G4: 2010 | H4: 2011 | I4: 2012 | J4: 2013 | K4: 2014 | L4: 2015 | M4: 2016 | N4: 2017 | O4: 2018 | P4: 2019 | Q4: 2020 | R4: 2021 | S4: 2022P/ | T4: 2023E/ | U4: 2024E/
A6: Producto Bruto Interno | D6: 319693 | E6: 352719 | F6: 363943 | G6: 416784 | H6: 473049 | I6: 508131 | J6: 543556 | K6: 570041 | L6: 604416 | M6: 647668 | N6: 687989 | O6: 731588 | P6: 761984 | Q6: 703915 | R6: 878281 | S6: 943706 | T6: 999447 | U6: 1085708
B8: Derechos de Importación | D8: 2831 | E8: 1768 | F8: 1405 | G8: 1789 | H8: 1254 | I8: 1449 | J8: 1708 | K8: 2133 | L8: 1719 | M8: 1587 | N8: 1375 | O8: 1383 | P8: 1380 | Q8: 1113 | R8: 1366 | S8: 1674 | T8: 1394 | U8: 1452
B9: Impuestos a los productos | D9: 23672 | E9: 26974 | F9: 28831 | G9: 33456 | H9: 36143 | I9: 42311 | J9: 46975 | K9: 49749 | L9: 50103 | M9: 51535 | N9: 53623 | O9: 56792 | P9: 61912 | Q9: 53608 | R9: 72701 | S9: 75661 | T9: 74403 | U9: 78853
B10: Valor Agregado Bruto | D10: 293190 | E10: 323977 | F10: 333707 | G10: 381539 | H10: 435652 | I10: 464371 | J10: 494873 | K10: 518159 | L10: 552594 | M10: 594546 | N10: 632991 | O10: 673413 | P10: 698692 | Q10: 649194 | R10: 804214 | S10: 866371 | T10: 923650 | U10: 1005403
B11: Agricultura, ganadería, caza y silvicultura | D11: 19074 | E11: 22904 | F11: 24421 | G11: 25870 | H11: 29803 | I11: 31913 | J11: 32820 | K11: 36284 | L11: 38962 | M11: 41592 | N11: 42968 | O11: 44683 | P11: 47363 | Q11: 49048 | R11: 55951 | S11: 61563 | T11: 67452 | U11: 73880
B12: Pesca y acuicultura | D12: 2364 | E12: 2354 | F12: 2525 | G12: 2588 | H12: 3784 | I12: 2260 | J12: 3426 | K12: 2503 | L12: 3623 | M12: 3324 | N12: 3676 | O12: 5693 | P12: 4856 | Q12: 5265 | R12: 6606 | S12: 6140 | T12: 4913 | U12: 5783
B13: Extracción de petróleo, gas, minerales y servicios conexos | D13: 45892 | E13: 44419 | F13: 38026 | G13: 51157 | H13: 69294 | I13: 61782 | J13: 56620 | K13: 49761 | L13: 45244 | M13: 53112 | N13: 64714 | O13: 67705 | P13: 63036 | Q13: 59839 | R13: 120605 | S13: 117801 | T13: 115087 | U13: 132895
C14: Extracción de petróleo crudo, gas natural y servicios conexos | D14: 7101 | E14: 8830 | F14: 5992 | G14: 9150 | H14: 14434 | I14: 13131 | J14: 12388 | K14: 10672 | L14: 4263 | M14: 3278 | N14: 4843 | O14: 8202 | P14: 5271 | Q14: 2756 | R14: 13647 | S14: 20831 | T14: 12385 | U14: …
C15: Extracción de minerales y servicios conexos | D15: 38791 | E15: 35589 | F15: 32034 | G15: 42007 | H15: 54860 | I15: 48651 | J15: 44232 | K15: 39089 | L15: 40981 | M15: 49834 | N15: 59871 | O15: 59503 | P15: 57765 | Q15: 57083 | R15: 106958 | S15: 96970 | T15: 102702 | U15: …
B16: Manufactura | D16: 52807 | E16: 57481 | F16: 55658 | G16: 64837 | H16: 71390 | I16: 77055 | J16: 80617 | K16: 79576 | L16: 83337 | M16: 86425 | N16: 89238 | O16: 96343 | P16: 97910 | Q16: 86248 | R16: 105972 | S16: 116968 | T16: 126123 | U16: 131523
C17: Procesamiento y conservación de carnes | D17: 1347 | E17: 1640 | F17: 1893 | G17: 2047 | H17: 2117 | I17: 2421 | J17: 2760 | K17: 3071 | L17: 3295 | M17: 3465 | N17: 3539 | O17: 3477 | P17: 3345 | Q17: 2696 | R17: 2298 | S17: 4740 | T17: 5381 | U17: …
C18: Elaboración y preservación de pescado | D18: 990 | E18: 1151 | F18: 1027 | G18: 921 | H18: 1576 | I18: 1531 | J18: 1574 | K18: 1722 | L18: 1611 | M18: 1486 | N18: 1308 | O18: 1350 | P18: 1927 | Q18: 1983 | R18: 1885 | S18: 1842 | T18: 2139 | U18: …
C19: Elaboración de harina y aceite de pescado | D19: 1638 | E19: 1592 | F19: 1465 | G19: 1321 | H19: 2423 | I19: 1382 | J19: 2406 | K19: 1197 | L19: 2265 | M19: 1944 | N19: 1790 | O19: 3651 | P19: 2003 | Q19: 2894 | R19: 3786 | S19: 3485 | T19: 1759 | U19: …
C20: Procesamiento y conservación de frutas y vegetales | D20: 752 | E20: 814 | F20: 701 | G20: 875 | H20: 886 | I20: 1034 | J20: 1120 | K20: 1215 | L20: 946 | M20: 1003 | N20: 1059 | O20: 1501 | P20: 1737 | Q20: 1880 | R20: 1722 | S20: 1922 | T20: 1255 | U20: …
C21: Elaboración de aceites y grasas de origen vegetal y animal | D21: 691 | E21: 900 | F21: 962 | G21: 967 | H21: 1016 | I21: 1163 | J21: 926 | K21: 965 | L21: 1014 | M21: 1060 | N21: 1200 | O21: 1280 | P21: 1283 | Q21: 1160 | R21: 1238 | S21: 1579 | T21: 1719 | U21: …
C22: Fabricación de productos lácteos | D22: 867 | E22: 1036 | F22: 863 | G22: 957 | H22: 1046 | I22: 1213 | J22: 1295 | K22: 1281 | L22: 1326 | M22: 1327 | N22: 1369 | O22: 1281 | P22: 1253 | Q22: 1172 | R22: 908 | S22: 1212 | T22: 1549 | U22: …
C23: Molinería, fideos, panadería y otros | D23: 2668 | E23: 3250 | F23: 3715 | G23: 4037 | H23: 3439 | I23: 4454 | J23: 4401 | K23: 4137 | L23: 4698 | M23: 5093 | N23: 5312 | O23: 5319 | P23: 5839 | Q23: 5777 | R23: 5447 | S23: 5596 | T23: 7917 | U23: …
C24: Elaboración y refinación de azúcar | D24: 466 | E24: 466 | F24: 635 | G24: 971 | H24: 1115 | I24: 1052 | J24: 772 | K24: 790 | L24: 933 | M24: 1155 | N24: 1057 | O24: 904 | P24: 795 | Q24: 1067 | R24: 978 | S24: 1413 | T24: 1485 | U24: …
C25: Elaboración de otros productos alimenticios | D25: 851 | E25: 1022 | F25: 1078 | G25: 1351 | H25: 1333 | I25: 1417 | J25: 1521 | K25: 1452 | L25: 1604 | M25: 2084 | N25: 2001 | O25: 2116 | P25: 2473 | Q25: 2541 | R25: 2935 | S25: 2655 | T25: 2558 | U25: …
C26: Elaboración de alimentos preparados para animales | D26: 313 | E26: 343 | F26: 481 | G26: 476 | H26: 442 | I26: 647 | J26: 788 | K26: 763 | L26: 800 | M26: 820 | N26: 872 | O26: 928 | P26: 911 | Q26: 828 | R26: 722 | S26: 682 | T26: 1036 | U26: …
C27: Elaboración de bebidas y productos del tabaco | D27: 1684 | E27: 1888 | F27: 2109 | G27: 2442 | H27: 2697 | I27: 3036 | J27: 3256 | K27: 3373 | L27: 3511 | M27: 3723 | N27: 3943 | O27: 4373 | P27: 5369 | Q27: 4484 | R27: 5111 | S27: 5239 | T27: 5962 | U27: …
C28: Fabricación de textiles | D28: 2377 | E28: 2341 | F28: 2126 | G28: 2500 | H28: 2495 | I28: 2532 | J28: 2674 | K28: 2609 | L28: 2605 | M28: 2491 | N28: 2562 | O28: 2578 | P28: 2548 | Q28: 2046 | R28: 2688 | S28: 2814 | T28: 2773 | U28: …
... C47: Otras industrias manufactureras | D47: 4323 | E47: 4450 | F47: 5154 | G47: 4843 | H47: 5004 | I47: 5207 | J47: 5093 | K47: 4653 | L47: 3952 | M47: 5090 | N47: 6098 | O47: 6454 | P47: 6314 | Q47: 6227 | R47: 7438 | S47: 7746 | T47: 7936 | U47: …
B48: Electricidad, gas y agua | D48: 5505 | E48: 6460 | F48: 6945 | G48: 7140 | H48: 7812 | I48: 8601 | J48: 9355 | K48: 10719 | L48: 12623 | M48: 15758 | N48: 16240 | O48: 17662 | P48: 19924 | Q48: 19764 | R48: 20883 | S48: 22159 | T48: 25184 | U48: 25854
B49: Construcción | D49: 16317 | E49: 19772 | F49: 21480 | G49: 25958 | H49: 27649 | I49: 33119 | J49: 37453 | K49: 40655 | L49: 42163 | M49: 42610 | N49: 45134 | O49: 49648 | P49: 51148 | Q49: 47571 | R49: 66423 | S49: 72722 | T49: 73113 | U49: 78569
B50: Comercio, mantenimiento y reparación de vehículos automotores y motocicletas | D50: 32537 | E50: 39013 | F50: 39429 | G50: 45020 | H50: 51694 | I50: 56156 | J50: 59186 | K50: 60975 | L50: 64539 | M50: 68335 | N50: 72045 | O50: 75639 | P50: 78684 | Q50: 74859 | R50: 93881 | S50: 105192 | T50: 113309 | U50: 120427
B51: Transporte, almacenamiento, correo y mensajería | D51: 15885 | E51: 18211 | F51: 20616 | G51: 23030 | H51: 24998 | I51: 27337 | J51: 30734 | K51: 33518 | L51: 40469 | M51: 43769 | N51: 44517 | O51: 44637 | P51: 47731 | Q51: 41708 | R51: 44904 | S51: 46978 | T51: 55317 | U51: 61028
B52: Alojamiento y restaurantes | D52: 9143 | E52: 10539 | F52: 11661 | G52: 13143 | H52: 15478 | I52: 18451 | J52: 21496 | K52: 24027 | L52: 26614 | M52: 29159 | N52: 30961 | O52: 33289 | P52: 34990 | Q52: 18521 | R52: 26100 | S52: 34328 | T52: 38869 | U52: 43620
B53: Telecomunicaciones y otros servicios de información | D53: 8517 | E53: 9391 | F53: 9396 | G53: 10101 | H53: 10619 | I53: 11295 | J53: 11906 | K53: 12447 | L53: 12809 | M53: 13530 | N53: 14473 | O53: 14964 | P53: 15827 | Q53: 15721 | R53: 15917 | S53: 16339 | T53: 16775 | U53: 18509
C54: Telecomunicaciones | D54: 5962 | E54: 6564 | F54: 6373 | G54: 6714 | H54: 6887 | I54: 7190 | J54: 7481 | K54: 7842 | L54: 8011 | M54: 8322 | N54: 8974 | O54: 9416 | P54: 9962 | Q54: 11047 | R54: 10831 | S54: 10314 | T54: 10500 | U54: …
C55: Otros servicios de información y comunicación | D55: 2555 | E55: 2827 | F55: 3023 | G55: 3387 | H55: 3732 | I55: 4105 | J55: 4425 | K55: 4605 | L55: 4798 | M55: 5208 | N55: 5499 | O55: 5548 | P55: 5865 | Q55: 4674 | R55: 5086 | S55: 6025 | T55: 6275 | U55: …
B56: Servicios financieros, seguros y pensiones | D56: 10279 | E56: 11793 | F56: 14719 | G56: 16847 | H56: 19286 | I56: 21552 | J56: 24366 | K56: 27799 | L56: 30733 | M56: 33106 | N56: 33834 | O56: 36257 | P56: 38509 | Q56: 41821 | R56: 39381 | S56: 41182 | T56: 43935 | U56: 48038
C57: Servicios financieros | D57: 8941 | E57: 10235 | F57: 12918 | G57: 14552 | H57: 16525 | I57: 18708 | J57: 21145 | K57: 24143 | L57: 26697 | M57: 29020 | N57: 29737 | O57: 32114 | P57: 34098 | Q57: 37328 | R57: 35156 | S57: 36097 | T57: 38254 | U57: …
C58: Seguros y pensiones | D58: 1338 | E58: 1558 | F58: 1801 | G58: 2295 | H58: 2761 | I58: 2844 | J58: 3221 | K58: 3656 | L58: 4036 | M58: 4086 | N58: 4097 | O58: 4143 | P58: 4411 | Q58: 4493 | R58: 4225 | S58: 5085 | T58: 5681 | U58: …
B59: Servicios prestados a empresas | D59: 13555 | E59: 15558 | F59: 16608 | G59: 18852 | H59: 21453 | I59: 23894 | J59: 26582 | K59: 28431 | L59: 30693 | M59: 32396 | N59: 34375 | O59: 36046 | P59: 38446 | Q59: 31837 | R59: 37228 | S59: 40875 | T59: 44300 | U59: 48011
C60: Servicios profesionales, científicos y técnicos | D60: 6502 | E60: 7677 | F60: 8188 | G60: 9384 | H60: 10531 | I60: 11719 | J60: 12967 | K60: 13579 | L60: 14579 | M60: 15384 | N60: 16298 | O60: 17077 | P60: 18291 | Q60: 15236 | R60: 18179 | S60: 20101 | T60: 22183 | U60: …
C61: Alquiler de vehículos, maquinaria y equipo y otros | D61: 1275 | E61: 1429 | F61: 1571 | G61: 1842 | H61: 2091 | I61: 2328 | J61: 2608 | K61: 3044 | L61: 3295 | M61: 3403 | N61: 3524 | O61: 3700 | P61: 3972 | Q61: 3109 | R61: 4059 | S61: 4475 | T61: 4849 | U61: …
C62: Agencias de viaje y operadores turísticos | D62: 437 | E62: 485 | F62: 489 | G62: 490 | H62: 560 | I62: 623 | J62: 743 | K62: 820 | L62: 1019 | M62: 1099 | N62: 1129 | O62: 1245 | P62: 1335 | Q62: 348 | R62: 301 | S62: 758 | T62: 769 | U62: …
...

Sheet MillonesSoles07
A2: PERÚ: PRODUCTO BRUTO INTERNO SEGÚN ACTIVIDAD ECONÓMICA (NIVEL 54), 2007-2024 Valores a precios constantes de 2007 (Millones de soles)
A4: Actividad Económica | D4: 2007 | E4: 2008 | F4: 2009 | G4: 2010 | H4: 2011 | I4: 2012 | J4: 2013 | K4: 2014 | L4: 2015 | M4: 2016 | N4: 2017 | O4: 2018 | P4: 2019 | Q4: 2020 | R4: 2021 | S4: 2022P/ | T4: 2023E/ | U4: 2024E/
A6: Producto Bruto Interno | D6: 319693 | E6: 348870 | F6: 352693 | G6: 382081 | H6: 406256 | I6: 431199 | J6: 456435 | K6: 467308 | L6: 482506 | M6: 501581 | N6: 514215 | O6: 534626 | P6: 546605 | Q6: 486843 | R6: 551898 | S6: 567401 | T6: 565113 | U6: 583784
B8: Derechos de Importación | D8: 2831 | E8: 3461 | F8: 2772 | G8: 3575 | H8: 3883 | I8: 4603 | J8: 4706 | K8: 4397 | L8: 3859 | M8: 3612 | N8: 3790 | O8: 3849 | P8: 3281 | Q8: 2739 | R8: 3502 | S8: 3726 | T8: 3607 | U8: 3876
B9: Impuestos a los productos | D9: 23672 | E9: 26618 | F9: 27397 | G9: 31092 | H9: 32442 | I9: 35163 | J9: 38195 | K9: 39717 | L9: 40458 | M9: 42247 | N9: 42666 | O9: 44420 | P9: 46142 | Q9: 40960 | R9: 47356 | S9: 48285 | T9: 47006 | U9: 48504
B10: Valor Agregado Bruto | D10: 293190 | E10: 318791 | F10: 322524 | G10: 347414 | H10: 369931 | I10: 391433 | J10: 413534 | K10: 423194 | L10: 438189 | M10: 455722 | N10: 467759 | O10: 486357 | P10: 497182 | Q10: 443144 | R10: 501040 | S10: 515390 | T10: 514500 | U10: 531404
B11: Agricultura, ganadería, caza y silvicultura | D11: 19074 | E11: 20600 | F11: 20784 | G11: 21656 | H11: 22517 | I11: 23944 | J11: 24216 | K11: 24540 | L11: 25294 | M11: 25963 | N11: 26624 | O11: 28643 | P11: 29474 | Q11: 29706 | R11: 31208 | S11: 32619 | T11: 31789 | U11: 33358
B12: Pesca y acuicultura | D12: 2364 | E12: 2435 | F12: 2321 | G12: 1675 | H12: 2709 | I12: 1729 | J12: 2126 | K12: 1515 | L12: 1791 | M12: 1593 | N12: 1750 | O12: 2464 | P12: 2099 | Q12: 2173 | R12: 2386 | S12: 2084 | T12: 1615 | U12: 2017
B13: Extracción de petróleo, gas, minerales y servicios conexos | D13: 45892 | E13: 49601 | F13: 49910 | G13: 50601 | H13: 50750 | I13: 51662 | J13: 54304 | K13: 53454 | L13: 57948 | M13: 65095 | N13: 67439 | O13: 66429 | P13: 66272 | Q13: 57237 | R13: 62219 | S13: 62477 | T13: 67485 | U13: 68865
C14: Extracción de petróleo crudo, gas natural y servicios conexos | D14: 7101 | E14: 7615 | F14: 9692 | G14: 11082 | H14: 11605 | I14: 11726 | J14: 12443 | K14: 12874 | L14: 11693 | M14: 10347 | N14: 10091 | O14: 10090 | P14: 10525 | Q14: 9313 | R14: 8770 | S14: 9031 | T14: 9235 | U14: …
C15: Extracción de minerales y servicios conexos | D15: 38791 | E15: 41986 | F15: 40218 | G15: 39519 | H15: 39145 | I15: 39936 | J15: 41861 | K15: 40580 | L15: 46255 | M15: 54748 | N15: 57348 | O15: 56339 | P15: 55747 | Q15: 47924 | R15: 53449 | S15: 53446 | T15: 58250 | U15: …
B16: Manufactura | D16: 52807 | E16: 57304 | F16: 53600 | G16: 59024 | H16: 63943 | I16: 64758 | J16: 68155 | K16: 67405 | L16: 66824 | M16: 66783 | N16: 67154 | O16: 71047 | P16: 70208 | Q16: 61450 | R16: 72839 | S16: 74107 | T16: 69186 | U16: 71915
C17: Procesamiento y conservación de carnes | D17: 1347 | E17: 1467 | F17: 1472 | G17: 1601 | H17: 1673 | I17: 1765 | J17: 1855 | K17: 1914 | L17: 1995 | M17: 2048 | N17: 2094 | O17: 2214 | P17: 2299 | Q17: 2158 | R17: 2304 | S17: 2325 | T17: 2235 | U17: …
C18: Elaboración y preservación de pescado | D18: 990 | E18: 1058 | F18: 874 | G18: 773 | H18: 1251 | I18: 1177 | J18: 1161 | K18: 1204 | L18: 1064 | M18: 954 | N18: 960 | O18: 1110 | P18: 1533 | Q18: 1484 | R18: 1575 | S18: 1418 | T18: 1620 | U18: …
C19: Elaboración de harina y aceite de pescado | D19: 1638 | E19: 1623 | F19: 1559 | G19: 931 | H19: 1775 | I19: 1032 | J19: 1295 | K19: 661 | L19: 1003 | M19: 787 | N19: 900 | O19: 1637 | P19: 952 | Q19: 1255 | R19: 1511 | S19: 1140 | T19: 552 | U19: …
C20: Procesamiento y conservación de frutas y vegetales | D20: 752 | E20: 830 | F20: 758 | G20: 928 | H20: 1059 | I20: 1076 | J20: 1070 | K20: 1135 | L20: 1091 | M20: 1149 | N20: 1166 | O20: 1512 | P20: 1598 | Q20: 1658 | R20: 1626 | S20: 1705 | T20: 1219 | U20: …
C21: Elaboración de aceites y grasas de origen vegetal y animal | D21: 691 | E21: 752 | F21: 780 | G21: 922 | H21: 916 | I21: 997 | J21: 1034 | K21: 1096 | L21: 1159 | M21: 1188 | N21: 1273 | O21: 1317 | P21: 1351 | Q21: 1226 | R21: 1283 | S21: 1208 | T21: 1045 | U21: …
C22: Fabricación de productos lácteos | D22: 867 | E22: 942 | F22: 903 | G22: 1020 | H22: 1071 | I22: 1169 | J22: 1225 | K22: 1250 | L22: 1265 | M22: 1221 | N22: 1188 | O22: 1209 | P22: 1244 | Q22: 1232 | R22: 1252 | S22: 1110 | T22: 1117 | U22: …
C23: Molinería, fideos, panadería y otros | D23: 2668 | E23: 2842 | F23: 2950 | G23: 3100 | H23: 3101 | I23: 3320 | J23: 3392 | K23: 3408 | L23: 3454 | M23: 3511 | N23: 3560 | O23: 3683 | P23: 3682 | Q23: 3909 | R23: 4147 | S23: 4183 | T23: 4057 | U23: …
C24: Elaboración y refinación de azúcar | D24: 466 | E24: 524 | F24: 553 | G24: 539 | H24: 555 | I24: 572 | J24: 607 | K24: 620 | L24: 587 | M24: 605 | N24: 575 | O24: 641 | P24: 646 | Q24: 654 | R24: 615 | S24: 612 | T24: 596 | U24: …
C25: Elaboración de otros productos alimenticios | D25: 851 | E25: 942 | F25: 907 | G25: 1038 | H25: 1139 | I25: 1165 | J25: 1119 | K25: 1047 | L25: 1075 | M25: 1083 | N25: 1224 | O25: 1299 | P25: 1307 | Q25: 1314 | R25: 1411 | S25: 1439 | T25: 1434 | U25: …
C26: Elaboración de alimentos preparados para animales | D26: 313 | E26: 327 | F26: 336 | G26: 360 | H26: 392 | I26: 422 | J26: 451 | K26: 448 | L26: 466 | M26: 473 | N26: 492 | O26: 527 | P26: 538 | Q26: 482 | R26: 542 | S26: 564 | T26: 471 | U26: …
C27: Elaboración de bebidas y productos del tabaco | D27: 1684 | E27: 1925 | F27: 1944 | G27: 2118 | H27: 2235 | I27: 2331 | J27: 2356 | K27: 2415 | L27: 2475 | M27: 2537 | N27: 2534 | O27: 2520 | P27: 2678 | Q27: 2190 | R27: 2708 | S27: 2947 | T27: 2940 | U27: …
C28: Fabricación de textiles | D28: 2377 | E28: 2320 | F28: 1965 | G28: 2428 | H28: 2588 | I28: 2435 | J28: 2537 | K28: 2499 | L28: 2366 | M28: 2206 | N28: 2321 | O28: 2303 | P28: 2172 | Q28: 1618 | R28: 2223 | S28: 2174 | T28: 1882 | U28: …
... C47: Otras industrias manufactureras | D47: 4323 | E47: 4604 | F47: 4741 | G47: 4790 | H47: 4940 | I47: 4965 | J47: 4906 | K47: 4461 | L47: 4163 | M47: 4435 | N47: 4834 | O47: 5217 | P47: 5246 | Q47: 5171 | R47: 6307 | S47: 6905 | T47: 6671 | U47: …
B48: Electricidad, gas y agua | D48: 5505 | E48: 5948 | F48: 6008 | G48: 6531 | H48: 7066 | I48: 7481 | J48: 7734 | K48: 8133 | L48: 8666 | M48: 9344 | N48: 9432 | O48: 9862 | P48: 10292 | Q48: 9627 | R48: 10488 | S48: 10894 | T48: 11285 | U48: 11551
B49: Construcción | D49: 16317 | E49: 19071 | F49: 20319 | G49: 23765 | H49: 24626 | I49: 28539 | J49: 31228 | K49: 31789 | L49: 30083 | M49: 29290 | N49: 30002 | O49: 31626 | P49: 32089 | Q49: 27306 | R49: 36857 | S49: 37807 | T49: 34803 | U49: 36051
B50: Comercio, mantenimiento y reparación de vehículos automotores y motocicletas | D50: 32537 | E50: 36029 | F50: 35735 | G50: 39981 | H50: 43434 | I50: 47105 | J50: 49408 | K50: 50364 | L50: 51919 | M50: 53369 | N50: 54070 | O50: 55442 | P50: 56802 | Q50: 49251 | R50: 57711 | S50: 59549 | T50: 60862 | U50: 62664
B51: Transporte, almacenamiento, correo y mensajería | D51: 15885 | E51: 17317 | F51: 17153 | G51: 19419 | H51: 21631 | I51: 23152 | J51: 24687 | K51: 25292 | L51: 26371 | M51: 27454 | N51: 28554 | O51: 30128 | P51: 30876 | Q51: 22347 | R51: 26797 | S51: 29098 | T51: 29406 | U51: 31211
B52: Alojamiento y restaurantes | D52: 9143 | E52: 10086 | F52: 10148 | G52: 10895 | H52: 12103 | I52: 13413 | J52: 14323 | K52: 15066 | L52: 15562 | M52: 15988 | N52: 16194 | O52: 16831 | P52: 17569 | Q52: 8696 | R52: 12368 | S52: 15238 | T52: 15619 | U52: 16191
B53: Telecomunicaciones y otros servicios de información | D53: 8517 | E53: 9974 | F53: 10784 | G53: 11876 | H53: 13243 | I53: 14855 | J53: 16149 | K53: 17542 | L53: 19133 | M53: 20812 | N53: 22523 | O53: 23686 | P53: 25340 | Q53: 26414 | R53: 29143 | S53: 30240 | T53: 29582 | U53: 30170
C54: Telecomunicaciones | D54: 5962 | E54: 7206 | F54: 7877 | G54: 8675 | H54: 9757 | I54: 11128 | J54: 12138 | K54: 13422 | L54: 14931 | M54: 16467 | N54: 18167 | O54: 19334 | P54: 20906 | Q54: 23003 | R54: 25427 | S54: 26292 | T54: 25728 | U54: …
C55: Otros servicios de información y comunicación | D55: 2555 | E55: 2768 | F55: 2907 | G55: 3201 | H55: 3486 | I55: 3727 | J55: 4011 | K55: 4120 | L55: 4202 | M55: 4345 | N55: 4356 | O55: 4352 | P55: 4434 | Q55: 3411 | R55: 3716 | S55: 3948 | T55: 3854 | U55: …
B56: Servicios financieros, seguros y pensiones | D56: 10279 | E56: 10941 | F56: 11830 | G56: 13015 | H56: 14417 | I56: 15802 | J56: 17335 | K56: 19555 | L56: 21430 | M56: 22588 | N56: 22928 | O56: 24253 | P56: 25571 | Q56: 28490 | R56: 29704 | S56: 28663 | T56: 27553 | U56: 27112
C57: Servicios financieros | D57: 8941 | E57: 9484 | F57: 10146 | G57: 10840 | H57: 11896 | I57: 13193 | J57: 14422 | K57: 16094 | L57: 17588 | M57: 18701 | N57: 19002 | O57: 20242 | P57: 21241 | Q57: 24126 | R57: 25527 | S57: 23862 | T57: 22370 | U57: …
C58: Seguros y pensiones | D58: 1338 | E58: 1457 | F58: 1684 | G58: 2175 | H58: 2521 | I58: 2609 | J58: 2913 | K58: 3461 | L58: 3842 | M58: 3887 | N58: 3926 | O58: 4011 | P58: 4330 | Q58: 4364 | R58: 4177 | S58: 4801 | T58: 5183 | U58: …
B59: Servicios prestados a empresas | D59: 13555 | E59: 15223 | F59: 15598 | G59: 17413 | H59: 19034 | I59: 20397 | J59: 21880 | K59: 22876 | L59: 23863 | M59: 24485 | N59: 25278 | O59: 26189 | P59: 27306 | Q59: 22273 | R59: 25380 | S59: 25681 | T59: 25776 | U59: 26692
C60: Servicios profesionales, científicos y técnicos | D60: 6502 | E60: 7542 | F60: 7704 | G60: 8706 | H60: 9408 | I60: 10055 | J60: 10752 | K60: 11109 | L60: 11619 | M60: 11932 | N60: 12278 | O60: 12764 | P60: 13391 | Q60: 10935 | R60: 12733 | S60: 12929 | T60: 13127 | U60: …
C61: Alquiler de vehículos, maquinaria y equipo y otros | D61: 1275 | E61: 1366 | F61: 1445 | G61: 1639 | H61: 1798 | I61: 1945 | J61: 2081 | K61: 2366 | L61: 2445 | M61: 2455 | N61: 2464 | O61: 2514 | P61: 2629 | Q61: 2029 | R61: 2593 | S61: 2670 | T61: 2688 | U61: …
C62: Agencias de viaje y operadores turísticos | D62: 437 | E62: 480 | F62: 446 | G62: 452 | H62: 497 | I62: 547 | J62: 606 | K62: 639 | L62: 680 | M62: 686 | N62: 722 | O62: 767 | P62: 780 | Q62: 206 | R62: 178 | S62: 417 | T62: 384 | U62: …
...

Sheet Deflactores
A1: Actividad Económica | D1: 2007 | E1: 2008 | F1: 2009 | G1: 2010 | H1: 2011 | I1: 2012 | J1: 2013 | K1: 2014 | L1: 2015 | M1: 2016 | N1: 2017 | O1: 2018 | P1: 2019 | Q1: 2020 | R1: 2021 | S1: 2022P/ | T1: 2023E/ | U1: 2024E/
A3: Producto Bruto Interno | D3: =IFERROR(MillonesSoles!D6/MillonesSoles07!D6*100,"") -> 100 | E3: =IFERROR(MillonesSoles!E6/MillonesSoles07!E6*100,"") -> 101.10328 | F3: =IFERROR(MillonesSoles!F6/MillonesSoles07!F6*100,"") -> 103.18974 | G3: =IFERROR(MillonesSoles!G6/MillonesSoles07!G6*100,"") -> 109.08263 | H3: =IFERROR(MillonesSoles!H6/MillonesSoles07!H6*100,"") -> 116.44111 | I3: =IFERROR(MillonesSoles!I6/MillonesSoles07!I6*100,"") -> 117.84141 | J3: =IFERROR(MillonesSoles!J6/MillonesSoles07!J6*100,"") -> 119.08727 | K3: =IFERROR(MillonesSoles!K6/MillonesSoles07!K6*100,"") -> 121.984 | ... U3: =IFERROR(MillonesSoles!U6/MillonesSoles07!U6*100,"") -> 185.97769
D4: =IFERROR(MillonesSoles!D7/MillonesSoles07!D7*100,"") | E4: =IFERROR(MillonesSoles!E7/MillonesSoles07!E7*100,"") | F4: =IFERROR(MillonesSoles!F7/MillonesSoles07!F7*100,"") | G4: =IFERROR(MillonesSoles!G7/MillonesSoles07!G7*100,"") | H4: =IFERROR(MillonesSoles!H7/MillonesSoles07!H7*100,"") | I4: =IFERROR(MillonesSoles!I7/MillonesSoles07!I7*100,"") | J4: =IFERROR(MillonesSoles!J7/MillonesSoles07!J7*100,"") | K4: =IFERROR(MillonesSoles!K7/MillonesSoles07!K7*100,"") | ... U4: =IFERROR(MillonesSoles!U7/MillonesSoles07!U7*100,"")
B5: Derechos de Importación | D5: =IFERROR(MillonesSoles!D8/MillonesSoles07!D8*100,"") -> 100 | E5: =IFERROR(MillonesSoles!E8/MillonesSoles07!E8*100,"") -> 51.083502 | F5: =IFERROR(MillonesSoles!F8/MillonesSoles07!F8*100,"") -> 50.685426 | G5: =IFERROR(MillonesSoles!G8/MillonesSoles07!G8*100,"") -> 50.041958 | H5: =IFERROR(MillonesSoles!H8/MillonesSoles07!H8*100,"") -> 32.294618 | I5: =IFERROR(MillonesSoles!I8/MillonesSoles07!I8*100,"") -> 31.47947 | J5: =IFERROR(MillonesSoles!J8/MillonesSoles07!J8*100,"") -> 36.294093 | K5: =IFERROR(MillonesSoles!K8/MillonesSoles07!K8*100,"") -> 48.510348 | ... U5: =IFERROR(MillonesSoles!U8/MillonesSoles07!U8*100,"") -> 37.4613
B6: Impuestos a los productos | D6: =IFERROR(MillonesSoles!D9/MillonesSoles07!D9*100,"") -> 100 | E6: =IFERROR(MillonesSoles!E9/MillonesSoles07!E9*100,"") -> 101.33744 | F6: =IFERROR(MillonesSoles!F9/MillonesSoles07!F9*100,"") -> 105.23415 | G6: =IFERROR(MillonesSoles!G9/MillonesSoles07!G9*100,"") -> 107.60324 | H6: =IFERROR(MillonesSoles!H9/MillonesSoles07!H9*100,"") -> 111.40805 | I6: =IFERROR(MillonesSoles!I9/MillonesSoles07!I9*100,"") -> 120.32819 | J6: =IFERROR(MillonesSoles!J9/MillonesSoles07!J9*100,"") -> 122.9873 | K6: =IFERROR(MillonesSoles!K9/MillonesSoles07!K9*100,"") -> 125.25871 | ... U6: =IFERROR(MillonesSoles!U9/MillonesSoles07!U9*100,"") -> 162.5701
B7: Valor Agregado Bruto | D7: =IFERROR(MillonesSoles!D10/MillonesSoles07!D10*100,"") -> 100 | E7: =IFERROR(MillonesSoles!E10/MillonesSoles07!E10*100,"") -> 101.62677 | F7: =IFERROR(MillonesSoles!F10/MillonesSoles07!F10*100,"") -> 103.46734 | G7: =IFERROR(MillonesSoles!G10/MillonesSoles07!G10*100,"") -> 109.82257 | H7: =IFERROR(MillonesSoles!H10/MillonesSoles07!H10*100,"") -> 117.76575 | I7: =IFERROR(MillonesSoles!I10/MillonesSoles07!I10*100,"") -> 118.63358 | J7: =IFERROR(MillonesSoles!J10/MillonesSoles07!J10*100,"") -> 119.66924 | K7: =IFERROR(MillonesSoles!K10/MillonesSoles07!K10*100,"") -> 122.44006 | ... U7: =IFERROR(MillonesSoles!U10/MillonesSoles07!U10*100,"") -> 189.19748
B8: Agricultura, ganadería, caza y silvicultura | D8: =IFERROR(MillonesSoles!D11/MillonesSoles07!D11*100,"") -> 100 | E8: =IFERROR(MillonesSoles!E11/MillonesSoles07!E11*100,"") -> 111.18447 | F8: =IFERROR(MillonesSoles!F11/MillonesSoles07!F11*100,"") -> 117.49904 | G8: =IFERROR(MillonesSoles!G11/MillonesSoles07!G11*100,"") -> 119.45881 | H8: =IFERROR(MillonesSoles!H11/MillonesSoles07!H11*100,"") -> 132.35777 | I8: =IFERROR(MillonesSoles!I11/MillonesSoles07!I11*100,"") -> 133.28182 | J8: =IFERROR(MillonesSoles!J11/MillonesSoles07!J11*100,"") -> 135.53023 | K8: =IFERROR(MillonesSoles!K11/MillonesSoles07!K11*100,"") -> 147.85656 | ... U8: =IFERROR(MillonesSoles!U11/MillonesSoles07!U11*100,"") -> 221.47611
B9: Pesca y acuicultura | D9: =IFERROR(MillonesSoles!D12/MillonesSoles07!D12*100,"") -> 100 | E9: =IFERROR(MillonesSoles!E12/MillonesSoles07!E12*100,"") -> 96.673511 | F9: =IFERROR(MillonesSoles!F12/MillonesSoles07!F12*100,"") -> 108.78931 | G9: =IFERROR(MillonesSoles!G12/MillonesSoles07!G12*100,"") -> 154.50746 | H9: =IFERROR(MillonesSoles!H12/MillonesSoles07!H12*100,"") -> 139.68254 | I9: =IFERROR(MillonesSoles!I12/MillonesSoles07!I12*100,"") -> 130.71139 | J9: =IFERROR(MillonesSoles!J12/MillonesSoles07!J12*100,"") -> 161.1477 | K9: =IFERROR(MillonesSoles!K12/MillonesSoles07!K12*100,"") -> 165.21452 | ... U9: =IFERROR(MillonesSoles!U12/MillonesSoles07!U12*100,"") -> 286.71294
B10: Extracción de petróleo, gas, minerales y servicios conexos | D10: =IFERROR(MillonesSoles!D13/MillonesSoles07!D13*100,"") -> 100 | E10: =IFERROR(MillonesSoles!E13/MillonesSoles07!E13*100,"") -> 89.55263 | F10: =IFERROR(MillonesSoles!F13/MillonesSoles07!F13*100,"") -> 76.18914 | G10: =IFERROR(MillonesSoles!G13/MillonesSoles07!G13*100,"") -> 101.09879 | H10: =IFERROR(MillonesSoles!H13/MillonesSoles07!H13*100,"") -> 136.5399 | I10: =IFERROR(MillonesSoles!I13/MillonesSoles07!I13*100,"") -> 119.58887 | J10: =IFERROR(MillonesSoles!J13/MillonesSoles07!J13*100,"") -> 104.26488 | K10: =IFERROR(MillonesSoles!K13/MillonesSoles07!K13*100,"") -> 93.091256 | ... U10: =IFERROR(MillonesSoles!U13/MillonesSoles07!U13*100,"") -> 192.97902
C11: Extracción de petróleo crudo, gas natural y servicios conexos | D11: =IFERROR(MillonesSoles!D14/MillonesSoles07!D14*100,"") -> 100 | E11: =IFERROR(MillonesSoles!E14/MillonesSoles07!E14*100,"") -> 115.95535 | F11: =IFERROR(MillonesSoles!F14/MillonesSoles07!F14*100,"") -> 61.824185 | G11: =IFERROR(MillonesSoles!G14/MillonesSoles07!G14*100,"") -> 82.566324 | H11: =IFERROR(MillonesSoles!H14/MillonesSoles07!H14*100,"") -> 124.37742 | I11: =IFERROR(MillonesSoles!I14/MillonesSoles07!I14*100,"") -> 111.98192 | J11: =IFERROR(MillonesSoles!J14/MillonesSoles07!J14*100,"") -> 99.557984 | K11: =IFERROR(MillonesSoles!K14/MillonesSoles07!K14*100,"") -> 82.895759 | ... U11: =IFERROR(MillonesSoles!U14/MillonesSoles07!U14*100,"")
C12: Extracción de minerales y servicios conexos | D12: =IFERROR(MillonesSoles!D15/MillonesSoles07!D15*100,"") -> 100 | E12: =IFERROR(MillonesSoles!E15/MillonesSoles07!E15*100,"") -> 84.763969 | F12: =IFERROR(MillonesSoles!F15/MillonesSoles07!F15*100,"") -> 79.650903 | G12: =IFERROR(MillonesSoles!G15/MillonesSoles07!G15*100,"") -> 106.29571 | H12: =IFERROR(MillonesSoles!H15/MillonesSoles07!H15*100,"") -> 140.14561 | I12: =IFERROR(MillonesSoles!I15/MillonesSoles07!I15*100,"") -> 121.82242 | J12: =IFERROR(MillonesSoles!J15/MillonesSoles07!J15*100,"") -> 105.66398 | K12: =IFERROR(MillonesSoles!K15/MillonesSoles07!K15*100,"") -> 96.325776 | ... U12: =IFERROR(MillonesSoles!U15/MillonesSoles07!U15*100,"")
B13: Manufactura | D13: =IFERROR(MillonesSoles!D16/MillonesSoles07!D16*100,"") -> 100 | E13: =IFERROR(MillonesSoles!E16/MillonesSoles07!E16*100,"") -> 100.30888 | F13: =IFERROR(MillonesSoles!F16/MillonesSoles07!F16*100,"") -> 103.83955 | G13: =IFERROR(MillonesSoles!G16/MillonesSoles07!G16*100,"") -> 109.84854 | H13: =IFERROR(MillonesSoles!H16/MillonesSoles07!H16*100,"") -> 111.64631 | I13: =IFERROR(MillonesSoles!I16/MillonesSoles07!I16*100,"") -> 118.98916 | J13: =IFERROR(MillonesSoles!J16/MillonesSoles07!J16*100,"") -> 118.28479 | K13: =IFERROR(MillonesSoles!K16/MillonesSoles07!K16*100,"") -> 118.05652 | ... U13: =IFERROR(MillonesSoles!U16/MillonesSoles07!U16*100,"") -> 182.88674
C14: Procesamiento y conservación de carnes | D14: =IFERROR(MillonesSoles!D17/MillonesSoles07!D17*100,"") -> 100 | E14: =IFERROR(MillonesSoles!E17/MillonesSoles07!E17*100,"") -> 111.79277 | F14: =IFERROR(MillonesSoles!F17/MillonesSoles07!F17*100,"") -> 128.60054 | G14: =IFERROR(MillonesSoles!G17/MillonesSoles07!G17*100,"") -> 127.85759 | H14: =IFERROR(MillonesSoles!H17/MillonesSoles07!H17*100,"") -> 126.53915 | I14: =IFERROR(MillonesSoles!I17/MillonesSoles07!I17*100,"") -> 137.16714 | J14: =IFERROR(MillonesSoles!J17/MillonesSoles07!J17*100,"") -> 148.78706 | K14: =IFERROR(MillonesSoles!K17/MillonesSoles07!K17*100,"") -> 160.44932 | ... U14: =IFERROR(MillonesSoles!U17/MillonesSoles07!U17*100,"")
C15: Elaboración y preservación de pescado | D15: =IFERROR(MillonesSoles!D18/MillonesSoles07!D18*100,"") -> 100 | E15: =IFERROR(MillonesSoles!E18/MillonesSoles07!E18*100,"") -> 108.79017 | F15: =IFERROR(MillonesSoles!F18/MillonesSoles07!F18*100,"") -> 117.50572 | G15: =IFERROR(MillonesSoles!G18/MillonesSoles07!G18*100,"") -> 119.14618 | H15: =IFERROR(MillonesSoles!H18/MillonesSoles07!H18*100,"") -> 125.97922 | I15: =IFERROR(MillonesSoles!I18/MillonesSoles07!I18*100,"") -> 130.07647 | J15: =IFERROR(MillonesSoles!J18/MillonesSoles07!J18*100,"") -> 135.57278 | K15: =IFERROR(MillonesSoles!K18/MillonesSoles07!K18*100,"") -> 143.02326 | ... U15: =IFERROR(MillonesSoles!U18/MillonesSoles07!U18*100,"")
C16: Elaboración de harina y aceite de pescado | D16: =IFERROR(MillonesSoles!D19/MillonesSoles07!D19*100,"") -> 100 | E16: =IFERROR(MillonesSoles!E19/MillonesSoles07!E19*100,"") -> 98.089957 | F16: =IFERROR(MillonesSoles!F19/MillonesSoles07!F19*100,"") -> 93.970494 | G16: =IFERROR(MillonesSoles!G19/MillonesSoles07!G19*100,"") -> 141.89044 | H16: =IFERROR(MillonesSoles!H19/MillonesSoles07!H19*100,"") -> 136.50704 | I16: =IFERROR(MillonesSoles!I19/MillonesSoles07!I19*100,"") -> 133.91473 | J16: =IFERROR(MillonesSoles!J19/MillonesSoles07!J19*100,"") -> 185.79151 | K16: =IFERROR(MillonesSoles!K19/MillonesSoles07!K19*100,"") -> 181.08926 | ... U16: =IFERROR(MillonesSoles!U19/MillonesSoles07!U19*100,"")
C17: Procesamiento y conservación de frutas y vegetales | D17: =IFERROR(MillonesSoles!D20/MillonesSoles07!D20*100,"") -> 100 | E17: =IFERROR(MillonesSoles!E20/MillonesSoles07!E20*100,"") -> 98.072289 | F17: =IFERROR(MillonesSoles!F20/MillonesSoles07!F20*100,"") -> 92.480211 | G17: =IFERROR(MillonesSoles!G20/MillonesSoles07!G20*100,"") -> 94.288793 | H17: =IFERROR(MillonesSoles!H20/MillonesSoles07!H20*100,"") -> 83.663834 | I17: =IFERROR(MillonesSoles!I20/MillonesSoles07!I20*100,"") -> 96.096654 | J17: =IFERROR(MillonesSoles!J20/MillonesSoles07!J20*100,"") -> 104.6729 | K17: =IFERROR(MillonesSoles!K20/MillonesSoles07!K20*100,"") -> 107.04846 | ... U17: =IFERROR(MillonesSoles!U20/MillonesSoles07!U20*100,"")
C18: Elaboración de aceites y grasas de origen vegetal y animal | D18: =IFERROR(MillonesSoles!D21/MillonesSoles07!D21*100,"") -> 100 | E18: =IFERROR(MillonesSoles!E21/MillonesSoles07!E21*100,"") -> 119.68085 | F18: =IFERROR(MillonesSoles!F21/MillonesSoles07!F21*100,"") -> 123.33333 | G18: =IFERROR(MillonesSoles!G21/MillonesSoles07!G21*100,"") -> 104.88069 | H18: =IFERROR(MillonesSoles!H21/MillonesSoles07!H21*100,"") -> 110.91703 | I18: =IFERROR(MillonesSoles!I21/MillonesSoles07!I21*100,"") -> 116.64995 | J18: =IFERROR(MillonesSoles!J21/MillonesSoles07!J21*100,"") -> 89.555126 | K18: =IFERROR(MillonesSoles!K21/MillonesSoles07!K21*100,"") -> 88.047445 | ... U18: =IFERROR(MillonesSoles!U21/MillonesSoles07!U21*100,"")
C19: Fabricación de productos lácteos | D19: =IFERROR(MillonesSoles!D22/MillonesSoles07!D22*100,"") -> 100 | E19: =IFERROR(MillonesSoles!E22/MillonesSoles07!E22*100,"") -> 109.97877 | F19: =IFERROR(MillonesSoles!F22/MillonesSoles07!F22*100,"") -> 95.570321 | G19: =IFERROR(MillonesSoles!G22/MillonesSoles07!G22*100,"") -> 93.823529 | H19: =IFERROR(MillonesSoles!H22/MillonesSoles07!H22*100,"") -> 97.665733 | I19: =IFERROR(MillonesSoles!I22/MillonesSoles07!I22*100,"") -> 103.7639 | J19: =IFERROR(MillonesSoles!J22/MillonesSoles07!J22*100,"") -> 105.71429 | K19: =IFERROR(MillonesSoles!K22/MillonesSoles07!K22*100,"") -> 102.48 | ... U19: =IFERROR(MillonesSoles!U22/MillonesSoles07!U22*100,"")
C20: Molinería, fideos, panadería y otros | D20: =IFERROR(MillonesSoles!D23/MillonesSoles07!D23*100,"") -> 100 | E20: =IFERROR(MillonesSoles!E23/MillonesSoles07!E23*100,"") -> 114.35609 | F20: =IFERROR(MillonesSoles!F23/MillonesSoles07!F23*100,"") -> 125.9322 | G20: =IFERROR(MillonesSoles!G23/MillonesSoles07!G23*100,"") -> 130.22581 | H20: =IFERROR(MillonesSoles!H23/MillonesSoles07!H23*100,"") -> 110.89971 | I20: =IFERROR(MillonesSoles!I23/MillonesSoles07!I23*100,"") -> 134.15663 | J20: =IFERROR(MillonesSoles!J23/MillonesSoles07!J23*100,"") -> 129.74646 | K20: =IFERROR(MillonesSoles!K23/MillonesSoles07!K23*100,"") -> 121.39085 | ... U20: =IFERROR(MillonesSoles!U23/MillonesSoles07!U23*100,"")
C21: Elaboración y refinación de azúcar | D21: =IFERROR(MillonesSoles!D24/MillonesSoles07!D24*100,"") -> 100 | E21: =IFERROR(MillonesSoles!E24/MillonesSoles07!E24*100,"") -> 88.931298 | F21: =IFERROR(MillonesSoles!F24/MillonesSoles07!F24*100,"") -> 114.82821 | G21: =IFERROR(MillonesSoles!G24/MillonesSoles07!G24*100,"") -> 180.14842 | H21: =IFERROR(MillonesSoles!H24/MillonesSoles07!H24*100,"") -> 200.9009 | I21: =IFERROR(MillonesSoles!I24/MillonesSoles07!I24*100,"") -> 183.91608 | J21: =IFERROR(MillonesSoles!J24/MillonesSoles07!J24*100,"") -> 127.18287 | K21: =IFERROR(MillonesSoles!K24/MillonesSoles07!K24*100,"") -> 127.41935 | ... U21: =IFERROR(MillonesSoles!U24/MillonesSoles07!U24*100,"")
C22: Elaboración de otros productos alimenticios | D22: =IFERROR(MillonesSoles!D25/MillonesSoles07!D25*100,"") -> 100 | E22: =IFERROR(MillonesSoles!E25/MillonesSoles07!E25*100,"") -> 108.49257 | F22: =IFERROR(MillonesSoles!F25/MillonesSoles07!F25*100,"") -> 118.85336 | G22: =IFERROR(MillonesSoles!G25/MillonesSoles07!G25*100,"") -> 130.15414 | H22: =IFERROR(MillonesSoles!H25/MillonesSoles07!H25*100,"") -> 117.03248 | I22: =IFERROR(MillonesSoles!I25/MillonesSoles07!I25*100,"") -> 121.6309 | J22: =IFERROR(MillonesSoles!J25/MillonesSoles07!J25*100,"") -> 135.92493 | K22: =IFERROR(MillonesSoles!K25/MillonesSoles07!K25*100,"") -> 138.68195 | ... U22: =IFERROR(MillonesSoles!U25/MillonesSoles07!U25*100,"")
C23: Elaboración de alimentos preparados para animales | D23: =IFERROR(MillonesSoles!D26/MillonesSoles07!D26*100,"") -> 100 | E23: =IFERROR(MillonesSoles!E26/MillonesSoles07!E26*100,"") -> 104.89297 | F23: =IFERROR(MillonesSoles!F26/MillonesSoles07!F26*100,"") -> 143.15476 | G23: =IFERROR(MillonesSoles!G26/MillonesSoles07!G26*100,"") -> 132.22222 | H23: =IFERROR(MillonesSoles!H26/MillonesSoles07!H26*100,"") -> 112.7551 | I23: =IFERROR(MillonesSoles!I26/MillonesSoles07!I26*100,"") -> 153.31754 | J23: =IFERROR(MillonesSoles!J26/MillonesSoles07!J26*100,"") -> 174.72284 | K23: =IFERROR(MillonesSoles!K26/MillonesSoles07!K26*100,"") -> 170.3125 | ... U23: =IFERROR(MillonesSoles!U26/MillonesSoles07!U26*100,"")
C24: Elaboración de bebidas y productos del tabaco | D24: =IFERROR(MillonesSoles!D27/MillonesSoles07!D27*100,"") -> 100 | E24: =IFERROR(MillonesSoles!E27/MillonesSoles07!E27*100,"") -> 98.077922 | F24: =IFERROR(MillonesSoles!F27/MillonesSoles07!F27*100,"") -> 108.48765 | G24: =IFERROR(MillonesSoles!G27/MillonesSoles07!G27*100,"") -> 115.29745 | H24: =IFERROR(MillonesSoles!H27/MillonesSoles07!H27*100,"") -> 120.67114 | I24: =IFERROR(MillonesSoles!I27/MillonesSoles07!I27*100,"") -> 130.24453 | J24: =IFERROR(MillonesSoles!J27/MillonesSoles07!J27*100,"") -> 138.20034 | K24: =IFERROR(MillonesSoles!K27/MillonesSoles07!K27*100,"") -> 139.66874 | ... U24: =IFERROR(MillonesSoles!U27/MillonesSoles07!U27*100,"")
C25: Fabricación de textiles | D25: =IFERROR(MillonesSoles!D28/MillonesSoles07!D28*100,"") -> 100 | E25: =IFERROR(MillonesSoles!E28/MillonesSoles07!E28*100,"") -> 100.90517 | F25: =IFERROR(MillonesSoles!F28/MillonesSoles07!F28*100,"") -> 108.19338 | G25: =IFERROR(MillonesSoles!G28/MillonesSoles07!G28*100,"") -> 102.9654 | H25: =IFERROR(MillonesSoles!H28/MillonesSoles07!H28*100,"") -> 96.406491 | I25: =IFERROR(MillonesSoles!I28/MillonesSoles07!I28*100,"") -> 103.98357 | J25: =IFERROR(MillonesSoles!J28/MillonesSoles07!J28*100,"") -> 105.40008 | K25: =IFERROR(MillonesSoles!K28/MillonesSoles07!K28*100,"") -> 104.40176 | ... U25: =IFERROR(MillonesSoles!U28/MillonesSoles07!U28*100,"")
... C44: Otras industrias manufactureras | D44: =IFERROR(MillonesSoles!D47/MillonesSoles07!D47*100,"") -> 100 | E44: =IFERROR(MillonesSoles!E47/MillonesSoles07!E47*100,"") -> 96.655083 | F44: =IFERROR(MillonesSoles!F47/MillonesSoles07!F47*100,"") -> 108.71124 | G44: =IFERROR(MillonesSoles!G47/MillonesSoles07!G47*100,"") -> 101.10647 | H44: =IFERROR(MillonesSoles!H47/MillonesSoles07!H47*100,"") -> 101.29555 | I44: =IFERROR(MillonesSoles!I47/MillonesSoles07!I47*100,"") -> 104.87412 | J44: =IFERROR(MillonesSoles!J47/MillonesSoles07!J47*100,"") -> 103.81166 | K44: =IFERROR(MillonesSoles!K47/MillonesSoles07!K47*100,"") -> 104.30397 | ... U44: =IFERROR(MillonesSoles!U47/MillonesSoles07!U47*100,"")
B45: Electricidad, gas y agua | D45: =IFERROR(MillonesSoles!D48/MillonesSoles07!D48*100,"") -> 100 | E45: =IFERROR(MillonesSoles!E48/MillonesSoles07!E48*100,"") -> 108.60794 | F45: =IFERROR(MillonesSoles!F48/MillonesSoles07!F48*100,"") -> 115.59587 | G45: =IFERROR(MillonesSoles!G48/MillonesSoles07!G48*100,"") -> 109.32476 | H45: =IFERROR(MillonesSoles!H48/MillonesSoles07!H48*100,"") -> 110.5576 | I45: =IFERROR(MillonesSoles!I48/MillonesSoles07!I48*100,"") -> 114.97126 | J45: =IFERROR(MillonesSoles!J48/MillonesSoles07!J48*100,"") -> 120.9594 | K45: =IFERROR(MillonesSoles!K48/MillonesSoles07!K48*100,"") -> 131.79639 | ... U45: =IFERROR(MillonesSoles!U48/MillonesSoles07!U48*100,"") -> 223.82478
B46: Construcción | D46: =IFERROR(MillonesSoles!D49/MillonesSoles07!D49*100,"") -> 100 | E46: =IFERROR(MillonesSoles!E49/MillonesSoles07!E49*100,"") -> 103.67574 | F46: =IFERROR(MillonesSoles!F49/MillonesSoles07!F49*100,"") -> 105.71386 | G46: =IFERROR(MillonesSoles!G49/MillonesSoles07!G49*100,"") -> 109.22786 | H46: =IFERROR(MillonesSoles!H49/MillonesSoles07!H49*100,"") -> 112.27564 | I46: =IFERROR(MillonesSoles!I49/MillonesSoles07!I49*100,"") -> 116.04821 | J46: =IFERROR(MillonesSoles!J49/MillonesSoles07!J49*100,"") -> 119.93403 | K46: =IFERROR(MillonesSoles!K49/MillonesSoles07!K49*100,"") -> 127.89015 | ... U46: =IFERROR(MillonesSoles!U49/MillonesSoles07!U49*100,"") -> 217.93848
B47: Comercio, mantenimiento y reparación de vehículos automotores y motocicletas | D47: =IFERROR(MillonesSoles!D50/MillonesSoles07!D50*100,"") -> 100 | E47: =IFERROR(MillonesSoles!E50/MillonesSoles07!E50*100,"") -> 108.28222 | F47: =IFERROR(MillonesSoles!F50/MillonesSoles07!F50*100,"") -> 110.3372 | G47: =IFERROR(MillonesSoles!G50/MillonesSoles07!G50*100,"") -> 112.60349 | H47: =IFERROR(MillonesSoles!H50/MillonesSoles07!H50*100,"") -> 119.01736 | I47: =IFERROR(MillonesSoles!I50/MillonesSoles07!I50*100,"") -> 119.21452 | J47: =IFERROR(MillonesSoles!J50/MillonesSoles07!J50*100,"") -> 119.79032 | K47: =IFERROR(MillonesSoles!K50/MillonesSoles07!K50*100,"") -> 121.06862 | ... U47: =IFERROR(MillonesSoles!U50/MillonesSoles07!U50*100,"") -> 192.17892
B48: Transporte, almacenamiento, correo y mensajería | D48: =IFERROR(MillonesSoles!D51/MillonesSoles07!D51*100,"") -> 100 | E48: =IFERROR(MillonesSoles!E51/MillonesSoles07!E51*100,"") -> 105.16256 | F48: =IFERROR(MillonesSoles!F51/MillonesSoles07!F51*100,"") -> 120.18889 | G48: =IFERROR(MillonesSoles!G51/MillonesSoles07!G51*100,"") -> 118.59519 | H48: =IFERROR(MillonesSoles!H51/MillonesSoles07!H51*100,"") -> 115.56562 | I48: =IFERROR(MillonesSoles!I51/MillonesSoles07!I51*100,"") -> 118.07619 | J48: =IFERROR(MillonesSoles!J51/MillonesSoles07!J51*100,"") -> 124.49467 | K48: =IFERROR(MillonesSoles!K51/MillonesSoles07!K51*100,"") -> 132.52412 | ... U48: =IFERROR(MillonesSoles!U51/MillonesSoles07!U51*100,"") -> 195.53363
B49: Alojamiento y restaurantes | D49: =IFERROR(MillonesSoles!D52/MillonesSoles07!D52*100,"") -> 100 | E49: =IFERROR(MillonesSoles!E52/MillonesSoles07!E52*100,"") -> 104.49137 | F49: =IFERROR(MillonesSoles!F52/MillonesSoles07!F52*100,"") -> 114.90934 | G49: =IFERROR(MillonesSoles!G52/MillonesSoles07!G52*100,"") -> 120.63332 | H49: =IFERROR(MillonesSoles!H52/MillonesSoles07!H52*100,"") -> 127.88565 | I49: =IFERROR(MillonesSoles!I52/MillonesSoles07!I52*100,"") -> 137.56058 | J49: =IFERROR(MillonesSoles!J52/MillonesSoles07!J52*100,"") -> 150.08029 | K49: =IFERROR(MillonesSoles!K52/MillonesSoles07!K52*100,"") -> 159.4783 | ... U49: =IFERROR(MillonesSoles!U52/MillonesSoles07!U52*100,"") -> 269.40893
B50: Telecomunicaciones y otros servicios de información | D50: =IFERROR(MillonesSoles!D53/MillonesSoles07!D53*100,"") -> 100 | E50: =IFERROR(MillonesSoles!E53/MillonesSoles07!E53*100,"") -> 94.154802 | F50: =IFERROR(MillonesSoles!F53/MillonesSoles07!F53*100,"") -> 87.12908 | G50: =IFERROR(MillonesSoles!G53/MillonesSoles07!G53*100,"") -> 85.05389 | H50: =IFERROR(MillonesSoles!H53/MillonesSoles07!H53*100,"") -> 80.185759 | I50: =IFERROR(MillonesSoles!I53/MillonesSoles07!I53*100,"") -> 76.035005 | J50: =IFERROR(MillonesSoles!J53/MillonesSoles07!J53*100,"") -> 73.725927 | K50: =IFERROR(MillonesSoles!K53/MillonesSoles07!K53*100,"") -> 70.955421 | ... U50: =IFERROR(MillonesSoles!U53/MillonesSoles07!U53*100,"") -> 61.349022
C51: Telecomunicaciones | D51: =IFERROR(MillonesSoles!D54/MillonesSoles07!D54*100,"") -> 100 | E51: =IFERROR(MillonesSoles!E54/MillonesSoles07!E54*100,"") -> 91.090758 | F51: =IFERROR(MillonesSoles!F54/MillonesSoles07!F54*100,"") -> 80.906436 | G51: =IFERROR(MillonesSoles!G54/MillonesSoles07!G54*100,"") -> 77.394813 | H51: =IFERROR(MillonesSoles!H54/MillonesSoles07!H54*100,"") -> 70.585221 | I51: =IFERROR(MillonesSoles!I54/MillonesSoles07!I54*100,"") -> 64.61179 | J51: =IFERROR(MillonesSoles!J54/MillonesSoles07!J54*100,"") -> 61.632888 | K51: =IFERROR(MillonesSoles!K54/MillonesSoles07!K54*100,"") -> 58.426464 | ... U51: =IFERROR(MillonesSoles!U54/MillonesSoles07!U54*100,"")
C52: Otros servicios de información y comunicación | D52: =IFERROR(MillonesSoles!D55/MillonesSoles07!D55*100,"") -> 100 | E52: =IFERROR(MillonesSoles!E55/MillonesSoles07!E55*100,"") -> 102.1315 | F52: =IFERROR(MillonesSoles!F55/MillonesSoles07!F55*100,"") -> 103.99037 | G52: =IFERROR(MillonesSoles!G55/MillonesSoles07!G55*100,"") -> 105.81068 | H52: =IFERROR(MillonesSoles!H55/MillonesSoles07!H55*100,"") -> 107.0568 | I52: =IFERROR(MillonesSoles!I55/MillonesSoles07!I55*100,"") -> 110.14221 | J52: =IFERROR(MillonesSoles!J55/MillonesSoles07!J55*100,"") -> 110.32162 | K52: =IFERROR(MillonesSoles!K55/MillonesSoles07!K55*100,"") -> 111.77184 | ... U52: =IFERROR(MillonesSoles!U55/MillonesSoles07!U55*100,"")
B53: Servicios financieros, seguros y pensiones | D53: =IFERROR(MillonesSoles!D56/MillonesSoles07!D56*100,"") -> 100 | E53: =IFERROR(MillonesSoles!E56/MillonesSoles07!E56*100,"") -> 107.78722 | F53: =IFERROR(MillonesSoles!F56/MillonesSoles07!F56*100,"") -> 124.42096 | G53: =IFERROR(MillonesSoles!G56/MillonesSoles07!G56*100,"") -> 129.44295 | H53: =IFERROR(MillonesSoles!H56/MillonesSoles07!H56*100,"") -> 133.77263 | I53: =IFERROR(MillonesSoles!I56/MillonesSoles07!I56*100,"") -> 136.3878 | J53: =IFERROR(MillonesSoles!J56/MillonesSoles07!J56*100,"") -> 140.55956 | K53: =IFERROR(MillonesSoles!K56/MillonesSoles07!K56*100,"") -> 142.15802 | ... U53: =IFERROR(MillonesSoles!U56/MillonesSoles07!U56*100,"") -> 177.18353
C54: Servicios financieros | D54: =IFERROR(MillonesSoles!D57/MillonesSoles07!D57*100,"") -> 100 | E54: =IFERROR(MillonesSoles!E57/MillonesSoles07!E57*100,"") -> 107.9186 | F54: =IFERROR(MillonesSoles!F57/MillonesSoles07!F57*100,"") -> 127.32111 | G54: =IFERROR(MillonesSoles!G57/MillonesSoles07!G57*100,"") -> 134.24354 | H54: =IFERROR(MillonesSoles!H57/MillonesSoles07!H57*100,"") -> 138.91224 | I54: =IFERROR(MillonesSoles!I57/MillonesSoles07!I57*100,"") -> 141.80247 | J54: =IFERROR(MillonesSoles!J57/MillonesSoles07!J57*100,"") -> 146.61628 | K54: =IFERROR(MillonesSoles!K57/MillonesSoles07!K57*100,"") -> 150.01243 | ... U54: =IFERROR(MillonesSoles!U57/MillonesSoles07!U57*100,"")
C55: Seguros y pensiones | D55: =IFERROR(MillonesSoles!D58/MillonesSoles07!D58*100,"") -> 100 | E55: =IFERROR(MillonesSoles!E58/MillonesSoles07!E58*100,"") -> 106.93205 | F55: =IFERROR(MillonesSoles!F58/MillonesSoles07!F58*100,"") -> 106.94774 | G55: =IFERROR(MillonesSoles!G58/MillonesSoles07!G58*100,"") -> 105.51724 | H55: =IFERROR(MillonesSoles!H58/MillonesSoles07!H58*100,"") -> 109.52003 | I55: =IFERROR(MillonesSoles!I58/MillonesSoles07!I58*100,"") -> 109.00728 | J55: =IFERROR(MillonesSoles!J58/MillonesSoles07!J58*100,"") -> 110.57329 | K55: =IFERROR(MillonesSoles!K58/MillonesSoles07!K58*100,"") -> 105.63421 | ... U55: =IFERROR(MillonesSoles!U58/MillonesSoles07!U58*100,"")
B56: Servicios prestados a empresas | D56: =IFERROR(MillonesSoles!D59/MillonesSoles07!D59*100,"") -> 100 | E56: =IFERROR(MillonesSoles!E59/MillonesSoles07!E59*100,"") -> 102.20062 | F56: =IFERROR(MillonesSoles!F59/MillonesSoles07!F59*100,"") -> 106.47519 | G56: =IFERROR(MillonesSoles!G59/MillonesSoles07!G59*100,"") -> 108.26394 | H56: =IFERROR(MillonesSoles!H59/MillonesSoles07!H59*100,"") -> 112.70884 | I56: =IFERROR(MillonesSoles!I59/MillonesSoles07!I59*100,"") -> 117.14468 | J56: =IFERROR(MillonesSoles!J59/MillonesSoles07!J59*100,"") -> 121.48995 | K56: =IFERROR(MillonesSoles!K59/MillonesSoles07!K59*100,"") -> 124.28309 | ... U56: =IFERROR(MillonesSoles!U59/MillonesSoles07!U59*100,"") -> 179.87037
C57: Servicios profesionales, científicos y técnicos | D57: =IFERROR(MillonesSoles!D60/MillonesSoles07!D60*100,"") -> 100 | E57: =IFERROR(MillonesSoles!E60/MillonesSoles07!E60*100,"") -> 101.78998 | F57: =IFERROR(MillonesSoles!F60/MillonesSoles07!F60*100,"") -> 106.28245 | G57: =IFERROR(MillonesSoles!G60/MillonesSoles07!G60*100,"") -> 107.78773 | H57: =IFERROR(MillonesSoles!H60/MillonesSoles07!H60*100,"") -> 111.93665 | I57: =IFERROR(MillonesSoles!I60/MillonesSoles07!I60*100,"") -> 116.54898 | J57: =IFERROR(MillonesSoles!J60/MillonesSoles07!J60*100,"") -> 120.60082 | K57: =IFERROR(MillonesSoles!K60/MillonesSoles07!K60*100,"") -> 122.23422 | ... U57: =IFERROR(MillonesSoles!U60/MillonesSoles07!U60*100,"")
C58: Alquiler de vehículos, maquinaria y equipo y otros | D58: =IFERROR(MillonesSoles!D61/MillonesSoles07!D61*100,"") -> 100 | E58: =IFERROR(MillonesSoles!E61/MillonesSoles07!E61*100,"") -> 104.61201 | F58: =IFERROR(MillonesSoles!F61/MillonesSoles07!F61*100,"") -> 108.71972 | G58: =IFERROR(MillonesSoles!G61/MillonesSoles07!G61*100,"") -> 112.3856 | H58: =IFERROR(MillonesSoles!H61/MillonesSoles07!H61*100,"") -> 116.29588 | I58: =IFERROR(MillonesSoles!I61/MillonesSoles07!I61*100,"") -> 119.69152 | J58: =IFERROR(MillonesSoles!J61/MillonesSoles07!J61*100,"") -> 125.32436 | K58: =IFERROR(MillonesSoles!K61/MillonesSoles07!K61*100,"") -> 128.65596 | ... U58: =IFERROR(MillonesSoles!U61/MillonesSoles07!U61*100,"")
C59: Agencias de viaje y operadores turísticos | D59: =IFERROR(MillonesSoles!D62/MillonesSoles07!D62*100,"") -> 100 | E59: =IFERROR(MillonesSoles!E62/MillonesSoles07!E62*100,"") -> 101.04167 | F59: =IFERROR(MillonesSoles!F62/MillonesSoles07!F62*100,"") -> 109.64126 | G59: =IFERROR(MillonesSoles!G62/MillonesSoles07!G62*100,"") -> 108.40708 | H59: =IFERROR(MillonesSoles!H62/MillonesSoles07!H62*100,"") -> 112.67606 | I59: =IFERROR(MillonesSoles!I62/MillonesSoles07!I62*100,"") -> 113.89397 | J59: =IFERROR(MillonesSoles!J62/MillonesSoles07!J62*100,"") -> 122.60726 | K59: =IFERROR(MillonesSoles!K62/MillonesSoles07!K62*100,"") -> 128.32551 | ... U59: =IFERROR(MillonesSoles!U62/MillonesSoles07!U62*100,"")
...

Sheet Sheet1
B1: código | C1: 2016 | D1: 2017 | E1: 2018 | F1: 2019 | G1: 2020 | H1: 2021 | I1: 2022P/ | J1: 2023E/
A2: Manufactura | C2: 129.41168 | D2: 132.88561 | E2: 135.6046 | F2: 139.45704 | G2: 140.35476 | H2: 145.48799 | I2: 157.83664 | J2: 182.29555
A3: Procesamiento y conservación de carnes | C3: 169.18945 | D3: 169.00669 | E3: 157.04607 | F3: 145.49804 | G3: 124.93049 | H3: 99.739583 | I3: 203.87097 | J3: 240.76063
A4: Elaboración y preservación de pescado | C4: 155.7652 | D4: 136.25 | E4: 121.62162 | F4: 125.70124 | G4: 133.62534 | H4: 119.68254 | I4: 129.90127 | J4: 132.03704
A5: Elaboración de harina y aceite de pescado | C5: 247.01398 | D5: 198.88889 | E5: 223.02993 | F5: 210.39916 | G5: 230.59761 | H5: 250.56254 | I5: 305.70175 | J5: 318.65942
A6: Procesamiento y conservación de frutas y vegetales | C6: 87.293299 | D6: 90.823328 | E6: 99.272487 | F6: 108.69837 | G6: 113.38963 | H6: 105.90406 | I6: 112.72727 | J6: 102.95324
A7: Elaboración de aceites y grasas de origen vegetal y animal | C7: 89.225589 | D7: 94.265515 | E7: 97.190585 | F7: 94.966691 | G7: 94.616639 | H7: 96.492595 | I7: 130.71192 | J7: 164.49761
A8: Fabricación de productos lácteos | C8: 108.68141 | D8: 115.23569 | E8: 105.95533 | F8: 100.72347 | G8: 95.12987 | H8: 72.523962 | I8: 109.18919 | J8: 138.67502
A9: Molinería, fideos, panadería y otros | C9: 145.05839 | D9: 149.21348 | E9: 144.42031 | F9: 158.58229 | G9: 147.78716 | H9: 131.34796 | I9: 133.77958 | J9: 195.1442
A10: Elaboración y refinación de azúcar | C10: 190.90909 | D10: 183.82609 | E10: 141.02964 | F10: 123.06502 | G10: 163.14985 | H10: 159.02439 | I10: 230.88235 | J10: 249.16107
A11: Elaboración de otros productos alimenticios | B11: C10 | C11: 192.42844 | D11: 163.48039 | E11: 162.89453 | F11: 189.21194 | G11: 193.379 | H11: 208.0085 | I11: 184.50313 | J11: 178.38215
A12: Elaboración de alimentos preparados para animales | C12: 173.36152 | D12: 177.23577 | E12: 176.09108 | F12: 169.33086 | G12: 171.78423 | H12: 133.21033 | I12: 120.92199 | J12: 219.95754
A13: Elaboración de bebidas y productos del tabaco | B13: C11 | C13: 146.74813 | D13: 155.60379 | E13: 173.53175 | F13: 200.48544 | G13: 204.74886 | H13: 188.73708 | I13: 177.77401 | J13: 202.78912
A14: Fabricación de textiles | B14: C13 | C14: 112.91931 | D14: 110.38346 | E14: 111.94095 | F14: 117.31123 | G14: 126.45241 | H14: 120.91768 | I14: 129.43882 | J14: 147.34325
A15: Fabricación de prendas de vestir | B15: C14 | C15: 118.46479 | D15: 116.00614 | E15: 110.94743 | F15: 113.53361 | G15: 128.31216 | H15: 113.17009 | I15: 97.710548 | J15: 118.16291
A16: Fabricación de cuero y calzado | B16: C15 | C16: 105.84344 | D16: 105.30973 | E16: 110.98678 | F16: 115.22727 | G16: 116.75042 | H16: 106.78211 | I16: 105.01982 | J16: 120.0299
A17: Fabricación de madera y productos de madera | B17: C16 | C17: 115.76129 | D17: 113.46633 | E17: 111.23499 | F17: 113.42905 | G17: 116.98113 | H17: 120.9369 | I17: 140.10939 | J17: 133.80448
A18: Fabricación de papel y productos de papel | B18: C17 | C18: 128.29712 | D18: 138.71422 | E18: 142.23795 | F18: 147.98903 | G18: 153.37774 | H18: 140.09238 | I18: 130.47294 | J18: 129.59641
A19: Impresión y reproducción de grabaciones | B19: C18 | C19: 110.6724 | D19: 116.88948 | E19: 108.3731 | F19: 111.86047 | G19: 119.87028 | H19: 109.3463 | I19: 105.67583 | J19: 120.36254
A20: Refinación de petróleo | B20: C19 | C20: 249.75861 | D20: 285.28765 | E20: 360.25557 | F20: 443.52465 | G20: 455.65217 | H20: 572.94931 | I20: 876.62142 | J20: 1052.1079
A21: Fabricación de sustancias químicas básicas y abonos | C21: 90.044577 | D21: 89.044944 | E21: 89.626556 | F21: 91.395046 | G21: 98.728814 | H21: 119.87097 | I21: 118.11698 | J21: 114.21875
A22: Fabricación de productos químicos | B22: C20 | C22: 124.17414 | D22: 127.68409 | E22: 128.13496 | F22: 129.29376 | G22: 125.90949 | H22: 115.61027 | I22: 115.76437 | J22: 139.94531
A23: Fabricación de productos farmacéuticos y medicamentos | B23: C21 | C23: 121.10429 | D23: 123.28042 | E23: 122.26322 | F23: 123.20988 | G23: 123.9548 | H23: 112.23629 | I23: 98.591549 | J23: 107.5431
A24: Fabricacion de productos de caucho y plástico | B24: C22 | C24: 144.35284 | D24: 135.38896 | E24: 123.29412 | F24: 132.26172 | G24: 136.03306 | H24: 134.06326 | I24: 149.09694 | J24: 180.15936
A25: Fabricación de productos minerales no metálicos | B25: C23 | C25: 114.85866 | D25: 114.86057 | E25: 111.19313 | F25: 112.47889 | G25: 114.04675 | H25: 102.56532 | I25: 100.61872 | J25: 117.19178
A26: Industria básica de hierro y acero | C26: 72.752809 | D26: 71.95122 | E26: 83.23393 | F26: 84.96732 | G26: 80.960699 | H26: 123.46336 | I26: 165.63728 | J26: 156.68907
A27: Industria de metales preciosos y de metales no ferrosos | B27: C24 | C27: 61.211573 | D27: 80.660377 | E27: 84.240815 | F27: 76.288818 | G27: 78.798099 | H27: 154.64706 | I27: 150.91864 | J27: 123.50278
A28: Fabricación de productos metálicos diversos | B28: C25 | C28: 157.80914 | D28: 148.32837 | E28: 149.37126 | F28: 152.84004 | G28: 166.47681 | H28: 173.43425 | I28: 169.18539 | J28: 180.83522
A29: Fabricación de productos informáticos, electrónicos y ópticos | B29: C26 | C29: 104.19162 | D29: 110 | E29: 109.1954 | F29: 107.44681 | G29: 108.47458 | H29: 94.140625 | I29: 98.672566 | J29: 118.45238
A30: Fabricación de maquinaria y equipo | B30: C28 | C30: 141.87943 | D30: 135.52432 | E30: 131.50248 | F30: 135.73255 | G30: 136.53618 | H30: 114.95488 | I30: 128.77759 | J30: 160.69606
A31: Construcción de material de transporte | B31: C30 | C31: 154.83491 | D31: 149.41119 | E31: 152.76786 | F31: 155.06608 | G31: 169.85345 | H31: 189.04382 | I31: 198.63336 | J31: 206.31988
A32: Fabricación de muebles | B32: C31 | C32: 137.9773 | D32: 137.51295 | E32: 135.27725 | F32: 136.6223 | G32: 135.16091 | H32: 124.88292 | I32: 127.64826 | J32: 157.79193
A33: Otras industrias manufactureras | B33: C32 | C33: 114.76888 | D33: 126.14812 | E33: 123.71094 | F33: 120.35837 | G33: 120.42158 | H33: 117.93246 | I33: 112.17958 | J33: 118.96267
