Workbook

Sheet corriente
E3: Valor Agregado Bruto
E4: Millones de pesos corrientes
E5: Valoración: precio básico
B8: Código | C8: Descripción | F8: 2016 | G8: 2017 | H8: 2018 | I8: 2019 | J8: 2020 | K8: 2021 | L8: 2022* | M8: 2023*
A9: 1 | B9: A.01RT.0 | C9: Cultivos; servicios agrícolas aplicados a los cultivos; propagación de plantas | F9: 51399.325 | G9: 37496.682 | H9: 49259.144 | I9: 50174.131 | J9: 65833.066 | K9: 82185.581 | L9: 74444.407 | M9: 93388.346
A10: 2 | B10: A.014T.0 | C10: Ganadería; servicios aplicados a la ganadería | F10: 51315.075 | G10: 50191.307 | H10: 51641.554 | I10: 74973.944 | J10: 73947.752 | K10: 102274.2 | L10: 108698.49 | M10: 71635.667
A11: 3 | B11: A.02TT.0 | C11: Silvicultura, extracción de madera y actividades de servicios conexas | F11: 11801.645 | G11: 11635.214 | H11: 14315.094 | I11: 15556.091 | J11: 20232.104 | K11: 18086.212 | L11: 15420.371 | M11: 16785.784
A12: 4 | B12: A.03TT.0 | C12: Pesca, explotación de criaderos de peces; actividades de servicios relacionados con la pesca | F12: 1277.5941 | G12: 1459.5357 | H12: 1711.662 | I12: 1945.7756 | J12: 2152.6671 | K12: 2061.3531 | L12: 2515.6826 | M12: 2622.434
A13: 5 | B13: B.TTTT.0 | C13: Explotación de minas y canteras | F13: 4916.0713 | G13: 3071.5623 | H13: 3137.5963 | I13: 4224.1336 | J13: 4328.5262 | K13: 5729.9851 | L13: 4678.069 | M13: 5064.4276
A14: 6 | B14: C.101T.0 | C14: Procesamiento y conservación de carne | F14: 22667.773 | G14: 24098.78 | H14: 27693.028 | I14: 24217.638 | J14: 30458.072 | K14: 42638.71 | L14: 38586.507 | M14: 45157.525
A15: 7 | B15: C.1020.0 | C15: Elaboración y conservación de pescados, crustáceos y mariscos | F15: 914.80532 | G15: 1060.2 | H15: 1302.0679 | I15: 1471.8984 | J15: 1635.3621 | K15: 1682.5886 | L15: 2070.3663 | M15: 1985.4028
A16: 8 | B16: C.1030.0 | C16: Elaboración y conservación de frutas, legumbres y hortalizas | F16: 867.54223 | G16: 918.1311 | H16: 763.76222 | I16: 900.29228 | J16: 1031.2319 | K16: 1121.1503 | L16: 1394.6989 | M16: 1067.3894
A17: 9 | B17: C.1040.0 | C17: Elaboración de aceites de origen vegetal y animal excepto el de maíz | F17: 1079.2182 | G17: 1376.0729 | H17: 1533.8277 | I17: 1608.0374 | J17: 2105.1372 | K17: 2517.1394 | L17: 3499.3421 | M17: 4203.5596
A18: 10 | B18: C.1050.0 | C18: Elaboración de productos lácteos | F18: 9487.4755 | G18: 10022.285 | H18: 10689.96 | I18: 12405.113 | J18: 14093.012 | K18: 15939.38 | L18: 16752.459 | M18: 17007.296
A19: 11 | B19: C.10RT.0 | C19: Elaboración de productos de molinería, almidones y productos derivados del almidón; Elaboración de alimentos preparados para animales | F19: 8307.9197 | G19: 9511.4233 | H19: 10589.58 | I19: 10319.818 | J19: 11722.772 | K19: 7110.6942 | L19: 8248.7293 | M19: 10176.197
A20: 12 | B20: C.107V.0 | C20: Elaboración de productos de panadería y confitería; Elaboración de productos de fideería | F20: 15061.909 | G20: 17183.035 | H20: 18046.672 | I20: 19838.165 | J20: 18650.342 | K20: 19739.586 | L20: 22929.36 | M20: 26243.136
... A56: 48 | B56: T.9700.0 | C56: Actividades de los hogares como empleadores de personal doméstico | F56: 20354.134 | G56: 22083.492 | H56: 24944.505 | I56: 26359.826 | J56: 24248.958 | K56: 25021.77 | L56: 27070.71 | M56: 29353.462
B57: Total VAB | F57: 1544182.2 | G57: 1655307.5 | H57: 1784630.3 | I57: 1951187.9 | J57: 1997760.9 | K57: 2350374.9 | L57: 2569123.7 | M57: 2679589.5
B58: D.21 - D.31 | C58: Impuestos menos subvenciones sobre los productos | F58: 189587.84 | G58: 208831.66 | H58: 223098.68 | I58: 242483.54 | J58: 252443.93 | K58: 295089.14 | L58: 337311.35 | M58: 348351.12
B59: PIB | F59: 1733770 | G59: 1864139.2 | H59: 2007729 | I59: 2193671.4 | J59: 2250204.8 | K59: 2645464 | L59: 2906435.1 | M59: 3027940.6
A60: * 2022 datos preliminares, 2023 datos provisorios
A61: Nota: La suma de los parciales puede no coincidir con el total debido al redondeo de las cifras.

Sheet constante
E3: Valor Agregado Bruto
E4: Millones de pesos a precios constantes del año 2016
E5: Valoración: precio básico
B8: Código | C8: Descripción | F8: 2016 | G8: 2017 | H8: 2018 | I8: 2019 | J8: 2020 | K8: 2021 | L8: 2022* | M8: 2023*
A9: 1 | B9: A.01RT.0 | C9: Cultivos; servicios agrícolas aplicados a los cultivos; propagación de plantas | F9: 51399.325 | G9: 40403.576 | H9: 48917.284 | I9: 50161.172 | J9: 45282.555 | K9: 52883.901 | L9: 43637.888 | M9: 51010.425
A10: 2 | B10: A.014T.0 | C10: Ganadería; servicios aplicados a la ganadería | F10: 51315.075 | G10: 49481.623 | H10: 45993.748 | I10: 47332.376 | J10: 42127.455 | K10: 47866.59 | L10: 45445.81 | M10: 45789.494
A11: 3 | B11: A.02TT.0 | C11: Silvicultura, extracción de madera y actividades de servicios conexas | F11: 11801.645 | G11: 12559.35 | H11: 13562.516 | I11: 13794.849 | J11: 14823.759 | K11: 14045.256 | L11: 12902.823 | M11: 14621.796
A12: 4 | B12: A.03TT.0 | C12: Pesca, explotación de criaderos de peces; actividades de servicios relacionados con la pesca | F12: 1277.5941 | G12: 1382.7829 | H12: 1542.0234 | I12: 1548.4442 | J12: 1438.1077 | K12: 1369.6757 | L12: 1539.8624 | M12: 1544.7221
A13: 5 | B13: B.TTTT.0 | C13: Explotación de minas y canteras | F13: 4916.0713 | G13: 3835.4013 | H13: 3486.486 | I13: 3425.6948 | J13: 3369.4919 | K13: 4385.3652 | L13: 4460.3826 | M13: 4289.7323
A14: 6 | B14: C.101T.0 | C14: Procesamiento y conservación de carne | F14: 22667.773 | G14: 25691.056 | H14: 27205.805 | I14: 24802.967 | J14: 23957.106 | K14: 26357.768 | L14: 27166.629 | M14: 27660.462
A15: 7 | B15: C.1020.0 | C15: Elaboración y conservación de pescados, crustáceos y mariscos | F15: 914.80532 | G15: 1059.0166 | H15: 1158.1492 | I15: 1197.6442 | J15: 1240.9096 | K15: 1197.1778 | L15: 1383.8412 | M15: 1435.7167
A16: 8 | B16: C.1030.0 | C16: Elaboración y conservación de frutas, legumbres y hortalizas | F16: 867.54223 | G16: 649.04901 | H16: 575.30807 | I16: 582.03579 | J16: 627.52737 | K16: 649.15507 | L16: 583.37609 | M16: 597.53899
A17: 9 | B17: C.1040.0 | C17: Elaboración de aceites de origen vegetal y animal excepto el de maíz | F17: 1079.2182 | G17: 1144.2664 | H17: 1233.4465 | I17: 1207.073 | J17: 1319.0175 | K17: 1456.7267 | L17: 1706.5704 | M17: 1581.7513
A18: 10 | B18: C.1050.0 | C18: Elaboración de productos lácteos | F18: 9487.4755 | G18: 8680.7113 | H18: 7892.4514 | I18: 8169.8699 | J18: 8305.7153 | K18: 9050.0551 | L18: 9140.5756 | M18: 9368.7856
A19: 11 | B19: C.10RT.0 | C19: Elaboración de productos de molinería, almidones y productos derivados del almidón; Elaboración de alimentos preparados para animales | F19: 8307.9197 | G19: 8150.8165 | H19: 8970.497 | I19: 8162.3503 | J19: 9365.7609 | K19: 7564.6609 | L19: 8029.261 | M19: 8596.6438
A20: 12 | B20: C.107V.0 | C20: Elaboración de productos de panadería y confitería; Elaboración de productos de fideería | F20: 15061.909 | G20: 15319.999 | H20: 14495.905 | I20: 14775.034 | J20: 13647.306 | K20: 13984.396 | L20: 14656.842 | M20: 14747.698
... A56: 48 | B56: T.9700.0 | C56: Actividades de los hogares como empleadores de personal doméstico | F56: 20354.134 | G56: 19823.602 | H56: 20633 | I56: 20158 | J56: 17192.967 | K56: 16713.095 | L56: 16741.616 | M56: 16991.733
C57: Total VAB | F57: 1544182.2 | G57: 1562127.4 | H57: 1568333.9 | I57: 1587121.6 | J57: 1469080.7 | K57: 1552098.9 | L57: 1619811.8 | M57: 1633495
B58: D.21 - D.31 | C58: Impuestos menos subvenciones sobre los productos | F58: 189587.84 | G58: 201816.71 | H58: 198516.88 | I58: 196131.73 | J58: 182972.8 | K58: 196505.16 | L58: 207238.57 | M58: 207114.46
C59: PIB | F59: 1733770 | G59: 1763944.2 | H59: 1766850.7 | I59: 1783253.3 | J59: 1652053.5 | K59: 1748604.1 | L59: 1827050.4 | M59: 1840609.5
A60: * 2022 datos preliminares, 2023 datos provisorios
A61: Nota: La suma de los parciales puede no coincidir con el total debido al redondeo de las cifras.

Sheet Deflactores
B1: Código | C1: Descripción | F1: código | G1: 2016 | H1: 2017 | I1: 2018 | J1: 2019 | K1: 2020 | L1: 2021 | M1: 2022* | N1: 2023*
A2: 1 | B2: A.01RT.0 | C2: Cultivos; servicios agrícolas aplicados a los cultivos; propagación de plantas | G2: =+corriente!F9/constante!F9*100 -> 100 | H2: =+corriente!G9/constante!G9*100 -> 92.805357 | I2: =+corriente!H9/constante!H9*100 -> 100.69885 | J2: =+corriente!I9/constante!I9*100 -> 100.02583 | K2: =+corriente!J9/constante!J9*100 -> 145.38284 | L2: =+corriente!K9/constante!K9*100 -> 155.40756 | M2: =+corriente!L9/constante!L9*100 -> 170.5958 | N2: =+corriente!M9/constante!M9*100 -> 183.07698
A3: 2 | B3: A.014T.0 | C3: Ganadería; servicios aplicados a la ganadería | G3: =+corriente!F10/constante!F10*100 -> 100 | H3: =+corriente!G10/constante!G10*100 -> 101.43424 | I3: =+corriente!H10/constante!H10*100 -> 112.27951 | J3: =+corriente!I10/constante!I10*100 -> 158.39886 | K3: =+corriente!J10/constante!J10*100 -> 175.5334 | L3: =+corriente!K10/constante!K10*100 -> 213.6651 | M3: =+corriente!L10/constante!L10*100 -> 239.18264 | N3: =+corriente!M10/constante!M10*100 -> 156.44564
A4: 3 | B4: A.02TT.0 | C4: Silvicultura, extracción de madera y actividades de servicios conexas | G4: =+corriente!F11/constante!F11*100 -> 100 | H4: =+corriente!G11/constante!G11*100 -> 92.64185 | I4: =+corriente!H11/constante!H11*100 -> 105.54895 | J4: =+corriente!I11/constante!I11*100 -> 112.7674 | K4: =+corriente!J11/constante!J11*100 -> 136.4843 | L4: =+corriente!K11/constante!K11*100 -> 128.77096 | M4: =+corriente!L11/constante!L11*100 -> 119.51161 | N4: =+corriente!M11/constante!M11*100 -> 114.79974
A5: 4 | B5: A.03TT.0 | C5: Pesca, explotación de criaderos de peces; actividades de servicios relacionados con la pesca | G5: =+corriente!F12/constante!F12*100 -> 100 | H5: =+corriente!G12/constante!G12*100 -> 105.5506 | I5: =+corriente!H12/constante!H12*100 -> 111.00104 | J5: =+corriente!I12/constante!I12*100 -> 125.66004 | K5: =+corriente!J12/constante!J12*100 -> 149.68748 | L5: =+corriente!K12/constante!K12*100 -> 150.49936 | M5: =+corriente!L12/constante!L12*100 -> 163.3706 | N5: =+corriente!M12/constante!M12*100 -> 169.76737
A6: 5 | B6: B.TTTT.0 | C6: Explotación de minas y canteras | G6: =+corriente!F13/constante!F13*100 -> 100 | H6: =+corriente!G13/constante!G13*100 -> 80.084507 | I6: =+corriente!H13/constante!H13*100 -> 89.993084 | J6: =+corriente!I13/constante!I13*100 -> 123.30735 | K6: =+corriente!J13/constante!J13*100 -> 128.46228 | L6: =+corriente!K13/constante!K13*100 -> 130.66152 | M6: =+corriente!L13/constante!L13*100 -> 104.88044 | N6: =+corriente!M13/constante!M13*100 -> 118.05929
A7: 6 | B7: C.101T.0 | C7: Procesamiento y conservación de carne | G7: =+corriente!F14/constante!F14*100 -> 100 | H7: =+corriente!G14/constante!G14*100 -> 93.802219 | I7: =+corriente!H14/constante!H14*100 -> 101.79088 | J7: =+corriente!I14/constante!I14*100 -> 97.640084 | K7: =+corriente!J14/constante!J14*100 -> 127.13586 | L7: =+corriente!K14/constante!K14*100 -> 161.76905 | M7: =+corriente!L14/constante!L14*100 -> 142.03642 | N7: =+corriente!M14/constante!M14*100 -> 163.25658
A8: 7 | B8: C.1020.0 | C8: Elaboración y conservación de pescados, crustáceos y mariscos | G8: =+corriente!F15/constante!F15*100 -> 100 | H8: =+corriente!G15/constante!G15*100 -> 100.11175 | I8: =+corriente!H15/constante!H15*100 -> 112.42662 | J8: =+corriente!I15/constante!I15*100 -> 122.89948 | K8: =+corriente!J15/constante!J15*100 -> 131.78736 | L8: =+corriente!K15/constante!K15*100 -> 140.54626 | M8: =+corriente!L15/constante!L15*100 -> 149.61011 | N8: =+corriente!M15/constante!M15*100 -> 138.28653
A9: 8 | B9: C.1030.0 | C9: Elaboración y conservación de frutas, legumbres y hortalizas | G9: =+corriente!F16/constante!F16*100 -> 100 | H9: =+corriente!G16/constante!G16*100 -> 141.4579 | I9: =+corriente!H16/constante!H16*100 -> 132.75708 | J9: =+corriente!I16/constante!I16*100 -> 154.67988 | K9: =+corriente!J16/constante!J16*100 -> 164.33258 | L9: =+corriente!K16/constante!K16*100 -> 172.70916 | M9: =+corriente!L16/constante!L16*100 -> 239.07372 | N9: =+corriente!M16/constante!M16*100 -> 178.63091
A10: 9 | B10: C.1040.0 | C10: Elaboración de aceites de origen vegetal y animal excepto el de maíz | G10: =+corriente!F17/constante!F17*100 -> 100 | H10: =+corriente!G17/constante!G17*100 -> 120.25809 | I10: =+corriente!H17/constante!H17*100 -> 124.353 | J10: =+corriente!I17/constante!I17*100 -> 133.21791 | K10: =+corriente!J17/constante!J17*100 -> 159.59888 | L10: =+corriente!K17/constante!K17*100 -> 172.79422 | M10: =+corriente!L17/constante!L17*100 -> 205.05114 | N10: =+corriente!M17/constante!M17*100 -> 265.75352
A11: 10 | B11: C.1050.0 | C11: Elaboración de productos lácteos | G11: =+corriente!F18/constante!F18*100 -> 100 | H11: =+corriente!G18/constante!G18*100 -> 115.45465 | I11: =+corriente!H18/constante!H18*100 -> 135.44536 | J11: =+corriente!I18/constante!I18*100 -> 151.83978 | K11: =+corriente!J18/constante!J18*100 -> 169.67849 | L11: =+corriente!K18/constante!K18*100 -> 176.12467 | M11: =+corriente!L18/constante!L18*100 -> 183.27575 | N11: =+corriente!M18/constante!M18*100 -> 181.53148
A12: 11 | B12: C.10RT.0 | C12: Elaboración de productos de molinería, almidones y productos derivados del almidón; Elaboración de alimentos preparados para animales | G12: =+corriente!F19/constante!F19*100 -> 100 | H12: =+corriente!G19/constante!G19*100 -> 116.69289 | I12: =+corriente!H19/constante!H19*100 -> 118.04898 | J12: =+corriente!I19/constante!I19*100 -> 126.43195 | K12: =+corriente!J19/constante!J19*100 -> 125.16625 | L12: =+corriente!K19/constante!K19*100 -> 93.99885 | M12: =+corriente!L19/constante!L19*100 -> 102.73336 | N12: =+corriente!M19/constante!M19*100 -> 118.37407
A13: 12 | B13: C.107V.0 | C13: Elaboración de productos de panadería y confitería; Elaboración de productos de fideería | G13: =+corriente!F20/constante!F20*100 -> 100 | H13: =+corriente!G20/constante!G20*100 -> 112.16081 | I13: =+corriente!H20/constante!H20*100 -> 124.49496 | J13: =+corriente!I20/constante!I20*100 -> 134.26815 | K13: =+corriente!J20/constante!J20*100 -> 136.65952 | L13: =+corriente!K20/constante!K20*100 -> 141.15437 | M13: =+corriente!L20/constante!L20*100 -> 156.44134 | N13: =+corriente!M20/constante!M20*100 -> 177.94734
A14: 13 | B14: C.107X.1 C.107X.9 | C14: Elaboración de jarabes y concentrados; Elaboración de azúcar; Elaboración de cacao, chocolates y de otros productos alimenticios n.c.p. Elaboración de comidas y platos preparados | G14: =+corriente!F21/constante!F21*100 -> 100 | H14: =+corriente!G21/constante!G21*100 -> 99.261221 | I14: =+corriente!H21/constante!H21*100 -> 103.28483 | J14: =+corriente!I21/constante!I21*100 -> 110.6141 | K14: =+corriente!J21/constante!J21*100 -> 113.9011 | L14: =+corriente!K21/constante!K21*100 -> 112.60243 | M14: =+corriente!L21/constante!L21*100 -> 97.870943 | N14: =+corriente!M21/constante!M21*100 -> 131.21542
A15: 14 | B15: C.1PTT.0 | C15: Elaboración de bebidas; Elaboración de productos de tabaco | F15: C11 | G15: =+corriente!F22/constante!F22*100 -> 100 | H15: =+corriente!G22/constante!G22*100 -> 109.48621 | I15: =+corriente!H22/constante!H22*100 -> 130.97125 | J15: =+corriente!I22/constante!I22*100 -> 141.89861 | K15: =+corriente!J22/constante!J22*100 -> 145.81519 | L15: =+corriente!K22/constante!K22*100 -> 163.84091 | M15: =+corriente!L22/constante!L22*100 -> 175.34252 | N15: =+corriente!M22/constante!M22*100 -> 180.58227
A16: 15 | B16: C.13TT.0 | C16: Fabricación de productos textiles | F16: C13 | G16: =+corriente!F23/constante!F23*100 -> 100 | H16: =+corriente!G23/constante!G23*100 -> 104.57566 | I16: =+corriente!H23/constante!H23*100 -> 123.31798 | J16: =+corriente!I23/constante!I23*100 -> 117.45976 | K16: =+corriente!J23/constante!J23*100 -> 118.61049 | L16: =+corriente!K23/constante!K23*100 -> 136.00529 | M16: =+corriente!L23/constante!L23*100 -> 145.4341 | N16: =+corriente!M23/constante!M23*100 -> 133.65277
A17: 16 | B17: C.14TT.0 | C17: Fabricación de prendas de vestir de todo tipo de material; artículos de piel y de punto y ganchillo | F17: C14 | G17: =+corriente!F24/constante!F24*100 -> 100 | H17: =+corriente!G24/constante!G24*100 -> 100.46887 | I17: =+corriente!H24/constante!H24*100 -> 120.63816 | J17: =+corriente!I24/constante!I24*100 -> 131.41853 | K17: =+corriente!J24/constante!J24*100 -> 146.3616 | L17: =+corriente!K24/constante!K24*100 -> 158.71642 | M17: =+corriente!L24/constante!L24*100 -> 182.52083 | N17: =+corriente!M24/constante!M24*100 -> 169.56435
A18: 17 | B18: C.15TT.0 | C18: Fabricación de productos de cuero y productos conexos | F18: C15 | G18: =+corriente!F25/constante!F25*100 -> 100 | H18: =+corriente!G25/constante!G25*100 -> 114.26551 | I18: =+corriente!H25/constante!H25*100 -> 75.69224 | J18: =+corriente!I25/constante!I25*100 -> 186.44937 | K18: =+corriente!J25/constante!J25*100 -> 256.78233 | L18: =+corriente!K25/constante!K25*100 -> 175.42214 | M18: =+corriente!L25/constante!L25*100 -> 172.38164 | N18: =+corriente!M25/constante!M25*100 -> 163.11029
A19: 18 | B19: C.16TT.0 | C19: Producción de madera y fabricación de madera y corcho, excepto muebles; fabricación de artículos de paja y de materiales trenzables | F19: C16 | G19: =+corriente!F26/constante!F26*100 -> 100 | H19: =+corriente!G26/constante!G26*100 -> 91.716363 | I19: =+corriente!H26/constante!H26*100 -> 104.20861 | J19: =+corriente!I26/constante!I26*100 -> 118.46039 | K19: =+corriente!J26/constante!J26*100 -> 137.70776 | L19: =+corriente!K26/constante!K26*100 -> 197.38919 | M19: =+corriente!L26/constante!L26*100 -> 170.17162 | N19: =+corriente!M26/constante!M26*100 -> 124.18774
A20: 19 | B20: C.170V.1 C.170V.9 | C20: Fabricación de pasta de madera; Fabricación de papel y de productos de papel y cartón | F20: C17 | G20: =+corriente!F27/constante!F27*100 -> 100 | H20: =+corriente!G27/constante!G27*100 -> 99.81838 | I20: =+corriente!H27/constante!H27*100 -> 175.60634 | J20: =+corriente!I27/constante!I27*100 -> 159.40256 | K20: =+corriente!J27/constante!J27*100 -> 77.56079 | L20: =+corriente!K27/constante!K27*100 -> 207.67555 | M20: =+corriente!L27/constante!L27*100 -> 269.99082 | N20: =+corriente!M27/constante!M27*100 -> 144.111
A21: 20 | B21: C.18TT.0 | C21: Actividades de impresión. Servicios relacionados con la impresión. Reproducción de grabaciones | F21: C18 | G21: =+corriente!F28/constante!F28*100 -> 100 | H21: =+corriente!G28/constante!G28*100 -> 107.61749 | I21: =+corriente!H28/constante!H28*100 -> 109.52471 | J21: =+corriente!I28/constante!I28*100 -> 112.39701 | K21: =+corriente!J28/constante!J28*100 -> 116.93525 | L21: =+corriente!K28/constante!K28*100 -> 121.08206 | M21: =+corriente!L28/constante!L28*100 -> 127.70267 | N21: =+corriente!M28/constante!M28*100 -> 138.62657
A22: 21 | B22: C.19TT.0 | C22: Fabricación de coque y de productos de la refinación de petróleo | F22: C19 | G22: =+corriente!F29/constante!F29*100 -> 100 | H22: =+corriente!G29/constante!G29*100 -> 91.443228 | I22: =+corriente!H29/constante!H29*100 -> 81.536083 | J22: =+corriente!I29/constante!I29*100 -> 80.392794 | K22: =+corriente!J29/constante!J29*100 -> 78.715495 | L22: =+corriente!K29/constante!K29*100 -> 65.796738 | M22: =+corriente!L29/constante!L29*100 -> 93.470336 | N22: =+corriente!M29/constante!M29*100 -> 89.876754
A23: 22 | B23: C.20TV.0 | C23: Fabricación de abonos y compuestos de nitrógeno; fabricación de plaguicidas y otros productos químicos de usos agropecuario | G23: =+corriente!F30/constante!F30*100 -> 100 | H23: =+corriente!G30/constante!G30*100 -> 97.374961 | I23: =+corriente!H30/constante!H30*100 -> 91.619921 | J23: =+corriente!I30/constante!I30*100 -> 107.72309 | K23: =+corriente!J30/constante!J30*100 -> 151.14395 | L23: =+corriente!K30/constante!K30*100 -> 749.65497 | M23: =+corriente!L30/constante!L30*100 -> 842.4802 | N23: =+corriente!M30/constante!M30*100 -> 854.59964
A24: 23 | B24: C.20TX.0 | C24: Fabricación de sustancias químicas básicas y biocombustibles. Fabricación de plásticos y caucho sintético; Fabricación de productos de limpieza y tocador; Fabricación de pinturas, barnices y productos de revestimiento similares, tintas de imprenta y masillas; fabricación de otros productos químicos n.c.p.; fabricación de fibras artificiales | F24: C20 | G24: =+corriente!F31/constante!F31*100 -> 100 | H24: =+corriente!G31/constante!G31*100 -> 100.08518 | I24: =+corriente!H31/constante!H31*100 -> 100.70288 | J24: =+corriente!I31/constante!I31*100 -> 117.89802 | K24: =+corriente!J31/constante!J31*100 -> 144.32836 | L24: =+corriente!K31/constante!K31*100 -> 138.92075 | M24: =+corriente!L31/constante!L31*100 -> 161.91839 | N24: =+corriente!M31/constante!M31*100 -> 173.02241
A25: 24 | B25: C.2100.0 | C25: Fabricación de productos farmacéuticos, sustancias químicas medicinales y productos botánicos de uso farmaceútico | F25: C21 | G25: =+corriente!F32/constante!F32*100 -> 100 | H25: =+corriente!G32/constante!G32*100 -> 98.716162 | I25: =+corriente!H32/constante!H32*100 -> 107.56471 | J25: =+corriente!I32/constante!I32*100 -> 121.12555 | K25: =+corriente!J32/constante!J32*100 -> 139.02776 | L25: =+corriente!K32/constante!K32*100 -> 148.51597 | M25: =+corriente!L32/constante!L32*100 -> 130.15609 | N25: =+corriente!M32/constante!M32*100 -> 113.38879
A26: 25 | B26: C.22TT.0 | C26: Fabricación de productos de caucho y plástico | F26: C22 | G26: =+corriente!F33/constante!F33*100 -> 100 | H26: =+corriente!G33/constante!G33*100 -> 93.436103 | I26: =+corriente!H33/constante!H33*100 -> 103.65527 | J26: =+corriente!I33/constante!I33*100 -> 129.02273 | K26: =+corriente!J33/constante!J33*100 -> 136.35418 | L26: =+corriente!K33/constante!K33*100 -> 156.39818 | M26: =+corriente!L33/constante!L33*100 -> 163.72064 | N26: =+corriente!M33/constante!M33*100 -> 183.49621
A27: 26 | B27: C.23TT.0 | C27: Fabricación de otros productos minerales no metálicos | F27: C23 | G27: =+corriente!F34/constante!F34*100 -> 100 | H27: =+corriente!G34/constante!G34*100 -> 125.40875 | I27: =+corriente!H34/constante!H34*100 -> 119.25778 | J27: =+corriente!I34/constante!I34*100 -> 137.31168 | K27: =+corriente!J34/constante!J34*100 -> 140.73373 | L27: =+corriente!K34/constante!K34*100 -> 147.54159 | M27: =+corriente!L34/constante!L34*100 -> 194.7336 | N27: =+corriente!M34/constante!M34*100 -> 278.4141
A28: 27 | B28: C.2PTT.0 | C28: Fabricación de metales comunes; Fabricación de productos elaborados de metal excepto maquinaria y equipo | F28: C31 | G28: =+corriente!F35/constante!F35*100 -> 100 | H28: =+corriente!G35/constante!G35*100 -> 100.87256 | I28: =+corriente!H35/constante!H35*100 -> 110.88171 | J28: =+corriente!I35/constante!I35*100 -> 131.20191 | K28: =+corriente!J35/constante!J35*100 -> 154.38506 | L28: =+corriente!K35/constante!K35*100 -> 191.09958 | M28: =+corriente!L35/constante!L35*100 -> 188.87 | N28: =+corriente!M35/constante!M35*100 -> 154.94377
A29: 28 | B29: C.2QTT.0 | C29: Fabricación de productos de informática, de electrónica y de óptica; Fabricación de equipo eléctrico; Fabricación de maquinaria y equipo n.c.p. | F29: C27 | G29: =+corriente!F36/constante!F36*100 -> 100 | H29: =+corriente!G36/constante!G36*100 -> 100.6734 | I29: =+corriente!H36/constante!H36*100 -> 104.31392 | J29: =+corriente!I36/constante!I36*100 -> 128.17288 | K29: =+corriente!J36/constante!J36*100 -> 155.8043 | L29: =+corriente!K36/constante!K36*100 -> 155.40009 | M29: =+corriente!L36/constante!L36*100 -> 167.48785 | N29: =+corriente!M36/constante!M36*100 -> 176.36273
A30: 29 | B30: C.PPTT.0 | C30: Fabricación de vehículos automotores, remolques y semirremolques; Fabricación de otros tipos de equipo de transporte | F30: C30 | G30: =+corriente!F37/constante!F37*100 -> 100 | H30: =+corriente!G37/constante!G37*100 -> 108.67081 | I30: =+corriente!H37/constante!H37*100 -> 75.124699 | J30: =+corriente!I37/constante!I37*100 -> 78.734895 | K30: =+corriente!J37/constante!J37*100 -> 76.860997 | L30: =+corriente!K37/constante!K37*100 -> 110.13745 | M30: =+corriente!L37/constante!L37*100 -> 101.0111 | N30: =+corriente!M37/constante!M37*100 -> 183.47647
A31: 30 | B31: C.3PTT.0 | C31: Fabricación de muebles; Fabricación de instrumentos y suministros médicos y dentales; Fabricación de joyas y artículos conexos, instrumentos musicales, artículos de deporte, juguetes. Otras industrias manufactureras n.c.p.;Reparación e instalación de maquinaria y equipo | F31: C32 | G31: =+corriente!F38/constante!F38*100 -> 100 | H31: =+corriente!G38/constante!G38*100 -> 109.76692 | I31: =+corriente!H38/constante!H38*100 -> 117.16064 | J31: =+corriente!I38/constante!I38*100 -> 123.31769 | K31: =+corriente!J38/constante!J38*100 -> 141.57609 | L31: =+corriente!K38/constante!K38*100 -> 153.10191 | M31: =+corriente!L38/constante!L38*100 -> 161.83114 | N31: =+corriente!M38/constante!M38*100 -> 145.24621
A32: 31 | B32: D.35TT.0 | C32: Suministro de electricidad, gas, vapor y aire acondicionado | G32: =+corriente!F39/constante!F39*100 -> 100 | H32: =+corriente!G39/constante!G39*100 -> 107.68446 | I32: =+corriente!H39/constante!H39*100 -> 106.32594 | J32: =+corriente!I39/constante!I39*100 -> 97.229494 | K32: =+corriente!J39/constante!J39*100 -> 120.28783 | L32: =+corriente!K39/constante!K39*100 -> 148.28832 | M32: =+corriente!L39/constante!L39*100 -> 117.39712 | N32: =+corriente!M39/constante!M39*100 -> 120.95806
A33: 32 | B33: E.TTTT.0 | C33: Suministro de agua; alcantarillado, gestión de desechos y actividades de saneamiento | G33: =+corriente!F40/constante!F40*100 -> 100 | H33: =+corriente!G40/constante!G40*100 -> 116.68694 | I33: =+corriente!H40/constante!H40*100 -> 121.51567 | J33: =+corriente!I40/constante!I40*100 -> 123.78184 | K33: =+corriente!J40/constante!J40*100 -> 136.94151 | L33: =+corriente!K40/constante!K40*100 -> 153.73932 | M33: =+corriente!L40/constante!L40*100 -> 162.06502 | N33: =+corriente!M40/constante!M40*100 -> 176.72681
A34: 33 | B34: F.TTTT.0 | C34: Construcción | G34: =+corriente!F41/constante!F41*100 -> 100 | H34: =+corriente!G41/constante!G41*100 -> 111.28737 | I34: =+corriente!H41/constante!H41*100 -> 117.47366 | J34: =+corriente!I41/constante!I41*100 -> 128.69844 | K34: =+corriente!J41/constante!J41*100 -> 138.05832 | L34: =+corriente!K41/constante!K41*100 -> 152.14649 | M34: =+corriente!L41/constante!L41*100 -> 170.06809 | N34: =+corriente!M41/constante!M41*100 -> 180.70137
A35: 34 | B35: G.4PTT.0 | C35: Comercio al por mayor y al por menor; reparación de los vehículos de motor y de las motocicletas, no incluye reexportaciones. Incluye compraventa de empresas no dedicadas exclusivamente a la compraventa | G35: =+corriente!F42/constante!F42*100 -> 100 | H35: =+corriente!G42/constante!G42*100 -> 103.81967 | I35: =+corriente!H42/constante!H42*100 -> 111.33569 | J35: =+corriente!I42/constante!I42*100 -> 120.54699 | K35: =+corriente!J42/constante!J42*100 -> 138.49538 | L35: =+corriente!K42/constante!K42*100 -> 151.6141 | M35: =+corriente!L42/constante!L42*100 -> 164.62407 | N35: =+corriente!M42/constante!M42*100 -> 177.8578
A36: 35 | B36: G.4QTT.0 G.4RTT.0 | C36: Compraventa; Re-exportaciones | G36: =+corriente!F43/constante!F43*100 -> 100 | H36: =+corriente!G43/constante!G43*100 -> 93.402758 | I36: =+corriente!H43/constante!H43*100 -> 106.67889 | J36: =+corriente!I43/constante!I43*100 -> 147.71182 | K36: =+corriente!J43/constante!J43*100 -> 146.48225 | L36: =+corriente!K43/constante!K43*100 -> 422.37217 | M36: =+corriente!L43/constante!L43*100 -> 421.24896 | N36: =+corriente!M43/constante!M43*100 -> 292.19525
A37: 36 | B37: H.TTTT.0 | C37: Transporte y almacenamiento | G37: =+corriente!F44/constante!F44*100 -> 100 | H37: =+corriente!G44/constante!G44*100 -> 101.25694 | I37: =+corriente!H44/constante!H44*100 -> 111.30155 | J37: =+corriente!I44/constante!I44*100 -> 121.4619 | K37: =+corriente!J44/constante!J44*100 -> 131.36115 | L37: =+corriente!K44/constante!K44*100 -> 138.80908 | M37: =+corriente!L44/constante!L44*100 -> 147.53684 | N37: =+corriente!M44/constante!M44*100 -> 155.99742
A38: 37 | B38: I.TTTT.0 | C38: Alojamiento y servicios de comida | G38: =+corriente!F45/constante!F45*100 -> 100 | H38: =+corriente!G45/constante!G45*100 -> 108.31333 | I38: =+corriente!H45/constante!H45*100 -> 115.77306 | J38: =+corriente!I45/constante!I45*100 -> 118.64133 | K38: =+corriente!J45/constante!J45*100 -> 129.01211 | L38: =+corriente!K45/constante!K45*100 -> 135.30393 | M38: =+corriente!L45/constante!L45*100 -> 143.42486 | N38: =+corriente!M45/constante!M45*100 -> 164.96661
A39: 38 | B39: J.TTTT.0 | C39: Información y comunicación | G39: =+corriente!F46/constante!F46*100 -> 100 | H39: =+corriente!G46/constante!G46*100 -> 104.98435 | I39: =+corriente!H46/constante!H46*100 -> 112.12818 | J39: =+corriente!I46/constante!I46*100 -> 118.3822 | K39: =+corriente!J46/constante!J46*100 -> 122.75358 | L39: =+corriente!K46/constante!K46*100 -> 126.48495 | M39: =+corriente!L46/constante!L46*100 -> 131.23244 | N39: =+corriente!M46/constante!M46*100 -> 126.38364
A40: 39 | B40: K.TTTT.0 | C40: Actividades financieras y de seguros | G40: =+corriente!F47/constante!F47*100 -> 100 | H40: =+corriente!G47/constante!G47*100 -> 105.52429 | I40: =+corriente!H47/constante!H47*100 -> 112.77926 | J40: =+corriente!I47/constante!I47*100 -> 119.06953 | K40: =+corriente!J47/constante!J47*100 -> 123.24602 | L40: =+corriente!K47/constante!K47*100 -> 130.53634 | M40: =+corriente!L47/constante!L47*100 -> 146.86406 | N40: =+corriente!M47/constante!M47*100 -> 160.68785
...
