Workbook

Sheet Prod
A2: descripcion | B2: Comercio al por mayor, excepto de vehículos de motor y motocicletas
A4: Suma de prod_trab | B4: Etiquetas de columna
A5: Etiquetas de fila | B5: 2016 | C5: 2017 | D5: 2018 | E5: 2019 | F5: 2020 | G5: 2021 | H5: 2022 | I5: 2023
A6: Chile | B6: 3971.3581 | C6: 3658.3158 | D6: 3568.5421 | E6: 3650.2226 | F6: 3286.4673 | G6: 3882.8864 | H6: 3502.0706
A7: México | B7: 27350.44 | C7: 24470.541 | D7: 37965.324 | E7: 36723.233 | F7: 30336.691 | G7: 38301.13 | H7: 42667.159 | I7: 60404.748
L9: promedio
B10: Chile | C10: =C6/B6*100-100 -> -7.8824983 | D10: =D6/C6*100-100 -> -2.4539641 | E10: =E6/D6*100-100 -> 2.2889031 | F10: =F6/E6*100-100 -> -9.9652905 | G10: =G6/F6*100-100 -> 18.147727 | H10: =H6/G6*100-100 -> -9.8075427 | L10: =AVERAGE(C10:H10) -> -1.612111
B11: México | C11: =C7/B7*100-100 -> -10.529626 | D11: =D7/C7*100-100 -> 55.147059 | E11: =E7/D7*100-100 -> -3.2716483 | F11: =F7/E7*100-100 -> -17.39101 | G11: =G7/F7*100-100 -> 26.253484 | H11: =H7/G7*100-100 -> 11.399218 | I11: =I7/H7*100-100 -> 41.571994 | L11: =AVERAGE(C11:I11) -> 14.739924
A13: Chile | B13: =B6/$D6 -> 1.1128797 | C13: =C6/$D6 -> 1.025157 | D13: =D6/$D6 -> 1 | E13: =E6/$D6 -> 1.022889 | F13: =F6/$D6 -> 0.92095517 | G13: =G6/$D6 -> 1.0880876 | H13: =H6/$D6 -> 0.98137294
A14: México | B14: =B7/$D7 -> 0.7204058 | C14: =C7/$D7 -> 0.64454976 | D14: =D7/$D7 -> 1 | E14: =E7/$D7 -> 0.96728352 | F14: =F7/$D7 -> 0.79906314 | G14: =G7/$D7 -> 1.0088451 | H14: =H7/$D7 -> 1.1238455 | I14: =I7/$D7 -> 1.5910505
A16: descripcion | B16: Comercio al por mayor, excepto de vehículos de motor y motocicletas
A18: Suma de emp | B18: Etiquetas de columna
A19: Etiquetas de fila | B19: 2016 | C19: 2017 | D19: 2018 | E19: 2019 | F19: 2020 | G19: 2021 | H19: 2022 | I19: 2023
A20: Chile | B20: 1533942 | C20: 2949275.4 | D20: 3434103.8 | E20: 2923247.4 | F20: 3420807.5 | G20: 3593142.8 | H20: 5249696.3
A21: México | B21: 779287 | C21: 795803 | D21: 1561961 | E21: 1575997 | F21: 1570105 | G21: 1626213 | H21: 1652813 | I21: 1665682
B24: Chile | C24: =C20/B20*100-100 -> 92.267728 | D24: =D20/C20*100-100 -> 16.438899 | E24: =E20/D20*100-100 -> -14.875974 | F24: =F20/E20*100-100 -> 17.020797 | G24: =G20/F20*100-100 -> 5.0378562 | H24: =H20/G20*100-100 -> 46.103191 | L24: =AVERAGE(C24:H24) -> 26.99875
B25: México | C25: =C21/B21*100-100 -> 2.1193732 | D25: =D21/C21*100-100 -> 96.274832 | E25: =E21/D21*100-100 -> 0.89861399 | F25: =F21/E21*100-100 -> -0.37385858 | G25: =G21/F21*100-100 -> 3.573519 | H25: =H21/G21*100-100 -> 1.6357021 | I25: =I21/H21*100-100 -> 0.77861198 | L25: =AVERAGE(C25:I25) -> 14.986685
A28: descripcion | B28: Comercio al por mayor, excepto de vehículos de motor y motocicletas
A30: Suma de rem | B30: Etiquetas de columna
A31: Etiquetas de fila | B31: 2016 | C31: 2017 | D31: 2018 | E31: 2019 | F31: 2020 | G31: 2021 | H31: 2022 | I31: 2023
A32: Chile | B32: 3.0974596e+09 | C32: 5.7367606e+09 | D32: 6.6686859e+09 | E32: 5.8545196e+09 | F32: 5.9600122e+09 | G32: 6.7052121e+09 | H32: 9.4321527e+09
A33: México | B33: 2.7899177e+09 | C33: 2.8386951e+09 | D33: 9.2323208e+09 | E33: 9.5918375e+09 | F33: 8.372796e+09 | G33: 1.0522987e+10 | H33: 1.276345e+10 | I33: 1.8118783e+10
B36: Chile | C36: =C32/B32*100-100 -> 85.208568 | D36: =D32/C32*100-100 -> 16.2448 | E36: =E32/D32*100-100 -> -12.208797 | F36: =F32/E32*100-100 -> 1.8019002 | G36: =G32/F32*100-100 -> 12.503328 | H36: =H32/G32*100-100 -> 40.66897 | L36: =AVERAGE(C36:H36) -> 24.036462
B37: México | C37: =C33/B33*100-100 -> 1.7483447 | D37: =D33/C33*100-100 -> 225.23115 | E37: =E33/D33*100-100 -> 3.8941099 | F37: =F33/E33*100-100 -> -12.709155 | G37: =G33/F33*100-100 -> 25.68068 | H37: =H33/G33*100-100 -> 21.291131 | I37: =I33/H33*100-100 -> 41.958352 | L37: =AVERAGE(C37:I37) -> 43.870659
A43: descripcion | B43: Comercio al por mayor, excepto de vehículos de motor y motocicletas
A45: Suma de VA_defl | B45: Etiquetas de columna
A46: Etiquetas de fila | B46: 2016 | C46: 2017 | D46: 2018 | E46: 2019 | F46: 2020 | G46: 2021 | H46: 2022 | I46: 2023
A47: Chile | B47: 6.091833e+09 | C47: 1.0789381e+10 | D47: 1.2254744e+10 | E47: 1.0670504e+10 | F47: 1.1242372e+10 | G47: 1.3951765e+10 | H47: 1.8384807e+10
A48: México | B48: 2.1313842e+10 | C48: 1.947373e+10 | D48: 5.9300356e+10 | E48: 5.7875704e+10 | F48: 4.7631791e+10 | G48: 6.2285795e+10 | H48: 7.0520835e+10 | I48: 1.006151e+11
B51: Chile | C51: =C47/B47*100-100 -> 77.112228 | D51: =D47/C47*100-100 -> 13.58153 | E51: =E47/D47*100-100 -> -12.927568 | F51: =F47/E47*100-100 -> 5.3593344 | G51: =G47/F47*100-100 -> 24.099839 | H51: =H47/G47*100-100 -> 31.774058 | L51: =AVERAGE(C51:H51) -> 23.16657
B52: México | C52: =C48/B48*100-100 -> -8.6334144 | D52: =D48/C48*100-100 -> 204.51463 | E52: =E48/D48*100-100 -> -2.4024338 | F52: =F48/E48*100-100 -> -17.699851 | G52: =G48/F48*100-100 -> 30.765176 | H52: =H48/G48*100-100 -> 13.221377 | I52: =I48/H48*100-100 -> 42.67429 | L52: =AVERAGE(C52:I52) -> 37.491396

Sheet rem_emp
A1: descripcion | B1: Comercio al por mayor, excepto de vehículos de motor y motocicletas
A3: Suma de Rem_emp | B3: Etiquetas de columna
A4: Etiquetas de fila | B4: 2016 | C4: 2017 | D4: 2018 | E4: 2019 | F4: 2020 | G4: 2021 | H4: 2022 | I4: 2023 | J4: Total general
A5: Chile | B5: 2019.2808 | C5: 1945.1424 | D5: 1941.8999 | E5: 2002.7451 | F5: 1742.2823 | G5: 1866.1134 | H5: 1796.7045 | J5: 13314.168
A6: México | B6: 3580.0902 | C6: 3567.0827 | D6: 5910.7243 | E6: 6086.2029 | F6: 5332.6345 | G6: 6470.8541 | H6: 7722.2589 | I6: 10877.696 | J6: 49547.544
A7: Total general | B7: 5599.3709 | C7: 5512.225 | D7: 7852.6242 | E7: 8088.948 | F7: 7074.9167 | G7: 8336.9675 | H7: 9518.9634 | I7: 10877.696 | J7: 62861.712
B9: Chile | C9: =C5/B5*100-100 -> -3.6715263 | D9: =D5/C5*100-100 -> -0.1666955 | E9: =E5/D5*100-100 -> 3.1332835 | F9: =F5/E5*100-100 -> -13.005292 | G9: =G5/F5*100-100 -> 7.1074109 | H9: =H5/G5*100-100 -> -3.7194404 | K9: =AVERAGE(C9:H9) -> -1.7203767
B10: México | C10: =C6/B6*100-100 -> -0.36332828 | D10: =D6/C6*100-100 -> 65.701914 | E10: =E6/D6*100-100 -> 2.9688177 | F10: =F6/E6*100-100 -> -12.381586 | G10: =G6/F6*100-100 -> 21.344415 | H10: =H6/G6*100-100 -> 19.339099 | I10: =I6/H6*100-100 -> 40.861587 | K10: =AVERAGE(C10:I10) -> 19.638702

Sheet emp_prod
A1: País | B1: descripcion | C1: conc | D1: year | E1: Suma de prod_trab | F1: Suma de emp | G1: pm | H1: emp | I1: rem | J1: rem_emp | L1: tc_rem_emp
A2: Chile | B2: Actividades de edición | C2: =_xlfn.CONCAT(A2,D2,B2) -> Chile2016Actividades de edición | D2: 2016 | E2: 3858.0035 | F2: 53031 | I2: =VLOOKUP(C2,Sheet1!$H$2:$K$191,4,0) -> 1.3573433e+08 | J2: =IFERROR(I2/H2,"")
A3: Chile | B3: Actividades de edición | C3: =_xlfn.CONCAT(A3,D3,B3) -> Chile2017Actividades de edición | D3: 2017 | E3: 4237.4399 | F3: 52177 | G3: =IF(B3=B2,(E3-E2)/E2*100,"") -> 9.8350469 | H3: =IF(B3=B2,(F3-F2)/F2*100,"") -> -1.6103788 | I3: =VLOOKUP(C3,Sheet1!$H$2:$K$191,4,0) -> 1.605623e+08 | J3: =IFERROR(I3/H3,"") -> -99704675 | K3: =IF(B3=B2,(I3-I2)/I2*100,"") -> 18.291591 | L3: =IFERROR(IF(B3=B2,(J3-J2)/J2*100,""),"")
A4: Chile | B4: Actividades de edición | C4: =_xlfn.CONCAT(A4,D4,B4) -> Chile2018Actividades de edición | D4: 2018 | E4: 3002.4566 | F4: 63409 | G4: =IF(B4=B3,(E4-E3)/E3*100,"") -> -29.144562 | H4: =IF(B4=B3,(F4-F3)/F3*100,"") -> 21.526726 | I4: =VLOOKUP(C4,Sheet1!$H$2:$K$191,4,0) -> 1.4989045e+08 | J4: =IFERROR(I4/H4,"") -> 6962993.5 | K4: =IF(B4=B3,(I4-I3)/I3*100,"") -> -6.646544 | L4: =IFERROR(IF(B4=B3,(J4-J3)/J3*100,""),"") -> -106.98362
A5: Chile | B5: Actividades de edición | C5: =_xlfn.CONCAT(A5,D5,B5) -> Chile2019Actividades de edición | D5: 2019 | E5: 3830.0331 | F5: 40762 | G5: =IF(B5=B4,(E5-E4)/E4*100,"") -> 27.563312 | H5: =IF(B5=B4,(F5-F4)/F4*100,"") -> -35.71575 | I5: =VLOOKUP(C5,Sheet1!$H$2:$K$191,4,0) -> 1.2985275e+08 | J5: =IFERROR(I5/H5,"") -> -3635728 | K5: =IF(B5=B4,(I5-I4)/I4*100,"") -> -13.368231 | L5: =IFERROR(IF(B5=B4,(J5-J4)/J4*100,""),"") -> -152.21501
A6: Chile | B6: Actividades de edición | C6: =_xlfn.CONCAT(A6,D6,B6) -> Chile2020Actividades de edición | D6: 2020 | E6: 2311.6302 | F6: 49914 | G6: =IF(B6=B5,(E6-E5)/E5*100,"") -> -39.644642 | H6: =IF(B6=B5,(F6-F5)/F5*100,"") -> 22.452284 | I6: =VLOOKUP(C6,Sheet1!$H$2:$K$191,4,0) -> 1.1081943e+08 | J6: =IFERROR(I6/H6,"") -> 4935775.4 | K6: =IF(B6=B5,(I6-I5)/I5*100,"") -> -14.657619 | L6: =IFERROR(IF(B6=B5,(J6-J5)/J5*100,""),"") -> -235.75755
A7: Chile | B7: Actividades de edición | C7: =_xlfn.CONCAT(A7,D7,B7) -> Chile2021Actividades de edición | D7: 2021 | E7: 3181.8565 | F7: 92111 | G7: =IF(B7=B6,(E7-E6)/E6*100,"") -> 37.645565 | H7: =IF(B7=B6,(F7-F6)/F6*100,"") -> 84.539408 | I7: =VLOOKUP(C7,Sheet1!$H$2:$K$191,4,0) -> 1.8076035e+08 | J7: =IFERROR(I7/H7,"") -> 2138178.5 | K7: =IF(B7=B6,(I7-I6)/I6*100,"") -> 63.1125 | L7: =IFERROR(IF(B7=B6,(J7-J6)/J6*100,""),"") -> -56.679988
A8: Chile | B8: Actividades de edición | C8: =_xlfn.CONCAT(A8,D8,B8) -> Chile2022Actividades de edición | D8: 2022 | E8: 2964.6089 | F8: 154394.12 | G8: =IF(B8=B7,(E8-E7)/E7*100,"") -> -6.827699 | H8: =IF(B8=B7,(F8-F7)/F7*100,"") -> 67.617457 | I8: =VLOOKUP(C8,Sheet1!$H$2:$K$191,4,0) -> 2.5349341e+08 | J8: =IFERROR(I8/H8,"") -> 3748934.4 | K8: =IF(B8=B7,(I8-I7)/I7*100,"") -> 40.237289 | L8: =IFERROR(IF(B8=B7,(J8-J7)/J7*100,""),"") -> 75.333085
A9: Chile | B9: Actividades de programación y radiodifusión | C9: =_xlfn.CONCAT(A9,D9,B9) -> Chile2016Actividades de programación y radiodifusión | D9: 2016 | E9: 5100.8369 | F9: 85757 | G9: =IF(B9=B8,(E9-E8)/E8*100,"") | H9: =IF(B9=B8,(F9-F8)/F8*100,"") | I9: =VLOOKUP(C9,Sheet1!$H$2:$K$191,4,0) -> 1.8296761e+08 | J9: =IFERROR(I9/H9,"") | K9: =IF(B9=B8,(I9-I8)/I8*100,"") | L9: =IFERROR(IF(B9=B8,(J9-J8)/J8*100,""),"")
A10: Chile | B10: Actividades de programación y radiodifusión | C10: =_xlfn.CONCAT(A10,D10,B10) -> Chile2017Actividades de programación y radiodifusión | D10: 2017 | E10: 7133.7388 | F10: 71194 | G10: =IF(B10=B9,(E10-E9)/E9*100,"") -> 39.854282 | H10: =IF(B10=B9,(F10-F9)/F9*100,"") -> -16.981704 | I10: =VLOOKUP(C10,Sheet1!$H$2:$K$191,4,0) -> 1.9341023e+08 | J10: =IFERROR(I10/H10,"") -> -11389330 | K10: =IF(B10=B9,(I10-I9)/I9*100,"") -> 5.7073565 | L10: =IFERROR(IF(B10=B9,(J10-J9)/J9*100,""),"")
A11: Chile | B11: Actividades de programación y radiodifusión | C11: =_xlfn.CONCAT(A11,D11,B11) -> Chile2018Actividades de programación y radiodifusión | D11: 2018 | E11: 7737.9901 | F11: 69744 | G11: =IF(B11=B10,(E11-E10)/E10*100,"") -> 8.4703309 | H11: =IF(B11=B10,(F11-F10)/F10*100,"") -> -2.0366885 | I11: =VLOOKUP(C11,Sheet1!$H$2:$K$191,4,0) -> 1.956337e+08 | J11: =IFERROR(I11/H11,"") -> -96054797 | K11: =IF(B11=B10,(I11-I10)/I10*100,"") -> 1.1496138 | L11: =IFERROR(IF(B11=B10,(J11-J10)/J10*100,""),"") -> 743.37532
A12: Chile | B12: Actividades de programación y radiodifusión | C12: =_xlfn.CONCAT(A12,D12,B12) -> Chile2019Actividades de programación y radiodifusión | D12: 2019 | E12: 7602.5543 | F12: 55417 | G12: =IF(B12=B11,(E12-E11)/E11*100,"") -> -1.7502707 | H12: =IF(B12=B11,(F12-F11)/F11*100,"") -> -20.542269 | I12: =VLOOKUP(C12,Sheet1!$H$2:$K$191,4,0) -> 1.5766283e+08 | J12: =IFERROR(I12/H12,"") -> -7675044.8 | K12: =IF(B12=B11,(I12-I11)/I11*100,"") -> -19.409163 | L12: =IFERROR(IF(B12=B11,(J12-J11)/J11*100,""),"") -> -92.009723
A13: Chile | B13: Actividades de programación y radiodifusión | C13: =_xlfn.CONCAT(A13,D13,B13) -> Chile2020Actividades de programación y radiodifusión | D13: 2020 | E13: 6819.9634 | F13: 47046 | G13: =IF(B13=B12,(E13-E12)/E12*100,"") -> -10.293789 | H13: =IF(B13=B12,(F13-F12)/F12*100,"") -> -15.105473 | I13: =VLOOKUP(C13,Sheet1!$H$2:$K$191,4,0) -> 1.2360502e+08 | J13: =IFERROR(I13/H13,"") -> -8182797.1 | K13: =IF(B13=B12,(I13-I12)/I12*100,"") -> -21.601675 | L13: =IFERROR(IF(B13=B12,(J13-J12)/J12*100,""),"") -> 6.6156261
A14: Chile | B14: Actividades de programación y radiodifusión | C14: =_xlfn.CONCAT(A14,D14,B14) -> Chile2021Actividades de programación y radiodifusión | D14: 2021 | E14: 11081.546 | F14: 59201 | G14: =IF(B14=B13,(E14-E13)/E13*100,"") -> 62.486887 | H14: =IF(B14=B13,(F14-F13)/F13*100,"") -> 25.836415 | I14: =VLOOKUP(C14,Sheet1!$H$2:$K$191,4,0) -> 1.1521235e+08 | J14: =IFERROR(I14/H14,"") -> 4459300.9 | K14: =IF(B14=B13,(I14-I13)/I13*100,"") -> -6.7899107 | L14: =IFERROR(IF(B14=B13,(J14-J13)/J13*100,""),"") -> -154.49605
... A181: México | B181: Telecomunicaciones | C181: =_xlfn.CONCAT(A181,D181,B181) -> México2023Telecomunicaciones | D181: 2023 | E181: 106502.21 | F181: 151981 | G181: =IF(B181=B180,(E181-E180)/E180*100,"") -> 12.637356 | H181: =IF(B181=B180,(F181-F180)/F180*100,"") -> -3.1807815 | I181: =VLOOKUP(C181,Sheet1!$H$2:$K$191,4,0) -> 2.8096076e+09 | J181: =IFERROR(I181/H181,"") -> -8.8330731e+08 | K181: =IF(B181=B180,(I181-I180)/I180*100,"") -> 18.817986 | L181: =IFERROR(IF(B181=B180,(J181-J180)/J180*100,""),"") -> 447.44119

Sheet Sheet1
A1: País | B1: year | C1: descripcion | D1: VA_div | E1: CI_div | F1: VBP_div | G1: VA_VBP_div | H1: conca | I1: deflactores2dfinal | J1: emp | K1: rem | L1: consumo_energía | M1: horas | N1: VA_defl | O1: prod_trab | P1: Rem_emp
A2: Chile | B2: 2016 | C2: Elaboración de productos alimenticios | D2: 5.7177504e+09 | E2: 1.5325576e+10 | F2: 2.1043327e+10 | G2: 27.171323 | H2: =_xlfn.CONCAT(A2,B2,C2) -> Chile2016Elaboración de productos alimenticios | I2: 96.618125 | J2: =VLOOKUP(H2,[1]Hoja2!D$2:E$191,2,0) -> 150226.25 | K2: =VLOOKUP(H2,[1]Hoja2!D$2:F$191,3,0) -> 1.8424362e+09 | L2: =IFERROR(VLOOKUP(H2,[2]Sheet1!K$2:L$94,2,0),"") | M2: =IFERROR(VLOOKUP(H2,[2]Sheet1!K$372:L$648,2,0),"") | N2: =D2/I2*100 -> 5.917886e+09 | O2: =N2/J2 -> 39393.155 | P2: =K2/J2 -> 12264.409
A3: Chile | B3: 2016 | C3: Fabricación de prendas de vestir | D3: 1.2348923e+08 | E3: 2.2563182e+08 | F3: 3.4912106e+08 | G3: 35.371465 | H3: =_xlfn.CONCAT(A3,B3,C3) -> Chile2016Fabricación de prendas de vestir | I3: 117.93761 | J3: =VLOOKUP(H3,[1]Hoja2!D$2:E$191,2,0) -> 8550 | K3: =VLOOKUP(H3,[1]Hoja2!D$2:F$191,3,0) -> 90233466 | L3: =IFERROR(VLOOKUP(H3,[2]Sheet1!K$2:L$94,2,0),"") | M3: =IFERROR(VLOOKUP(H3,[2]Sheet1!K$372:L$648,2,0),"") | N3: =D3/I3*100 -> 1.0470725e+08 | O3: =N3/J3 -> 12246.462 | P3: =K3/J3 -> 10553.622
A4: Chile | B4: 2016 | C4: Fabricación de productos de cuero y productos conexos | D4: 1.46283e+08 | E4: 1.3929905e+08 | F4: 2.8558205e+08 | G4: 51.222756 | H4: =_xlfn.CONCAT(A4,B4,C4) -> Chile2016Fabricación de productos de cuero y productos conexos | I4: 117.93761 | J4: =VLOOKUP(H4,[1]Hoja2!D$2:E$191,2,0) -> 5885.75 | K4: =VLOOKUP(H4,[1]Hoja2!D$2:F$191,3,0) -> 67650512 | L4: =IFERROR(VLOOKUP(H4,[2]Sheet1!K$2:L$94,2,0),"") | M4: =IFERROR(VLOOKUP(H4,[2]Sheet1!K$372:L$648,2,0),"") | N4: =D4/I4*100 -> 1.2403422e+08 | O4: =N4/J4 -> 21073.647 | P4: =K4/J4 -> 11493.949
A5: Chile | B5: 2016 | C5: Fabricación de vehículos automotores, remolques y semirremolques | D5: 17635138 | E5: 76040542 | F5: 93675680 | G5: 18.825738 | H5: =_xlfn.CONCAT(A5,B5,C5) -> Chile2016Fabricación de vehículos automotores, remolques y semirremolques | I5: 101.10423 | J5: =VLOOKUP(H5,[1]Hoja2!D$2:E$191,2,0) -> 1132.75 | K5: =VLOOKUP(H5,[1]Hoja2!D$2:F$191,3,0) -> 17844337 | L5: =IFERROR(VLOOKUP(H5,[2]Sheet1!K$2:L$94,2,0),"") | M5: =IFERROR(VLOOKUP(H5,[2]Sheet1!K$372:L$648,2,0),"") | N5: =D5/I5*100 -> 17442532 | O5: =N5/J5 -> 15398.395 | P5: =K5/J5 -> 15753.111
A6: Chile | B6: 2016 | C6: Comercio al por mayor y al por menor y reparación de vehículos de motor y motocicletas | D6: 1.4375727e+09 | E6: 1.4647413e+09 | F6: 2.8863687e+09 | G6: 49.805582 | H6: =_xlfn.CONCAT(A6,B6,C6) -> Chile2016Comercio al por mayor y al por menor y reparación de vehículos de motor y motocicletas | I6: 99.27464 | J6: =VLOOKUP(H6,[1]Hoja2!D$2:E$191,2,0) -> 436535 | K6: =VLOOKUP(H6,[1]Hoja2!D$2:F$191,3,0) -> 8.7455318e+08 | L6: =IFERROR(VLOOKUP(H6,[2]Sheet1!K$2:L$94,2,0),"") | M6: =IFERROR(VLOOKUP(H6,[2]Sheet1!K$372:L$648,2,0),"") | N6: =D6/I6*100 -> 1.4480765e+09 | O6: =N6/J6 -> 3317.2059 | P6: =K6/J6 -> 2003.3976
A7: Chile | B7: 2016 | C7: Comercio al por mayor, excepto de vehículos de motor y motocicletas | D7: 6.0476453e+09 | E7: 7.9498249e+09 | F7: 1.398951e+10 | G7: 43.229859 | H7: =_xlfn.CONCAT(A7,B7,C7) -> Chile2016Comercio al por mayor, excepto de vehículos de motor y motocicletas | I7: 99.27464 | J7: =VLOOKUP(H7,[1]Hoja2!D$2:E$191,2,0) -> 1533942 | K7: =VLOOKUP(H7,[1]Hoja2!D$2:F$191,3,0) -> 3.0974596e+09 | L7: =IFERROR(VLOOKUP(H7,[2]Sheet1!K$2:L$94,2,0),"") | M7: =IFERROR(VLOOKUP(H7,[2]Sheet1!K$372:L$648,2,0),"") | N7: =D7/I7*100 -> 6.091833e+09 | O7: =N7/J7 -> 3971.3581 | P7: =K7/J7 -> 2019.2808
A8: Chile | B8: 2016 | C8: Comercio al por menor, excepto de vehículos de motor y motocicletas | D8: 6.2049222e+09 | E8: 6.339196e+09 | F8: 1.2540195e+10 | G8: 49.480269 | H8: =_xlfn.CONCAT(A8,B8,C8) -> Chile2016Comercio al por menor, excepto de vehículos de motor y motocicletas | I8: 99.27464 | J8: =VLOOKUP(H8,[1]Hoja2!D$2:E$191,2,0) -> 2597511 | K8: =VLOOKUP(H8,[1]Hoja2!D$2:F$191,3,0) -> 2.7125911e+09 | L8: =IFERROR(VLOOKUP(H8,[2]Sheet1!K$2:L$94,2,0),"") | M8: =IFERROR(VLOOKUP(H8,[2]Sheet1!K$372:L$648,2,0),"") | N8: =D8/I8*100 -> 6.2502591e+09 | O8: =N8/J8 -> 2406.2493 | P8: =K8/J8 -> 1044.304
A9: Chile | B9: 2016 | C9: Actividades de edición | D9: 2.2127654e+08 | E9: 1.5340648e+08 | F9: 3.7468302e+08 | G9: 59.056997 | H9: =_xlfn.CONCAT(A9,B9,C9) -> Chile2016Actividades de edición | I9: 108.15409 | J9: =VLOOKUP(H9,[1]Hoja2!D$2:E$191,2,0) -> 53031 | K9: =VLOOKUP(H9,[1]Hoja2!D$2:F$191,3,0) -> 1.3573433e+08 | L9: =IFERROR(VLOOKUP(H9,[2]Sheet1!K$2:L$94,2,0),"") | M9: =IFERROR(VLOOKUP(H9,[2]Sheet1!K$372:L$648,2,0),"") | N9: =D9/I9*100 -> 2.0459378e+08 | O9: =N9/J9 -> 3858.0035 | P9: =K9/J9 -> 2559.528
A10: Chile | B10: 2016 | C10: Actividades de programación y radiodifusión | D10: 4.731011e+08 | E10: 1.9859934e+08 | F10: 6.7170045e+08 | G10: 70.433347 | H10: =_xlfn.CONCAT(A10,B10,C10) -> Chile2016Actividades de programación y radiodifusión | I10: 108.15409 | J10: =VLOOKUP(H10,[1]Hoja2!D$2:E$191,2,0) -> 85757 | K10: =VLOOKUP(H10,[1]Hoja2!D$2:F$191,3,0) -> 1.8296761e+08 | L10: =IFERROR(VLOOKUP(H10,[2]Sheet1!K$2:L$94,2,0),"") | M10: =IFERROR(VLOOKUP(H10,[2]Sheet1!K$372:L$648,2,0),"") | N10: =D10/I10*100 -> 4.3743247e+08 | O10: =N10/J10 -> 5100.8369 | P10: =K10/J10 -> 2133.5589
A11: Chile | B11: 2016 | C11: Actividades de servicios de información | D11: 2.3390093e+08 | E11: 1.9996822e+08 | F11: 4.3386915e+08 | G11: 53.910478 | H11: =_xlfn.CONCAT(A11,B11,C11) -> Chile2016Actividades de servicios de información | I11: 108.15409 | J11: =VLOOKUP(H11,[1]Hoja2!D$2:E$191,2,0) -> 47839 | K11: =VLOOKUP(H11,[1]Hoja2!D$2:F$191,3,0) -> 1.2644068e+08 | L11: =IFERROR(VLOOKUP(H11,[2]Sheet1!K$2:L$94,2,0),"") | M11: =IFERROR(VLOOKUP(H11,[2]Sheet1!K$372:L$648,2,0),"") | N11: =D11/I11*100 -> 2.1626638e+08 | O11: =N11/J11 -> 4520.7128 | P11: =K11/J11 -> 2643.046
A12: Chile | B12: 2016 | C12: Producción de películas, videos y programas de televisión, grabación de sonido y edición musical | D12: 1.7174254e+08 | E12: 1.0878616e+08 | F12: 2.8052869e+08 | G12: 61.221023 | H12: =_xlfn.CONCAT(A12,B12,C12) -> Chile2016Producción de películas, videos y programas de televisión, grabación de sonido y edición musical | I12: 108.15409 | J12: =VLOOKUP(H12,[1]Hoja2!D$2:E$191,2,0) -> 23808 | K12: =VLOOKUP(H12,[1]Hoja2!D$2:F$191,3,0) -> 50080661 | L12: =IFERROR(VLOOKUP(H12,[2]Sheet1!K$2:L$94,2,0),"") | M12: =IFERROR(VLOOKUP(H12,[2]Sheet1!K$372:L$648,2,0),"") | N12: =D12/I12*100 -> 1.5879431e+08 | O12: =N12/J12 -> 6669.7878 | P12: =K12/J12 -> 2103.5224
A13: Chile | B13: 2016 | C13: Programación de computadoras, consultoría y actividades relacionadas | D13: 9.6221793e+08 | E13: 8.1845682e+08 | F13: 1.7806748e+09 | G13: 54.036703 | H13: =_xlfn.CONCAT(A13,B13,C13) -> Chile2016Programación de computadoras, consultoría y actividades relacionadas | I13: 108.15409 | J13: =VLOOKUP(H13,[1]Hoja2!D$2:E$191,2,0) -> 217507 | K13: =VLOOKUP(H13,[1]Hoja2!D$2:F$191,3,0) -> 7.1638244e+08 | L13: =IFERROR(VLOOKUP(H13,[2]Sheet1!K$2:L$94,2,0),"") | M13: =IFERROR(VLOOKUP(H13,[2]Sheet1!K$372:L$648,2,0),"") | N13: =D13/I13*100 -> 8.8967318e+08 | O13: =N13/J13 -> 4090.3198 | P13: =K13/J13 -> 3293.6064
... A61: Chile | B61: 2020 | C61: Programación de computadoras, consultoría y actividades relacionadas | D61: 8.0423265e+08 | E61: 6.5868993e+08 | F61: 1.4629226e+09 | G61: 54.974382 | H61: =_xlfn.CONCAT(A61,B61,C61) -> Chile2020Programación de computadoras, consultoría y actividades relacionadas | I61: 91.363838 | J61: =VLOOKUP(H61,[1]Hoja2!D$2:E$191,2,0) -> 221833 | K61: =VLOOKUP(H61,[1]Hoja2!D$2:F$191,3,0) -> 5.3227395e+08 | L61: =IFERROR(VLOOKUP(H61,[2]Sheet1!K$2:L$94,2,0),"") | M61: =IFERROR(VLOOKUP(H61,[2]Sheet1!K$372:L$648,2,0),"") | N61: =D61/I61*100 -> 8.802527e+08 | O61: =N61/J61 -> 3968.0872 | P61: =K61/J61 -> 2399.4354
A62: Chile | B62: 2021 | C62: Elaboración de productos alimenticios | D62: 8.3266235e+09 | E62: 1.7894554e+10 | F62: 2.6221179e+10 | G62: 31.755336 | H62: =_xlfn.CONCAT(A62,B62,C62) -> Chile2021Elaboración de productos alimenticios | I62: 108.85802 | J62: =VLOOKUP(H62,[1]Hoja2!D$2:E$191,2,0) -> 184026 | K62: 1896510188 | L62: =IFERROR(VLOOKUP(H62,[2]Sheet1!K$2:L$94,2,0),"") | M62: =IFERROR(VLOOKUP(H62,[2]Sheet1!K$372:L$648,2,0),"") | N62: =D62/I62*100 -> 7.6490673e+09 | O62: =N62/J62 -> 41565.145 | P62: =K62/J62 -> 10305.664
A63: Chile | B63: 2021 | C63: Fabricación de prendas de vestir | D63: 61466485 | E63: 71658479 | F63: 1.3312496e+08 | G63: 46.17202 | H63: =_xlfn.CONCAT(A63,B63,C63) -> Chile2021Fabricación de prendas de vestir | I63: 69.374467 | J63: =VLOOKUP(H63,[1]Hoja2!D$2:E$191,2,0) -> 3398 | K63: =VLOOKUP(H63,[1]Hoja2!D$2:F$191,3,0) -> 31451189 | L63: =IFERROR(VLOOKUP(H63,[2]Sheet1!K$2:L$94,2,0),"") | M63: =IFERROR(VLOOKUP(H63,[2]Sheet1!K$372:L$648,2,0),"") | N63: =D63/I63*100 -> 88601020 | O63: =N63/J63 -> 26074.462 | P63: =K63/J63 -> 9255.7943
A64: Chile | B64: 2021 | C64: Fabricación de productos de cuero y productos conexos | D64: 34907166 | E64: 24271425 | F64: 59178591 | G64: 58.986139 | H64: =_xlfn.CONCAT(A64,B64,C64) -> Chile2021Fabricación de productos de cuero y productos conexos | I64: 69.374467 | J64: =VLOOKUP(H64,[1]Hoja2!D$2:E$191,2,0) -> 1111 | K64: =VLOOKUP(H64,[1]Hoja2!D$2:F$191,3,0) -> 14658754 | L64: =IFERROR(VLOOKUP(H64,[2]Sheet1!K$2:L$94,2,0),"") | M64: =IFERROR(VLOOKUP(H64,[2]Sheet1!K$372:L$648,2,0),"") | N64: =D64/I64*100 -> 50317023 | O64: =N64/J64 -> 45289.849 | P64: =K64/J64 -> 13194.198
A65: Chile | B65: 2021 | C65: Fabricación de vehículos automotores, remolques y semirremolques | D65: 23975137 | E65: 43093828 | F65: 67068965 | G65: 35.746991 | H65: =_xlfn.CONCAT(A65,B65,C65) -> Chile2021Fabricación de vehículos automotores, remolques y semirremolques | I65: 106.47235 | J65: =VLOOKUP(H65,[1]Hoja2!D$2:E$191,2,0) -> 1079 | K65: =VLOOKUP(H65,[1]Hoja2!D$2:F$191,3,0) -> 13159501 | L65: =IFERROR(VLOOKUP(H65,[2]Sheet1!K$2:L$94,2,0),"") | M65: =IFERROR(VLOOKUP(H65,[2]Sheet1!K$372:L$648,2,0),"") | N65: =D65/I65*100 -> 22517713 | O65: =N65/J65 -> 20869.057 | P65: =K65/J65 -> 12196.016
A66: Chile | B66: 2021 | C66: Comercio al por mayor y al por menor y reparación de vehículos de motor y motocicletas | D66: 4.2925573e+09 | E66: 3.171441e+09 | F66: 7.4626081e+09 | G66: 57.520872 | H66: =_xlfn.CONCAT(A66,B66,C66) -> Chile2021Comercio al por mayor y al por menor y reparación de vehículos de motor y motocicletas | I66: 114.66887 | J66: =VLOOKUP(H66,[1]Hoja2!D$2:E$191,2,0) -> 1158227.6 | K66: =VLOOKUP(H66,[1]Hoja2!D$2:F$191,3,0) -> 1.9090266e+09 | L66: =IFERROR(VLOOKUP(H66,[2]Sheet1!K$2:L$94,2,0),"") | M66: =IFERROR(VLOOKUP(H66,[2]Sheet1!K$372:L$648,2,0),"") | N66: =D66/I66*100 -> 3.7434372e+09 | O66: =N66/J66 -> 3232.0392 | P66: =K66/J66 -> 1648.2309
A67: Chile | B67: 2021 | C67: Comercio al por mayor, excepto de vehículos de motor y motocicletas | D67: 1.5998332e+10 | E67: 1.4500891e+10 | F67: 3.0419064e+10 | G67: 52.593111 | H67: =_xlfn.CONCAT(A67,B67,C67) -> Chile2021Comercio al por mayor, excepto de vehículos de motor y motocicletas | I67: 114.66887 | J67: =VLOOKUP(H67,[1]Hoja2!D$2:E$191,2,0) -> 3593142.8 | K67: =VLOOKUP(H67,[1]Hoja2!D$2:F$191,3,0) -> 6.7052121e+09 | L67: =IFERROR(VLOOKUP(H67,[2]Sheet1!K$2:L$94,2,0),"") | M67: =IFERROR(VLOOKUP(H67,[2]Sheet1!K$372:L$648,2,0),"") | N67: =D67/I67*100 -> 1.3951765e+10 | O67: =N67/J67 -> 3882.8864 | P67: =K67/J67 -> 1866.1134
A68: Chile | B68: 2021 | C68: Comercio al por menor, excepto de vehículos de motor y motocicletas | D68: 1.216714e+10 | E68: 1.2287267e+10 | F68: 2.4232913e+10 | G68: 50.209152 | H68: =_xlfn.CONCAT(A68,B68,C68) -> Chile2021Comercio al por menor, excepto de vehículos de motor y motocicletas | I68: 114.66887 | J68: =VLOOKUP(H68,[1]Hoja2!D$2:E$191,2,0) -> 5306320.6 | K68: =VLOOKUP(H68,[1]Hoja2!D$2:F$191,3,0) -> 6.1335295e+09 | L68: =IFERROR(VLOOKUP(H68,[2]Sheet1!K$2:L$94,2,0),"") | M68: =IFERROR(VLOOKUP(H68,[2]Sheet1!K$372:L$648,2,0),"") | N68: =D68/I68*100 -> 1.0610674e+10 | O68: =N68/J68 -> 1999.6292 | P68: =K68/J68 -> 1155.8912
A69: Chile | B69: 2021 | C69: Actividades de edición | D69: 2.7227486e+08 | E69: 1.4292965e+08 | F69: 4.152045e+08 | G69: 65.576085 | H69: =_xlfn.CONCAT(A69,B69,C69) -> Chile2021Actividades de edición | I69: 92.899946 | J69: =VLOOKUP(H69,[1]Hoja2!D$2:E$191,2,0) -> 92111 | K69: =VLOOKUP(H69,[1]Hoja2!D$2:F$191,3,0) -> 1.8076035e+08 | L69: =IFERROR(VLOOKUP(H69,[2]Sheet1!K$2:L$94,2,0),"") | M69: =IFERROR(VLOOKUP(H69,[2]Sheet1!K$372:L$648,2,0),"") | N69: =D69/I69*100 -> 2.9308398e+08 | O69: =N69/J69 -> 3181.8565 | P69: =K69/J69 -> 1962.4187
A70: Chile | B70: 2021 | C70: Actividades de programación y radiodifusión | D70: 6.0945953e+08 | E70: 1.9384579e+08 | F70: 8.0330531e+08 | G70: 75.868977 | H70: =_xlfn.CONCAT(A70,B70,C70) -> Chile2021Actividades de programación y radiodifusión | I70: 92.899946 | J70: =VLOOKUP(H70,[1]Hoja2!D$2:E$191,2,0) -> 59201 | K70: =VLOOKUP(H70,[1]Hoja2!D$2:F$191,3,0) -> 1.1521235e+08 | L70: =IFERROR(VLOOKUP(H70,[2]Sheet1!K$2:L$94,2,0),"") | M70: =IFERROR(VLOOKUP(H70,[2]Sheet1!K$372:L$648,2,0),"") | N70: =D70/I70*100 -> 6.5603862e+08 | O70: =N70/J70 -> 11081.546 | P70: =K70/J70 -> 1946.1217
A71: Chile | B71: 2021 | C71: Actividades de servicios de información | D71: 2.2833767e+09 | E71: 1.857911e+09 | F71: 4.1412877e+09 | G71: 55.136877 | H71: =_xlfn.CONCAT(A71,B71,C71) -> Chile2021Actividades de servicios de información | I71: 92.899946 | J71: =VLOOKUP(H71,[1]Hoja2!D$2:E$191,2,0) -> 337733 | K71: =VLOOKUP(H71,[1]Hoja2!D$2:F$191,3,0) -> 1.2602022e+09 | L71: =IFERROR(VLOOKUP(H71,[2]Sheet1!K$2:L$94,2,0),"") | M71: =IFERROR(VLOOKUP(H71,[2]Sheet1!K$372:L$648,2,0),"") | N71: =D71/I71*100 -> 2.4578881e+09 | O71: =N71/J71 -> 7277.6071 | P71: =K71/J71 -> 3731.3565
A72: Chile | B72: 2021 | C72: Producción de películas, videos y programas de televisión, grabación de sonido y edición musical | D72: 1.9566222e+08 | E72: 1.2092698e+08 | F72: 3.165892e+08 | G72: 61.803188 | H72: =_xlfn.CONCAT(A72,B72,C72) -> Chile2021Producción de películas, videos y programas de televisión, grabación de sonido y edición musical | I72: 92.899946 | J72: =VLOOKUP(H72,[1]Hoja2!D$2:E$191,2,0) -> 78229 | K72: =VLOOKUP(H72,[1]Hoja2!D$2:F$191,3,0) -> 91040878 | L72: =IFERROR(VLOOKUP(H72,[2]Sheet1!K$2:L$94,2,0),"") | M72: =IFERROR(VLOOKUP(H72,[2]Sheet1!K$372:L$648,2,0),"") | N72: =D72/I72*100 -> 2.1061607e+08 | O72: =N72/J72 -> 2692.3017 | P72: =K72/J72 -> 1163.774
A73: Chile | B73: 2021 | C73: Programación de computadoras, consultoría y actividades relacionadas | D73: 2.3442425e+09 | E73: 1.1637839e+09 | F73: 3.5080264e+09 | G73: 66.825109 | H73: =_xlfn.CONCAT(A73,B73,C73) -> Chile2021Programación de computadoras, consultoría y actividades relacionadas | I73: 92.899946 | J73: =VLOOKUP(H73,[1]Hoja2!D$2:E$191,2,0) -> 757503 | K73: =VLOOKUP(H73,[1]Hoja2!D$2:F$191,3,0) -> 1.4558452e+09 | L73: =IFERROR(VLOOKUP(H73,[2]Sheet1!K$2:L$94,2,0),"") | M73: =IFERROR(VLOOKUP(H73,[2]Sheet1!K$372:L$648,2,0),"") | N73: =D73/I73*100 -> 2.5234056e+09 | O73: =N73/J73 -> 3331.2154 | P73: =K73/J73 -> 1921.9003
A74: Chile | B74: 2021 | C74: Actividades inmobiliarias | D74: 5.5335644e+09 | E74: 2.2386817e+09 | F74: 7.7722461e+09 | G74: 71.196464 | H74: =_xlfn.CONCAT(A74,B74,C74) -> Chile2021Actividades inmobiliarias | J74: =VLOOKUP(H74,[1]Hoja2!D$2:E$191,2,0) -> 369538 | K74: =VLOOKUP(H74,[1]Hoja2!D$2:F$191,3,0) -> 6.2983507e+08 | L74: =IFERROR(VLOOKUP(H74,[2]Sheet1!K$2:L$94,2,0),"") | M74: =IFERROR(VLOOKUP(H74,[2]Sheet1!K$372:L$648,2,0),"") | N74: =D74/I74*100 -> #VALUE! | O74: =N74/J74 -> #VALUE! | P74: =K74/J74 -> 1704.3851
A75: Chile | B75: 2022 | C75: Elaboración de productos alimenticios | D75: 5.5895002e+09 | E75: 2.3480553e+10 | F75: 2.9070055e+10 | G75: 19.22769 | H75: =_xlfn.CONCAT(A75,B75,C75) -> Chile2022Elaboración de productos alimenticios | I75: 138.22615 | J75: =VLOOKUP(H75,[1]Hoja2!D$2:E$191,2,0) -> 169707 | K75: 2066801275 | L75: =IFERROR(VLOOKUP(H75,[2]Sheet1!K$2:L$94,2,0),"") | M75: =IFERROR(VLOOKUP(H75,[2]Sheet1!K$372:L$648,2,0),"") | N75: =D75/I75*100 -> 4.0437357e+09 | O75: =N75/J75 -> 23827.748 | P75: =K75/J75 -> 12178.645
A76: Chile | B76: 2022 | C76: Fabricación de prendas de vestir | D76: 52745493 | E76: 79241821 | F76: 1.3198731e+08 | G76: 39.962547 | H76: =_xlfn.CONCAT(A76,B76,C76) -> Chile2022Fabricación de prendas de vestir | I76: 56.53987 | J76: =VLOOKUP(H76,[1]Hoja2!D$2:E$191,2,0) -> 2743 | K76: =VLOOKUP(H76,[1]Hoja2!D$2:F$191,3,0) -> 26554167 | L76: =IFERROR(VLOOKUP(H76,[2]Sheet1!K$2:L$94,2,0),"") | M76: =IFERROR(VLOOKUP(H76,[2]Sheet1!K$372:L$648,2,0),"") | N76: =D76/I76*100 -> 93289025 | O76: =N76/J76 -> 34009.852 | P76: =K76/J76 -> 9680.7027
A77: Chile | B77: 2022 | C77: Fabricación de productos de cuero y productos conexos | D77: 25730460 | E77: 26143204 | F77: 51873664 | G77: 49.602164 | H77: =_xlfn.CONCAT(A77,B77,C77) -> Chile2022Fabricación de productos de cuero y productos conexos | I77: 56.53987 | J77: =VLOOKUP(H77,[1]Hoja2!D$2:E$191,2,0) -> 1044 | K77: =VLOOKUP(H77,[1]Hoja2!D$2:F$191,3,0) -> 15117170 | L77: =IFERROR(VLOOKUP(H77,[2]Sheet1!K$2:L$94,2,0),"") | M77: =IFERROR(VLOOKUP(H77,[2]Sheet1!K$372:L$648,2,0),"") | N77: =D77/I77*100 -> 45508524 | O77: =N77/J77 -> 43590.54 | P77: =K77/J77 -> 14480.048
A78: Chile | B78: 2022 | C78: Fabricación de vehículos automotores, remolques y semirremolques | D78: 21303951 | E78: 47770467 | F78: 69074417 | G78: 30.842027 | H78: =_xlfn.CONCAT(A78,B78,C78) -> Chile2022Fabricación de vehículos automotores, remolques y semirremolques | I78: 123.96393 | J78: =VLOOKUP(H78,[1]Hoja2!D$2:E$191,2,0) -> 792 | K78: =VLOOKUP(H78,[1]Hoja2!D$2:F$191,3,0) -> 11261675 | L78: =IFERROR(VLOOKUP(H78,[2]Sheet1!K$2:L$94,2,0),"") | M78: =IFERROR(VLOOKUP(H78,[2]Sheet1!K$372:L$648,2,0),"") | N78: =D78/I78*100 -> 17185604 | O78: =N78/J78 -> 21698.996 | P78: =K78/J78 -> 14219.287
A79: Chile | B79: 2022 | C79: Comercio al por mayor y al por menor y reparación de vehículos de motor y motocicletas | D79: 5.0240729e+09 | E79: 3.3023925e+09 | F79: 8.3114139e+09 | G79: 60.447872 | H79: =_xlfn.CONCAT(A79,B79,C79) -> Chile2022Comercio al por mayor y al por menor y reparación de vehículos de motor y motocicletas | I79: 120.37242 | J79: =VLOOKUP(H79,[1]Hoja2!D$2:E$191,2,0) -> 1237926.9 | K79: =VLOOKUP(H79,[1]Hoja2!D$2:F$191,3,0) -> 2.1576065e+09 | L79: =IFERROR(VLOOKUP(H79,[2]Sheet1!K$2:L$94,2,0),"") | M79: =IFERROR(VLOOKUP(H79,[2]Sheet1!K$372:L$648,2,0),"") | N79: =D79/I79*100 -> 4.173774e+09 | O79: =N79/J79 -> 3371.5835 | P79: =K79/J79 -> 1742.9191
A80: Chile | B80: 2022 | C80: Comercio al por mayor, excepto de vehículos de motor y motocicletas | D80: 2.2130238e+10 | E80: 1.6533065e+10 | F80: 3.8576627e+10 | G80: 57.366958 | H80: =_xlfn.CONCAT(A80,B80,C80) -> Chile2022Comercio al por mayor, excepto de vehículos de motor y motocicletas | I80: 120.37242 | J80: =VLOOKUP(H80,[1]Hoja2!D$2:E$191,2,0) -> 5249696.3 | K80: =VLOOKUP(H80,[1]Hoja2!D$2:F$191,3,0) -> 9.4321527e+09 | L80: =IFERROR(VLOOKUP(H80,[2]Sheet1!K$2:L$94,2,0),"") | M80: =IFERROR(VLOOKUP(H80,[2]Sheet1!K$372:L$648,2,0),"") | N80: =D80/I80*100 -> 1.8384807e+10 | O80: =N80/J80 -> 3502.0706 | P80: =K80/J80 -> 1796.7045
A81: Chile | B81: 2022 | C81: Comercio al por menor, excepto de vehículos de motor y motocicletas | D81: 1.2623061e+10 | E81: 1.2287584e+10 | F81: 2.4799946e+10 | G81: 50.899551 | H81: =_xlfn.CONCAT(A81,B81,C81) -> Chile2022Comercio al por menor, excepto de vehículos de motor y motocicletas | I81: 120.37242 | J81: =VLOOKUP(H81,[1]Hoja2!D$2:E$191,2,0) -> 6235010.3 | K81: =VLOOKUP(H81,[1]Hoja2!D$2:F$191,3,0) -> 6.9513993e+09 | L81: =IFERROR(VLOOKUP(H81,[2]Sheet1!K$2:L$94,2,0),"") | M81: =IFERROR(VLOOKUP(H81,[2]Sheet1!K$372:L$648,2,0),"") | N81: =D81/I81*100 -> 1.0486672e+10 | O81: =N81/J81 -> 1681.9013 | P81: =K81/J81 -> 1114.8978
A82: Chile | B82: 2022 | C82: Actividades de edición | D82: 4.3321533e+08 | E82: 3.5858305e+08 | F82: 7.9179838e+08 | G82: 54.712834 | H82: =_xlfn.CONCAT(A82,B82,C82) -> Chile2022Actividades de edición | I82: 94.646742 | J82: =VLOOKUP(H82,[1]Hoja2!D$2:E$191,2,0) -> 154394.12 | K82: =VLOOKUP(H82,[1]Hoja2!D$2:F$191,3,0) -> 2.5349341e+08 | L82: =IFERROR(VLOOKUP(H82,[2]Sheet1!K$2:L$94,2,0),"") | M82: =IFERROR(VLOOKUP(H82,[2]Sheet1!K$372:L$648,2,0),"") | N82: =D82/I82*100 -> 4.5771817e+08 | O82: =N82/J82 -> 2964.6089 | P82: =K82/J82 -> 1641.8592
A83: Chile | B83: 2022 | C83: Actividades de programación y radiodifusión | D83: 8.8157769e+08 | E83: 3.9924763e+08 | F83: 1.2808253e+09 | G83: 68.828878 | H83: =_xlfn.CONCAT(A83,B83,C83) -> Chile2022Actividades de programación y radiodifusión | I83: 94.646742 | J83: =VLOOKUP(H83,[1]Hoja2!D$2:E$191,2,0) -> 183737.59 | K83: =VLOOKUP(H83,[1]Hoja2!D$2:F$191,3,0) -> 2.5127969e+08 | L83: =IFERROR(VLOOKUP(H83,[2]Sheet1!K$2:L$94,2,0),"") | M83: =IFERROR(VLOOKUP(H83,[2]Sheet1!K$372:L$648,2,0),"") | N83: =D83/I83*100 -> 9.3144008e+08 | O83: =N83/J83 -> 5069.4041 | P83: =K83/J83 -> 1367.6009
A84: Chile | B84: 2022 | C84: Actividades de servicios de información | D84: 1.6917426e+09 | E84: 8.1452596e+08 | F84: 2.4798475e+09 | G84: 68.219622 | H84: =_xlfn.CONCAT(A84,B84,C84) -> Chile2022Actividades de servicios de información | I84: 94.646742 | J84: =VLOOKUP(H84,[1]Hoja2!D$2:E$191,2,0) -> 432646.94 | K84: =VLOOKUP(H84,[1]Hoja2!D$2:F$191,3,0) -> 7.5222511e+08 | L84: =IFERROR(VLOOKUP(H84,[2]Sheet1!K$2:L$94,2,0),"") | M84: =IFERROR(VLOOKUP(H84,[2]Sheet1!K$372:L$648,2,0),"") | N84: =D84/I84*100 -> 1.7874283e+09 | O84: =N84/J84 -> 4131.3785 | P84: =K84/J84 -> 1738.6581
A85: Chile | B85: 2022 | C85: Producción de películas, videos y programas de televisión, grabación de sonido y edición musical | D85: 6.7715462e+08 | E85: 5.4379238e+08 | F85: 1.220947e+09 | G85: 55.461426 | H85: =_xlfn.CONCAT(A85,B85,C85) -> Chile2022Producción de películas, videos y programas de televisión, grabación de sonido y edición musical | I85: 94.646742 | J85: =VLOOKUP(H85,[1]Hoja2!D$2:E$191,2,0) -> 253206.02 | K85: =VLOOKUP(H85,[1]Hoja2!D$2:F$191,3,0) -> 3.1375648e+08 | L85: =IFERROR(VLOOKUP(H85,[2]Sheet1!K$2:L$94,2,0),"") | M85: =IFERROR(VLOOKUP(H85,[2]Sheet1!K$372:L$648,2,0),"") | N85: =D85/I85*100 -> 7.1545477e+08 | O85: =N85/J85 -> 2825.5835 | P85: =K85/J85 -> 1239.1351
A86: Chile | B86: 2022 | C86: Programación de computadoras, consultoría y actividades relacionadas | D86: 6.8048841e+09 | E86: 4.5095091e+09 | F86: 1.1314393e+10 | G86: 60.143606 | H86: =_xlfn.CONCAT(A86,B86,C86) -> Chile2022Programación de computadoras, consultoría y actividades relacionadas | I86: 94.646742 | J86: =VLOOKUP(H86,[1]Hoja2!D$2:E$191,2,0) -> 2252775.1 | K86: =VLOOKUP(H86,[1]Hoja2!D$2:F$191,3,0) -> 3.9652915e+09 | L86: =IFERROR(VLOOKUP(H86,[2]Sheet1!K$2:L$94,2,0),"") | M86: =IFERROR(VLOOKUP(H86,[2]Sheet1!K$372:L$648,2,0),"") | N86: =D86/I86*100 -> 7.1897711e+09 | O86: =N86/J86 -> 3191.5175 | P86: =K86/J86 -> 1760.1808
A87: Chile | B87: 2022 | C87: Actividades inmobiliarias | D87: 8.2709899e+09 | E87: 7.0256468e+09 | F87: 1.5296637e+10 | G87: 54.070644 | H87: =_xlfn.CONCAT(A87,B87,C87) -> Chile2022Actividades inmobiliarias | J87: =VLOOKUP(H87,[1]Hoja2!D$2:E$191,2,0) -> 2307037.4 | K87: =VLOOKUP(H87,[1]Hoja2!D$2:F$191,3,0) -> 2.3865128e+09 | L87: =IFERROR(VLOOKUP(H87,[2]Sheet1!K$2:L$94,2,0),"") | M87: =IFERROR(VLOOKUP(H87,[2]Sheet1!K$372:L$648,2,0),"") | N87: =D87/I87*100 -> #VALUE! | O87: =N87/J87 -> #VALUE! | P87: =K87/J87 -> 1034.4491
...

Sheet CuadroDivisi
A2: División | B2: País | C2: ΔVA/Emp(%) | D2: Δ REM/EMP(%) | E2: Brecha (p.p)
A3: Elaboración de alimentos | B3: Chile | C3: -4.81 | D3: 1.188 | E3: =D3-C3 -> 5.998
B4: México | C4: 3.3754834 | D4: 11.213344 | E4: =D4-C4 -> 7.8378606
A5: Comercio mayorista, excepto automotor y bicicletas | B5: Chile | C5: -1.61 | D5: -1.72 | E5: =D5-C5 -> -0.11
B6: México | C6: 3.5837278 | D6: 11.178841 | E6: =D6-C6 -> 7.5951134
A7: Producción de películas, videos y programas de televisión, grabación de sonido y edición musical | B7: Chile | C7: -8.69 | D7: -4.99 | E7: =D7-C7 -> 3.7
B8: México | C8: -8.3445601 | D8: 3.1495 | E8: =D8-C8 -> 11.49406
